INFO:root:2024-05-14 20:18:18.742491 - Login failed - Incorrect password for username: a
INFO:root:2024-05-14 20:20:05.676627 - Login failed - Incorrect password for username: a
INFO:root:2024-05-14 20:20:08.809139 - Login failed - Incorrect password for username: a
INFO:root:2024-05-14 20:20:17.589929 - Login failed - Incorrect password for username: a
INFO:root:2024-05-14 20:20:20.795077 - Login failed - Incorrect password for username: a
INFO:root:2024-05-16 15:17:43.376829 - Login failed - Incorrect password for username: a
INFO:paramiko.transport:Connected (version 2.0, client OpenSSH_8.2p1)
INFO:paramiko.transport:Authentication (password) successful!
INFO:paramiko.transport.sftp:[chan 3] Opened sftp connection (server version 3)
INFO:paramiko.transport.sftp:[chan 4] Opened sftp connection (server version 3)
INFO:root:2024-05-16 15:37:58.330203 - Login failed - Incorrect password for username: a
INFO:root:2024-05-16 15:38:05.202975 - Login failed - Incorrect password for username: a
INFO:paramiko.transport:Connected (version 2.0, client OpenSSH_8.2p1)
INFO:paramiko.transport:Authentication (password) successful!
INFO:paramiko.transport.sftp:[chan 3] Opened sftp connection (server version 3)
INFO:paramiko.transport.sftp:[chan 4] Opened sftp connection (server version 3)
INFO:paramiko.transport:Connected (version 2.0, client OpenSSH_8.2p1)
INFO:paramiko.transport:Authentication (password) successful!
INFO:paramiko.transport.sftp:[chan 3] Opened sftp connection (server version 3)
INFO:paramiko.transport.sftp:[chan 4] Opened sftp connection (server version 3)
INFO:paramiko.transport:Connected (version 2.0, client OpenSSH_8.2p1)
INFO:paramiko.transport:Authentication (password) successful!
INFO:paramiko.transport.sftp:[chan 0] Opened sftp connection (server version 3)
INFO:paramiko.transport.sftp:[chan 1] Opened sftp connection (server version 3)
INFO:paramiko.transport:Connected (version 2.0, client OpenSSH_8.2p1)
INFO:paramiko.transport:Authentication (password) successful!
INFO:paramiko.transport.sftp:[chan 3] Opened sftp connection (server version 3)
INFO:paramiko.transport.sftp:[chan 4] Opened sftp connection (server version 3)
INFO:paramiko.transport:Connected (version 2.0, client OpenSSH_8.2p1)
INFO:paramiko.transport:Authentication (password) successful!
INFO:paramiko.transport.sftp:[chan 3] Opened sftp connection (server version 3)
INFO:paramiko.transport:Connected (version 2.0, client OpenSSH_8.2p1)
INFO:paramiko.transport:Authentication (password) successful!
INFO:paramiko.transport.sftp:[chan 3] Opened sftp connection (server version 3)
INFO:paramiko.transport:Connected (version 2.0, client OpenSSH_8.2p1)
INFO:paramiko.transport:Authentication (password) successful!
INFO:paramiko.transport.sftp:[chan 0] Opened sftp connection (server version 3)
INFO:paramiko.transport:Connected (version 2.0, client OpenSSH_8.2p1)
INFO:paramiko.transport:Authentication (password) successful!
INFO:paramiko.transport:Connected (version 2.0, client OpenSSH_8.2p1)
INFO:paramiko.transport:Authentication (password) successful!
INFO:paramiko.transport.sftp:[chan 3] Opened sftp connection (server version 3)
INFO:paramiko.transport:Connected (version 2.0, client OpenSSH_8.2p1)
INFO:paramiko.transport:Authentication (password) successful!
INFO:paramiko.transport.sftp:[chan 0] Opened sftp connection (server version 3)
INFO:paramiko.transport:Connected (version 2.0, client OpenSSH_8.2p1)
INFO:paramiko.transport:Authentication (password) successful!
INFO:paramiko.transport:Connected (version 2.0, client OpenSSH_8.2p1)
INFO:paramiko.transport:Authentication (password) successful!
INFO:paramiko.transport.sftp:[chan 3] Opened sftp connection (server version 3)
INFO:paramiko.transport:Connected (version 2.0, client OpenSSH_8.2p1)
INFO:paramiko.transport:Authentication (password) successful!
INFO:paramiko.transport.sftp:[chan 0] Opened sftp connection (server version 3)
INFO:paramiko.transport:Connected (version 2.0, client OpenSSH_8.2p1)
INFO:paramiko.transport:Authentication (password) successful!
INFO:paramiko.transport:Connected (version 2.0, client OpenSSH_8.2p1)
INFO:paramiko.transport:Authentication (password) successful!
INFO:paramiko.transport.sftp:[chan 3] Opened sftp connection (server version 3)
INFO:paramiko.transport:Connected (version 2.0, client OpenSSH_8.2p1)
INFO:paramiko.transport:Authentication (password) successful!
INFO:paramiko.transport.sftp:[chan 0] Opened sftp connection (server version 3)
INFO:paramiko.transport:Connected (version 2.0, client OpenSSH_8.2p1)
INFO:paramiko.transport:Authentication (password) successful!
INFO:paramiko.transport:Connected (version 2.0, client OpenSSH_8.2p1)
INFO:paramiko.transport:Authentication (password) successful!
INFO:paramiko.transport.sftp:[chan 3] Opened sftp connection (server version 3)
INFO:paramiko.transport.sftp:[chan 4] Opened sftp connection (server version 3)
INFO:paramiko.transport:Connected (version 2.0, client OpenSSH_8.2p1)
INFO:paramiko.transport:Authentication (password) successful!
INFO:paramiko.transport.sftp:[chan 3] Opened sftp connection (server version 3)
INFO:paramiko.transport.sftp:[chan 4] Opened sftp connection (server version 3)
INFO:paramiko.transport:Connected (version 2.0, client OpenSSH_8.2p1)
INFO:paramiko.transport:Authentication (password) successful!
INFO:paramiko.transport.sftp:[chan 3] Opened sftp connection (server version 3)
INFO:paramiko.transport.sftp:[chan 4] Opened sftp connection (server version 3)
INFO:paramiko.transport:Connected (version 2.0, client OpenSSH_8.2p1)
INFO:paramiko.transport:Authentication (password) successful!
INFO:paramiko.transport.sftp:[chan 3] Opened sftp connection (server version 3)
INFO:paramiko.transport:Connected (version 2.0, client OpenSSH_8.2p1)
INFO:paramiko.transport:Authentication (password) successful!
INFO:paramiko.transport.sftp:[chan 3] Opened sftp connection (server version 3)
INFO:paramiko.transport:Connected (version 2.0, client OpenSSH_8.2p1)
INFO:paramiko.transport:Authentication (password) successful!
INFO:paramiko.transport.sftp:[chan 0] Opened sftp connection (server version 3)
INFO:paramiko.transport:Connected (version 2.0, client OpenSSH_8.2p1)
INFO:paramiko.transport:Authentication (password) successful!
INFO:paramiko.transport:Connected (version 2.0, client OpenSSH_8.2p1)
INFO:paramiko.transport:Authentication (password) successful!
INFO:paramiko.transport.sftp:[chan 3] Opened sftp connection (server version 3)
INFO:paramiko.transport:Connected (version 2.0, client OpenSSH_8.2p1)
INFO:paramiko.transport:Authentication (password) successful!
INFO:paramiko.transport.sftp:[chan 0] Opened sftp connection (server version 3)
INFO:paramiko.transport:Connected (version 2.0, client OpenSSH_8.2p1)
INFO:paramiko.transport:Authentication (password) successful!
INFO:paramiko.transport:Connected (version 2.0, client OpenSSH_8.2p1)
INFO:paramiko.transport:Authentication (password) successful!
INFO:paramiko.transport.sftp:[chan 3] Opened sftp connection (server version 3)
INFO:paramiko.transport:Connected (version 2.0, client OpenSSH_8.2p1)
INFO:paramiko.transport:Authentication (password) successful!
INFO:paramiko.transport.sftp:[chan 0] Opened sftp connection (server version 3)
ERROR:paramiko.transport:Socket exception: Se ha forzado la interrupción de una conexión existente por el host remoto (10054)
ERROR:paramiko.transport:Socket exception: Se ha forzado la interrupción de una conexión existente por el host remoto (10054)
INFO:paramiko.transport:Connected (version 2.0, client OpenSSH_8.2p1)
INFO:paramiko.transport:Authentication (password) successful!
INFO:paramiko.transport.sftp:[chan 3] Opened sftp connection (server version 3)
INFO:paramiko.transport:Connected (version 2.0, client OpenSSH_8.2p1)
INFO:paramiko.transport:Authentication (password) successful!
INFO:paramiko.transport.sftp:[chan 0] Opened sftp connection (server version 3)
INFO:paramiko.transport:Connected (version 2.0, client OpenSSH_8.2p1)
INFO:paramiko.transport:Authentication (password) successful!
INFO:paramiko.transport:Connected (version 2.0, client OpenSSH_8.2p1)
INFO:paramiko.transport:Authentication (password) successful!
INFO:paramiko.transport.sftp:[chan 3] Opened sftp connection (server version 3)
INFO:paramiko.transport.sftp:[chan 4] Opened sftp connection (server version 3)
INFO:paramiko.transport:Connected (version 2.0, client OpenSSH_8.2p1)
INFO:paramiko.transport:Authentication (password) successful!
INFO:paramiko.transport.sftp:[chan 3] Opened sftp connection (server version 3)
INFO:paramiko.transport.sftp:[chan 4] Opened sftp connection (server version 3)
INFO:paramiko.transport:Connected (version 2.0, client OpenSSH_8.2p1)
INFO:paramiko.transport:Authentication (password) successful!
INFO:paramiko.transport.sftp:[chan 3] Opened sftp connection (server version 3)
INFO:paramiko.transport.sftp:[chan 4] Opened sftp connection (server version 3)
ERROR:asyncio:Task exception was never retrieved
future: <Task finished name='Task-3' coro=<watch_changes() done, defined at E:\Project\Back4\BN-BackEnd\config\changeStream.py:5> exception=KeyError('fullDocument')>
Traceback (most recent call last):
  File "E:\Project\Back4\BN-BackEnd\config\changeStream.py", line 17, in watch_changes
    document = change["fullDocument"]
               ~~~~~~^^^^^^^^^^^^^^^^
KeyError: 'fullDocument'
ERROR:asyncio:Task exception was never retrieved
future: <Task finished name='Task-3' coro=<watch_changes() done, defined at E:\Project\Back4\BN-BackEnd\config\changeStream.py:5> exception=KeyError('fullDocument')>
Traceback (most recent call last):
  File "E:\Project\Back4\BN-BackEnd\config\changeStream.py", line 17, in watch_changes
    document = change["fullDocument"]
               ~~~~~~^^^^^^^^^^^^^^^^
KeyError: 'fullDocument'
ERROR:asyncio:Task exception was never retrieved
future: <Task finished name='Task-3' coro=<watch_changes() done, defined at E:\Project\Back4\BN-BackEnd\config\changeStream.py:5> exception=KeyError('fullDocument')>
Traceback (most recent call last):
  File "E:\Project\Back4\BN-BackEnd\config\changeStream.py", line 17, in watch_changes
    document = change["fullDocument"]
               ~~~~~~^^^^^^^^^^^^^^^^
KeyError: 'fullDocument'
ERROR:asyncio:Task exception was never retrieved
future: <Task finished name='Task-3' coro=<watch_changes() done, defined at E:\Project\Back4\BN-BackEnd\config\changeStream.py:5> exception=KeyError('fullDocument')>
Traceback (most recent call last):
  File "E:\Project\Back4\BN-BackEnd\config\changeStream.py", line 17, in watch_changes
    document = change["fullDocument"]
               ~~~~~~^^^^^^^^^^^^^^^^
KeyError: 'fullDocument'
ERROR:asyncio:Task exception was never retrieved
future: <Task finished name='Task-3' coro=<watch_changes() done, defined at E:\Project\Back4\BN-BackEnd\config\changeStream.py:5> exception=KeyError('fullDocument')>
Traceback (most recent call last):
  File "E:\Project\Back4\BN-BackEnd\config\changeStream.py", line 17, in watch_changes
    document = change["fullDocument"]
               ~~~~~~^^^^^^^^^^^^^^^^
KeyError: 'fullDocument'
ERROR:asyncio:Task exception was never retrieved
future: <Task finished name='Task-3' coro=<watch_changes() done, defined at E:\Project\Back4\BN-BackEnd\config\changeStream.py:5> exception=KeyError('fullDocument')>
Traceback (most recent call last):
  File "E:\Project\Back4\BN-BackEnd\config\changeStream.py", line 17, in watch_changes
    document = change["fullDocument"]
               ~~~~~~^^^^^^^^^^^^^^^^
KeyError: 'fullDocument'
ERROR:asyncio:Task exception was never retrieved
future: <Task finished name='Task-3' coro=<watch_changes() done, defined at E:\Project\Back4\BN-BackEnd\config\changeStream.py:5> exception=KeyError('fullDocument')>
Traceback (most recent call last):
  File "E:\Project\Back4\BN-BackEnd\config\changeStream.py", line 17, in watch_changes
    document = change["fullDocument"]
               ~~~~~~^^^^^^^^^^^^^^^^
KeyError: 'fullDocument'
ERROR:asyncio:Task exception was never retrieved
future: <Task finished name='Task-3' coro=<watch_changes() done, defined at E:\Project\Back4\BN-BackEnd\config\changeStream.py:5> exception=KeyError('fullDocument')>
Traceback (most recent call last):
  File "E:\Project\Back4\BN-BackEnd\config\changeStream.py", line 17, in watch_changes
    document = change["fullDocument"]
               ~~~~~~^^^^^^^^^^^^^^^^
KeyError: 'fullDocument'
ERROR:asyncio:Task exception was never retrieved
future: <Task finished name='Task-3' coro=<watch_changes() done, defined at E:\Project\Back4\BN-BackEnd\config\changeStream.py:5> exception=KeyError('fullDocument')>
Traceback (most recent call last):
  File "E:\Project\Back4\BN-BackEnd\config\changeStream.py", line 17, in watch_changes
    document = change["fullDocument"]
               ~~~~~~^^^^^^^^^^^^^^^^
KeyError: 'fullDocument'
ERROR:asyncio:Task exception was never retrieved
future: <Task finished name='Task-3' coro=<watch_changes() done, defined at E:\Project\Back4\BN-BackEnd\config\changeStream.py:5> exception=ServerSelectionTimeoutError("ac-7zrxalx-shard-00-00.v1mxd4q.mongodb.net:27017: [WinError 10013] Intento de acceso a un socket no permitido por sus permisos de acceso (configured timeouts: socketTimeoutMS: 20000.0ms, connectTimeoutMS: 20000.0ms),ac-7zrxalx-shard-00-01.v1mxd4q.mongodb.net:27017: [WinError 10013] Intento de acceso a un socket no permitido por sus permisos de acceso (configured timeouts: socketTimeoutMS: 20000.0ms, connectTimeoutMS: 20000.0ms),ac-7zrxalx-shard-00-02.v1mxd4q.mongodb.net:27017: [WinError 10013] Intento de acceso a un socket no permitido por sus permisos de acceso (configured timeouts: socketTimeoutMS: 20000.0ms, connectTimeoutMS: 20000.0ms), Timeout: 30s, Topology Description: <TopologyDescription id: 664ce5558badb90559bf1b47, topology_type: ReplicaSetNoPrimary, servers: [<ServerDescription ('ac-7zrxalx-shard-00-00.v1mxd4q.mongodb.net', 27017) server_type: Unknown, rtt: None, error=AutoReconnect('ac-7zrxalx-shard-00-00.v1mxd4q.mongodb.net:27017: [WinError 10013] Intento de acceso a un socket no permitido por sus permisos de acceso (configured timeouts: socketTimeoutMS: 20000.0ms, connectTimeoutMS: 20000.0ms)')>, <ServerDescription ('ac-7zrxalx-shard-00-01.v1mxd4q.mongodb.net', 27017) server_type: Unknown, rtt: None, error=AutoReconnect('ac-7zrxalx-shard-00-01.v1mxd4q.mongodb.net:27017: [WinError 10013] Intento de acceso a un socket no permitido por sus permisos de acceso (configured timeouts: socketTimeoutMS: 20000.0ms, connectTimeoutMS: 20000.0ms)')>, <ServerDescription ('ac-7zrxalx-shard-00-02.v1mxd4q.mongodb.net', 27017) server_type: Unknown, rtt: None, error=AutoReconnect('ac-7zrxalx-shard-00-02.v1mxd4q.mongodb.net:27017: [WinError 10013] Intento de acceso a un socket no permitido por sus permisos de acceso (configured timeouts: socketTimeoutMS: 20000.0ms, connectTimeoutMS: 20000.0ms)')>]>")>
Traceback (most recent call last):
  File "C:\Users\martimasxax\AppData\Local\Packages\PythonSoftwareFoundation.Python.3.12_qbz5n2kfra8p0\LocalCache\local-packages\Python312\site-packages\pymongo\pool.py", line 1020, in receive_message
    return receive_message(self, request_id, self.max_message_size)
           ^^^^^^^^^^^^^^^^^^^^^^^^^^^^^^^^^^^^^^^^^^^^^^^^^^^^^^^^
  File "C:\Users\martimasxax\AppData\Local\Packages\PythonSoftwareFoundation.Python.3.12_qbz5n2kfra8p0\LocalCache\local-packages\Python312\site-packages\pymongo\network.py", line 257, in receive_message
    length, _, response_to, op_code = _UNPACK_HEADER(_receive_data_on_socket(conn, 16, deadline))
                                                     ^^^^^^^^^^^^^^^^^^^^^^^^^^^^^^^^^^^^^^^^^^^
  File "C:\Users\martimasxax\AppData\Local\Packages\PythonSoftwareFoundation.Python.3.12_qbz5n2kfra8p0\LocalCache\local-packages\Python312\site-packages\pymongo\network.py", line 340, in _receive_data_on_socket
    chunk_length = conn.conn.recv_into(mv[bytes_read:])
                   ^^^^^^^^^^^^^^^^^^^^^^^^^^^^^^^^^^^^
  File "C:\Users\martimasxax\AppData\Local\Packages\PythonSoftwareFoundation.Python.3.12_qbz5n2kfra8p0\LocalCache\local-packages\Python312\site-packages\pymongo\pyopenssl_context.py", line 155, in recv_into
    return self._call(super().recv_into, *args, **kwargs)
           ^^^^^^^^^^^^^^^^^^^^^^^^^^^^^^^^^^^^^^^^^^^^^^
  File "C:\Users\martimasxax\AppData\Local\Packages\PythonSoftwareFoundation.Python.3.12_qbz5n2kfra8p0\LocalCache\local-packages\Python312\site-packages\pymongo\pyopenssl_context.py", line 120, in _call
    return call(*args, **kwargs)
           ^^^^^^^^^^^^^^^^^^^^^
  File "C:\Users\martimasxax\AppData\Local\Packages\PythonSoftwareFoundation.Python.3.12_qbz5n2kfra8p0\LocalCache\local-packages\Python312\site-packages\OpenSSL\SSL.py", line 2099, in recv_into
    self._raise_ssl_error(self._ssl, result)
  File "C:\Users\martimasxax\AppData\Local\Packages\PythonSoftwareFoundation.Python.3.12_qbz5n2kfra8p0\LocalCache\local-packages\Python312\site-packages\OpenSSL\SSL.py", line 1818, in _raise_ssl_error
    raise SysCallError(errno, errorcode.get(errno))
OpenSSL.SSL.SysCallError: (10054, 'WSAECONNRESET')

The above exception was the direct cause of the following exception:

Traceback (most recent call last):
  File "C:\Users\martimasxax\AppData\Local\Packages\PythonSoftwareFoundation.Python.3.12_qbz5n2kfra8p0\LocalCache\local-packages\Python312\site-packages\pymongo\change_stream.py", line 372, in try_next
    change = self._cursor._try_next(True)
             ^^^^^^^^^^^^^^^^^^^^^^^^^^^^
  File "C:\Users\martimasxax\AppData\Local\Packages\PythonSoftwareFoundation.Python.3.12_qbz5n2kfra8p0\LocalCache\local-packages\Python312\site-packages\pymongo\command_cursor.py", line 321, in _try_next
    self._refresh()
  File "C:\Users\martimasxax\AppData\Local\Packages\PythonSoftwareFoundation.Python.3.12_qbz5n2kfra8p0\LocalCache\local-packages\Python312\site-packages\pymongo\command_cursor.py", line 242, in _refresh
    self.__send_message(
  File "C:\Users\martimasxax\AppData\Local\Packages\PythonSoftwareFoundation.Python.3.12_qbz5n2kfra8p0\LocalCache\local-packages\Python312\site-packages\pymongo\command_cursor.py", line 179, in __send_message
    response = client._run_operation(
               ^^^^^^^^^^^^^^^^^^^^^^
  File "C:\Users\martimasxax\AppData\Local\Packages\PythonSoftwareFoundation.Python.3.12_qbz5n2kfra8p0\LocalCache\local-packages\Python312\site-packages\pymongo\_csot.py", line 107, in csot_wrapper
    return func(self, *args, **kwargs)
           ^^^^^^^^^^^^^^^^^^^^^^^^^^^
  File "C:\Users\martimasxax\AppData\Local\Packages\PythonSoftwareFoundation.Python.3.12_qbz5n2kfra8p0\LocalCache\local-packages\Python312\site-packages\pymongo\mongo_client.py", line 1394, in _run_operation
    return self._retryable_read(
           ^^^^^^^^^^^^^^^^^^^^^
  File "C:\Users\martimasxax\AppData\Local\Packages\PythonSoftwareFoundation.Python.3.12_qbz5n2kfra8p0\LocalCache\local-packages\Python312\site-packages\pymongo\mongo_client.py", line 1492, in _retryable_read
    return self._retry_internal(
           ^^^^^^^^^^^^^^^^^^^^^
  File "C:\Users\martimasxax\AppData\Local\Packages\PythonSoftwareFoundation.Python.3.12_qbz5n2kfra8p0\LocalCache\local-packages\Python312\site-packages\pymongo\_csot.py", line 107, in csot_wrapper
    return func(self, *args, **kwargs)
           ^^^^^^^^^^^^^^^^^^^^^^^^^^^
  File "C:\Users\martimasxax\AppData\Local\Packages\PythonSoftwareFoundation.Python.3.12_qbz5n2kfra8p0\LocalCache\local-packages\Python312\site-packages\pymongo\mongo_client.py", line 1462, in _retry_internal
    ).run()
      ^^^^^
  File "C:\Users\martimasxax\AppData\Local\Packages\PythonSoftwareFoundation.Python.3.12_qbz5n2kfra8p0\LocalCache\local-packages\Python312\site-packages\pymongo\mongo_client.py", line 2315, in run
    return self._read() if self._is_read else self._write()
           ^^^^^^^^^^^^
  File "C:\Users\martimasxax\AppData\Local\Packages\PythonSoftwareFoundation.Python.3.12_qbz5n2kfra8p0\LocalCache\local-packages\Python312\site-packages\pymongo\mongo_client.py", line 2445, in _read
    return self._func(self._session, self._server, conn, read_pref)  # type: ignore
           ^^^^^^^^^^^^^^^^^^^^^^^^^^^^^^^^^^^^^^^^^^^^^^^^^^^^^^^^
  File "C:\Users\martimasxax\AppData\Local\Packages\PythonSoftwareFoundation.Python.3.12_qbz5n2kfra8p0\LocalCache\local-packages\Python312\site-packages\pymongo\mongo_client.py", line 1390, in _cmd
    return server.run_operation(
           ^^^^^^^^^^^^^^^^^^^^^
  File "C:\Users\martimasxax\AppData\Local\Packages\PythonSoftwareFoundation.Python.3.12_qbz5n2kfra8p0\LocalCache\local-packages\Python312\site-packages\pymongo\helpers.py", line 322, in inner
    return func(*args, **kwargs)
           ^^^^^^^^^^^^^^^^^^^^^
  File "C:\Users\martimasxax\AppData\Local\Packages\PythonSoftwareFoundation.Python.3.12_qbz5n2kfra8p0\LocalCache\local-packages\Python312\site-packages\pymongo\server.py", line 148, in run_operation
    reply = conn.receive_message(request_id)
            ^^^^^^^^^^^^^^^^^^^^^^^^^^^^^^^^
  File "C:\Users\martimasxax\AppData\Local\Packages\PythonSoftwareFoundation.Python.3.12_qbz5n2kfra8p0\LocalCache\local-packages\Python312\site-packages\pymongo\pool.py", line 1022, in receive_message
    self._raise_connection_failure(error)
  File "C:\Users\martimasxax\AppData\Local\Packages\PythonSoftwareFoundation.Python.3.12_qbz5n2kfra8p0\LocalCache\local-packages\Python312\site-packages\pymongo\pool.py", line 1171, in _raise_connection_failure
    _raise_connection_failure(self.address, error, timeout_details=details)
  File "C:\Users\martimasxax\AppData\Local\Packages\PythonSoftwareFoundation.Python.3.12_qbz5n2kfra8p0\LocalCache\local-packages\Python312\site-packages\pymongo\pool.py", line 411, in _raise_connection_failure
    raise AutoReconnect(msg) from error
pymongo.errors.AutoReconnect: ac-7zrxalx-shard-00-01.v1mxd4q.mongodb.net:27017: (10054, 'WSAECONNRESET') (configured timeouts: connectTimeoutMS: 20000.0ms)

During handling of the above exception, another exception occurred:

Traceback (most recent call last):
  File "E:\Project\Back4\BN-BackEnd\config\changeStream.py", line 7, in watch_changes
    async for change in stream:
  File "C:\Users\martimasxax\AppData\Local\Packages\PythonSoftwareFoundation.Python.3.12_qbz5n2kfra8p0\LocalCache\local-packages\Python312\site-packages\motor\core.py", line 2038, in next
    doc = await self.try_next()
          ^^^^^^^^^^^^^^^^^^^^^
  File "C:\Users\martimasxax\AppData\Local\Packages\PythonSoftwareFoundation.Python.3.12_qbz5n2kfra8p0\LocalCache\local-packages\Python312\site-packages\motor\core.py", line 2079, in try_next
    return await self._framework.run_on_executor(loop, self._try_next)
           ^^^^^^^^^^^^^^^^^^^^^^^^^^^^^^^^^^^^^^^^^^^^^^^^^^^^^^^^^^^
  File "C:\Program Files\WindowsApps\PythonSoftwareFoundation.Python.3.12_3.12.1008.0_x64__qbz5n2kfra8p0\Lib\concurrent\futures\thread.py", line 58, in run
    result = self.fn(*self.args, **self.kwargs)
             ^^^^^^^^^^^^^^^^^^^^^^^^^^^^^^^^^^
  File "C:\Users\martimasxax\AppData\Local\Packages\PythonSoftwareFoundation.Python.3.12_qbz5n2kfra8p0\LocalCache\local-packages\Python312\site-packages\motor\core.py", line 1984, in _try_next
    return self.delegate.try_next()
           ^^^^^^^^^^^^^^^^^^^^^^^^
  File "C:\Users\martimasxax\AppData\Local\Packages\PythonSoftwareFoundation.Python.3.12_qbz5n2kfra8p0\LocalCache\local-packages\Python312\site-packages\pymongo\_csot.py", line 107, in csot_wrapper
    return func(self, *args, **kwargs)
           ^^^^^^^^^^^^^^^^^^^^^^^^^^^
  File "C:\Users\martimasxax\AppData\Local\Packages\PythonSoftwareFoundation.Python.3.12_qbz5n2kfra8p0\LocalCache\local-packages\Python312\site-packages\pymongo\change_stream.py", line 376, in try_next
    self._resume()
  File "C:\Users\martimasxax\AppData\Local\Packages\PythonSoftwareFoundation.Python.3.12_qbz5n2kfra8p0\LocalCache\local-packages\Python312\site-packages\pymongo\change_stream.py", line 260, in _resume
    self._cursor = self._create_cursor()
                   ^^^^^^^^^^^^^^^^^^^^^
  File "C:\Users\martimasxax\AppData\Local\Packages\PythonSoftwareFoundation.Python.3.12_qbz5n2kfra8p0\LocalCache\local-packages\Python312\site-packages\pymongo\change_stream.py", line 252, in _create_cursor
    return self._run_aggregation_cmd(session=s, explicit_session=self._session is not None)
           ^^^^^^^^^^^^^^^^^^^^^^^^^^^^^^^^^^^^^^^^^^^^^^^^^^^^^^^^^^^^^^^^^^^^^^^^^^^^^^^^
  File "C:\Users\martimasxax\AppData\Local\Packages\PythonSoftwareFoundation.Python.3.12_qbz5n2kfra8p0\LocalCache\local-packages\Python312\site-packages\pymongo\change_stream.py", line 246, in _run_aggregation_cmd
    return self._client._retryable_read(
           ^^^^^^^^^^^^^^^^^^^^^^^^^^^^^
  File "C:\Users\martimasxax\AppData\Local\Packages\PythonSoftwareFoundation.Python.3.12_qbz5n2kfra8p0\LocalCache\local-packages\Python312\site-packages\pymongo\mongo_client.py", line 1492, in _retryable_read
    return self._retry_internal(
           ^^^^^^^^^^^^^^^^^^^^^
  File "C:\Users\martimasxax\AppData\Local\Packages\PythonSoftwareFoundation.Python.3.12_qbz5n2kfra8p0\LocalCache\local-packages\Python312\site-packages\pymongo\_csot.py", line 107, in csot_wrapper
    return func(self, *args, **kwargs)
           ^^^^^^^^^^^^^^^^^^^^^^^^^^^
  File "C:\Users\martimasxax\AppData\Local\Packages\PythonSoftwareFoundation.Python.3.12_qbz5n2kfra8p0\LocalCache\local-packages\Python312\site-packages\pymongo\mongo_client.py", line 1462, in _retry_internal
    ).run()
      ^^^^^
  File "C:\Users\martimasxax\AppData\Local\Packages\PythonSoftwareFoundation.Python.3.12_qbz5n2kfra8p0\LocalCache\local-packages\Python312\site-packages\pymongo\mongo_client.py", line 2315, in run
    return self._read() if self._is_read else self._write()
           ^^^^^^^^^^^^
  File "C:\Users\martimasxax\AppData\Local\Packages\PythonSoftwareFoundation.Python.3.12_qbz5n2kfra8p0\LocalCache\local-packages\Python312\site-packages\pymongo\mongo_client.py", line 2437, in _read
    self._server = self._get_server()
                   ^^^^^^^^^^^^^^^^^^
  File "C:\Users\martimasxax\AppData\Local\Packages\PythonSoftwareFoundation.Python.3.12_qbz5n2kfra8p0\LocalCache\local-packages\Python312\site-packages\pymongo\mongo_client.py", line 2400, in _get_server
    return self._client._select_server(
           ^^^^^^^^^^^^^^^^^^^^^^^^^^^^
  File "C:\Users\martimasxax\AppData\Local\Packages\PythonSoftwareFoundation.Python.3.12_qbz5n2kfra8p0\LocalCache\local-packages\Python312\site-packages\pymongo\mongo_client.py", line 1303, in _select_server
    server = topology.select_server(server_selector)
             ^^^^^^^^^^^^^^^^^^^^^^^^^^^^^^^^^^^^^^^
  File "C:\Users\martimasxax\AppData\Local\Packages\PythonSoftwareFoundation.Python.3.12_qbz5n2kfra8p0\LocalCache\local-packages\Python312\site-packages\pymongo\topology.py", line 302, in select_server
    server = self._select_server(selector, server_selection_timeout, address)
             ^^^^^^^^^^^^^^^^^^^^^^^^^^^^^^^^^^^^^^^^^^^^^^^^^^^^^^^^^^^^^^^^
  File "C:\Users\martimasxax\AppData\Local\Packages\PythonSoftwareFoundation.Python.3.12_qbz5n2kfra8p0\LocalCache\local-packages\Python312\site-packages\pymongo\topology.py", line 286, in _select_server
    servers = self.select_servers(selector, server_selection_timeout, address)
              ^^^^^^^^^^^^^^^^^^^^^^^^^^^^^^^^^^^^^^^^^^^^^^^^^^^^^^^^^^^^^^^^
  File "C:\Users\martimasxax\AppData\Local\Packages\PythonSoftwareFoundation.Python.3.12_qbz5n2kfra8p0\LocalCache\local-packages\Python312\site-packages\pymongo\topology.py", line 237, in select_servers
    server_descriptions = self._select_servers_loop(selector, server_timeout, address)
                          ^^^^^^^^^^^^^^^^^^^^^^^^^^^^^^^^^^^^^^^^^^^^^^^^^^^^^^^^^^^^
  File "C:\Users\martimasxax\AppData\Local\Packages\PythonSoftwareFoundation.Python.3.12_qbz5n2kfra8p0\LocalCache\local-packages\Python312\site-packages\pymongo\topology.py", line 259, in _select_servers_loop
    raise ServerSelectionTimeoutError(
pymongo.errors.ServerSelectionTimeoutError: ac-7zrxalx-shard-00-00.v1mxd4q.mongodb.net:27017: [WinError 10013] Intento de acceso a un socket no permitido por sus permisos de acceso (configured timeouts: socketTimeoutMS: 20000.0ms, connectTimeoutMS: 20000.0ms),ac-7zrxalx-shard-00-01.v1mxd4q.mongodb.net:27017: [WinError 10013] Intento de acceso a un socket no permitido por sus permisos de acceso (configured timeouts: socketTimeoutMS: 20000.0ms, connectTimeoutMS: 20000.0ms),ac-7zrxalx-shard-00-02.v1mxd4q.mongodb.net:27017: [WinError 10013] Intento de acceso a un socket no permitido por sus permisos de acceso (configured timeouts: socketTimeoutMS: 20000.0ms, connectTimeoutMS: 20000.0ms), Timeout: 30s, Topology Description: <TopologyDescription id: 664ce5558badb90559bf1b47, topology_type: ReplicaSetNoPrimary, servers: [<ServerDescription ('ac-7zrxalx-shard-00-00.v1mxd4q.mongodb.net', 27017) server_type: Unknown, rtt: None, error=AutoReconnect('ac-7zrxalx-shard-00-00.v1mxd4q.mongodb.net:27017: [WinError 10013] Intento de acceso a un socket no permitido por sus permisos de acceso (configured timeouts: socketTimeoutMS: 20000.0ms, connectTimeoutMS: 20000.0ms)')>, <ServerDescription ('ac-7zrxalx-shard-00-01.v1mxd4q.mongodb.net', 27017) server_type: Unknown, rtt: None, error=AutoReconnect('ac-7zrxalx-shard-00-01.v1mxd4q.mongodb.net:27017: [WinError 10013] Intento de acceso a un socket no permitido por sus permisos de acceso (configured timeouts: socketTimeoutMS: 20000.0ms, connectTimeoutMS: 20000.0ms)')>, <ServerDescription ('ac-7zrxalx-shard-00-02.v1mxd4q.mongodb.net', 27017) server_type: Unknown, rtt: None, error=AutoReconnect('ac-7zrxalx-shard-00-02.v1mxd4q.mongodb.net:27017: [WinError 10013] Intento de acceso a un socket no permitido por sus permisos de acceso (configured timeouts: socketTimeoutMS: 20000.0ms, connectTimeoutMS: 20000.0ms)')>]>
INFO:paramiko.transport:Connected (version 2.0, client OpenSSH_8.2p1)
INFO:paramiko.transport:Authentication (password) successful!
ERROR:asyncio:Task exception was never retrieved
future: <Task finished name='Task-3' coro=<watch_changes() done, defined at E:\Project\Back4\BN-BackEnd\config\changeStream.py:5> exception=ServerSelectionTimeoutError("ac-7zrxalx-shard-00-00.v1mxd4q.mongodb.net:27017: [WinError 10013] Intento de acceso a un socket no permitido por sus permisos de acceso (configured timeouts: socketTimeoutMS: 20000.0ms, connectTimeoutMS: 20000.0ms),ac-7zrxalx-shard-00-02.v1mxd4q.mongodb.net:27017: [WinError 10013] Intento de acceso a un socket no permitido por sus permisos de acceso (configured timeouts: socketTimeoutMS: 20000.0ms, connectTimeoutMS: 20000.0ms),ac-7zrxalx-shard-00-01.v1mxd4q.mongodb.net:27017: [WinError 10013] Intento de acceso a un socket no permitido por sus permisos de acceso (configured timeouts: socketTimeoutMS: 20000.0ms, connectTimeoutMS: 20000.0ms), Timeout: 30s, Topology Description: <TopologyDescription id: 664e0a315470cf5cd6615b5a, topology_type: ReplicaSetNoPrimary, servers: [<ServerDescription ('ac-7zrxalx-shard-00-00.v1mxd4q.mongodb.net', 27017) server_type: Unknown, rtt: None, error=AutoReconnect('ac-7zrxalx-shard-00-00.v1mxd4q.mongodb.net:27017: [WinError 10013] Intento de acceso a un socket no permitido por sus permisos de acceso (configured timeouts: socketTimeoutMS: 20000.0ms, connectTimeoutMS: 20000.0ms)')>, <ServerDescription ('ac-7zrxalx-shard-00-01.v1mxd4q.mongodb.net', 27017) server_type: Unknown, rtt: None, error=AutoReconnect('ac-7zrxalx-shard-00-01.v1mxd4q.mongodb.net:27017: [WinError 10013] Intento de acceso a un socket no permitido por sus permisos de acceso (configured timeouts: socketTimeoutMS: 20000.0ms, connectTimeoutMS: 20000.0ms)')>, <ServerDescription ('ac-7zrxalx-shard-00-02.v1mxd4q.mongodb.net', 27017) server_type: Unknown, rtt: None, error=AutoReconnect('ac-7zrxalx-shard-00-02.v1mxd4q.mongodb.net:27017: [WinError 10013] Intento de acceso a un socket no permitido por sus permisos de acceso (configured timeouts: socketTimeoutMS: 20000.0ms, connectTimeoutMS: 20000.0ms)')>]>")>
Traceback (most recent call last):
  File "C:\Users\martimasxax\AppData\Local\Packages\PythonSoftwareFoundation.Python.3.12_qbz5n2kfra8p0\LocalCache\local-packages\Python312\site-packages\pymongo\pool.py", line 1020, in receive_message
    return receive_message(self, request_id, self.max_message_size)
           ^^^^^^^^^^^^^^^^^^^^^^^^^^^^^^^^^^^^^^^^^^^^^^^^^^^^^^^^
  File "C:\Users\martimasxax\AppData\Local\Packages\PythonSoftwareFoundation.Python.3.12_qbz5n2kfra8p0\LocalCache\local-packages\Python312\site-packages\pymongo\network.py", line 257, in receive_message
    length, _, response_to, op_code = _UNPACK_HEADER(_receive_data_on_socket(conn, 16, deadline))
                                                     ^^^^^^^^^^^^^^^^^^^^^^^^^^^^^^^^^^^^^^^^^^^
  File "C:\Users\martimasxax\AppData\Local\Packages\PythonSoftwareFoundation.Python.3.12_qbz5n2kfra8p0\LocalCache\local-packages\Python312\site-packages\pymongo\network.py", line 340, in _receive_data_on_socket
    chunk_length = conn.conn.recv_into(mv[bytes_read:])
                   ^^^^^^^^^^^^^^^^^^^^^^^^^^^^^^^^^^^^
  File "C:\Users\martimasxax\AppData\Local\Packages\PythonSoftwareFoundation.Python.3.12_qbz5n2kfra8p0\LocalCache\local-packages\Python312\site-packages\pymongo\pyopenssl_context.py", line 155, in recv_into
    return self._call(super().recv_into, *args, **kwargs)
           ^^^^^^^^^^^^^^^^^^^^^^^^^^^^^^^^^^^^^^^^^^^^^^
  File "C:\Users\martimasxax\AppData\Local\Packages\PythonSoftwareFoundation.Python.3.12_qbz5n2kfra8p0\LocalCache\local-packages\Python312\site-packages\pymongo\pyopenssl_context.py", line 120, in _call
    return call(*args, **kwargs)
           ^^^^^^^^^^^^^^^^^^^^^
  File "C:\Users\martimasxax\AppData\Local\Packages\PythonSoftwareFoundation.Python.3.12_qbz5n2kfra8p0\LocalCache\local-packages\Python312\site-packages\OpenSSL\SSL.py", line 2099, in recv_into
    self._raise_ssl_error(self._ssl, result)
  File "C:\Users\martimasxax\AppData\Local\Packages\PythonSoftwareFoundation.Python.3.12_qbz5n2kfra8p0\LocalCache\local-packages\Python312\site-packages\OpenSSL\SSL.py", line 1818, in _raise_ssl_error
    raise SysCallError(errno, errorcode.get(errno))
OpenSSL.SSL.SysCallError: (10054, 'WSAECONNRESET')

The above exception was the direct cause of the following exception:

Traceback (most recent call last):
  File "C:\Users\martimasxax\AppData\Local\Packages\PythonSoftwareFoundation.Python.3.12_qbz5n2kfra8p0\LocalCache\local-packages\Python312\site-packages\pymongo\change_stream.py", line 372, in try_next
    change = self._cursor._try_next(True)
             ^^^^^^^^^^^^^^^^^^^^^^^^^^^^
  File "C:\Users\martimasxax\AppData\Local\Packages\PythonSoftwareFoundation.Python.3.12_qbz5n2kfra8p0\LocalCache\local-packages\Python312\site-packages\pymongo\command_cursor.py", line 321, in _try_next
    self._refresh()
  File "C:\Users\martimasxax\AppData\Local\Packages\PythonSoftwareFoundation.Python.3.12_qbz5n2kfra8p0\LocalCache\local-packages\Python312\site-packages\pymongo\command_cursor.py", line 242, in _refresh
    self.__send_message(
  File "C:\Users\martimasxax\AppData\Local\Packages\PythonSoftwareFoundation.Python.3.12_qbz5n2kfra8p0\LocalCache\local-packages\Python312\site-packages\pymongo\command_cursor.py", line 179, in __send_message
    response = client._run_operation(
               ^^^^^^^^^^^^^^^^^^^^^^
  File "C:\Users\martimasxax\AppData\Local\Packages\PythonSoftwareFoundation.Python.3.12_qbz5n2kfra8p0\LocalCache\local-packages\Python312\site-packages\pymongo\_csot.py", line 107, in csot_wrapper
    return func(self, *args, **kwargs)
           ^^^^^^^^^^^^^^^^^^^^^^^^^^^
  File "C:\Users\martimasxax\AppData\Local\Packages\PythonSoftwareFoundation.Python.3.12_qbz5n2kfra8p0\LocalCache\local-packages\Python312\site-packages\pymongo\mongo_client.py", line 1394, in _run_operation
    return self._retryable_read(
           ^^^^^^^^^^^^^^^^^^^^^
  File "C:\Users\martimasxax\AppData\Local\Packages\PythonSoftwareFoundation.Python.3.12_qbz5n2kfra8p0\LocalCache\local-packages\Python312\site-packages\pymongo\mongo_client.py", line 1492, in _retryable_read
    return self._retry_internal(
           ^^^^^^^^^^^^^^^^^^^^^
  File "C:\Users\martimasxax\AppData\Local\Packages\PythonSoftwareFoundation.Python.3.12_qbz5n2kfra8p0\LocalCache\local-packages\Python312\site-packages\pymongo\_csot.py", line 107, in csot_wrapper
    return func(self, *args, **kwargs)
           ^^^^^^^^^^^^^^^^^^^^^^^^^^^
  File "C:\Users\martimasxax\AppData\Local\Packages\PythonSoftwareFoundation.Python.3.12_qbz5n2kfra8p0\LocalCache\local-packages\Python312\site-packages\pymongo\mongo_client.py", line 1462, in _retry_internal
    ).run()
      ^^^^^
  File "C:\Users\martimasxax\AppData\Local\Packages\PythonSoftwareFoundation.Python.3.12_qbz5n2kfra8p0\LocalCache\local-packages\Python312\site-packages\pymongo\mongo_client.py", line 2315, in run
    return self._read() if self._is_read else self._write()
           ^^^^^^^^^^^^
  File "C:\Users\martimasxax\AppData\Local\Packages\PythonSoftwareFoundation.Python.3.12_qbz5n2kfra8p0\LocalCache\local-packages\Python312\site-packages\pymongo\mongo_client.py", line 2445, in _read
    return self._func(self._session, self._server, conn, read_pref)  # type: ignore
           ^^^^^^^^^^^^^^^^^^^^^^^^^^^^^^^^^^^^^^^^^^^^^^^^^^^^^^^^
  File "C:\Users\martimasxax\AppData\Local\Packages\PythonSoftwareFoundation.Python.3.12_qbz5n2kfra8p0\LocalCache\local-packages\Python312\site-packages\pymongo\mongo_client.py", line 1390, in _cmd
    return server.run_operation(
           ^^^^^^^^^^^^^^^^^^^^^
  File "C:\Users\martimasxax\AppData\Local\Packages\PythonSoftwareFoundation.Python.3.12_qbz5n2kfra8p0\LocalCache\local-packages\Python312\site-packages\pymongo\helpers.py", line 322, in inner
    return func(*args, **kwargs)
           ^^^^^^^^^^^^^^^^^^^^^
  File "C:\Users\martimasxax\AppData\Local\Packages\PythonSoftwareFoundation.Python.3.12_qbz5n2kfra8p0\LocalCache\local-packages\Python312\site-packages\pymongo\server.py", line 148, in run_operation
    reply = conn.receive_message(request_id)
            ^^^^^^^^^^^^^^^^^^^^^^^^^^^^^^^^
  File "C:\Users\martimasxax\AppData\Local\Packages\PythonSoftwareFoundation.Python.3.12_qbz5n2kfra8p0\LocalCache\local-packages\Python312\site-packages\pymongo\pool.py", line 1022, in receive_message
    self._raise_connection_failure(error)
  File "C:\Users\martimasxax\AppData\Local\Packages\PythonSoftwareFoundation.Python.3.12_qbz5n2kfra8p0\LocalCache\local-packages\Python312\site-packages\pymongo\pool.py", line 1171, in _raise_connection_failure
    _raise_connection_failure(self.address, error, timeout_details=details)
  File "C:\Users\martimasxax\AppData\Local\Packages\PythonSoftwareFoundation.Python.3.12_qbz5n2kfra8p0\LocalCache\local-packages\Python312\site-packages\pymongo\pool.py", line 411, in _raise_connection_failure
    raise AutoReconnect(msg) from error
pymongo.errors.AutoReconnect: ac-7zrxalx-shard-00-01.v1mxd4q.mongodb.net:27017: (10054, 'WSAECONNRESET') (configured timeouts: connectTimeoutMS: 20000.0ms)

During handling of the above exception, another exception occurred:

Traceback (most recent call last):
  File "E:\Project\Back4\BN-BackEnd\config\changeStream.py", line 7, in watch_changes
    async for change in stream:
  File "C:\Users\martimasxax\AppData\Local\Packages\PythonSoftwareFoundation.Python.3.12_qbz5n2kfra8p0\LocalCache\local-packages\Python312\site-packages\motor\core.py", line 2038, in next
    doc = await self.try_next()
          ^^^^^^^^^^^^^^^^^^^^^
  File "C:\Users\martimasxax\AppData\Local\Packages\PythonSoftwareFoundation.Python.3.12_qbz5n2kfra8p0\LocalCache\local-packages\Python312\site-packages\motor\core.py", line 2079, in try_next
    return await self._framework.run_on_executor(loop, self._try_next)
           ^^^^^^^^^^^^^^^^^^^^^^^^^^^^^^^^^^^^^^^^^^^^^^^^^^^^^^^^^^^
  File "C:\Program Files\WindowsApps\PythonSoftwareFoundation.Python.3.12_3.12.1008.0_x64__qbz5n2kfra8p0\Lib\concurrent\futures\thread.py", line 58, in run
    result = self.fn(*self.args, **self.kwargs)
             ^^^^^^^^^^^^^^^^^^^^^^^^^^^^^^^^^^
  File "C:\Users\martimasxax\AppData\Local\Packages\PythonSoftwareFoundation.Python.3.12_qbz5n2kfra8p0\LocalCache\local-packages\Python312\site-packages\motor\core.py", line 1984, in _try_next
    return self.delegate.try_next()
           ^^^^^^^^^^^^^^^^^^^^^^^^
  File "C:\Users\martimasxax\AppData\Local\Packages\PythonSoftwareFoundation.Python.3.12_qbz5n2kfra8p0\LocalCache\local-packages\Python312\site-packages\pymongo\_csot.py", line 107, in csot_wrapper
    return func(self, *args, **kwargs)
           ^^^^^^^^^^^^^^^^^^^^^^^^^^^
  File "C:\Users\martimasxax\AppData\Local\Packages\PythonSoftwareFoundation.Python.3.12_qbz5n2kfra8p0\LocalCache\local-packages\Python312\site-packages\pymongo\change_stream.py", line 376, in try_next
    self._resume()
  File "C:\Users\martimasxax\AppData\Local\Packages\PythonSoftwareFoundation.Python.3.12_qbz5n2kfra8p0\LocalCache\local-packages\Python312\site-packages\pymongo\change_stream.py", line 260, in _resume
    self._cursor = self._create_cursor()
                   ^^^^^^^^^^^^^^^^^^^^^
  File "C:\Users\martimasxax\AppData\Local\Packages\PythonSoftwareFoundation.Python.3.12_qbz5n2kfra8p0\LocalCache\local-packages\Python312\site-packages\pymongo\change_stream.py", line 251, in _create_cursor
    with self._client._tmp_session(self._session, close=False) as s:
  File "C:\Program Files\WindowsApps\PythonSoftwareFoundation.Python.3.12_3.12.1008.0_x64__qbz5n2kfra8p0\Lib\contextlib.py", line 137, in __enter__
    return next(self.gen)
           ^^^^^^^^^^^^^^
  File "C:\Users\martimasxax\AppData\Local\Packages\PythonSoftwareFoundation.Python.3.12_qbz5n2kfra8p0\LocalCache\local-packages\Python312\site-packages\pymongo\mongo_client.py", line 1840, in _tmp_session
    s = self._ensure_session(session)
        ^^^^^^^^^^^^^^^^^^^^^^^^^^^^^
  File "C:\Users\martimasxax\AppData\Local\Packages\PythonSoftwareFoundation.Python.3.12_qbz5n2kfra8p0\LocalCache\local-packages\Python312\site-packages\pymongo\mongo_client.py", line 1823, in _ensure_session
    return self.__start_session(True, causal_consistency=False)
           ^^^^^^^^^^^^^^^^^^^^^^^^^^^^^^^^^^^^^^^^^^^^^^^^^^^^
  File "C:\Users\martimasxax\AppData\Local\Packages\PythonSoftwareFoundation.Python.3.12_qbz5n2kfra8p0\LocalCache\local-packages\Python312\site-packages\pymongo\mongo_client.py", line 1766, in __start_session
    self._topology._check_implicit_session_support()
  File "C:\Users\martimasxax\AppData\Local\Packages\PythonSoftwareFoundation.Python.3.12_qbz5n2kfra8p0\LocalCache\local-packages\Python312\site-packages\pymongo\topology.py", line 573, in _check_implicit_session_support
    self._check_session_support()
  File "C:\Users\martimasxax\AppData\Local\Packages\PythonSoftwareFoundation.Python.3.12_qbz5n2kfra8p0\LocalCache\local-packages\Python312\site-packages\pymongo\topology.py", line 589, in _check_session_support
    self._select_servers_loop(
  File "C:\Users\martimasxax\AppData\Local\Packages\PythonSoftwareFoundation.Python.3.12_qbz5n2kfra8p0\LocalCache\local-packages\Python312\site-packages\pymongo\topology.py", line 259, in _select_servers_loop
    raise ServerSelectionTimeoutError(
pymongo.errors.ServerSelectionTimeoutError: ac-7zrxalx-shard-00-00.v1mxd4q.mongodb.net:27017: [WinError 10013] Intento de acceso a un socket no permitido por sus permisos de acceso (configured timeouts: socketTimeoutMS: 20000.0ms, connectTimeoutMS: 20000.0ms),ac-7zrxalx-shard-00-02.v1mxd4q.mongodb.net:27017: [WinError 10013] Intento de acceso a un socket no permitido por sus permisos de acceso (configured timeouts: socketTimeoutMS: 20000.0ms, connectTimeoutMS: 20000.0ms),ac-7zrxalx-shard-00-01.v1mxd4q.mongodb.net:27017: [WinError 10013] Intento de acceso a un socket no permitido por sus permisos de acceso (configured timeouts: socketTimeoutMS: 20000.0ms, connectTimeoutMS: 20000.0ms), Timeout: 30s, Topology Description: <TopologyDescription id: 664e0a315470cf5cd6615b5a, topology_type: ReplicaSetNoPrimary, servers: [<ServerDescription ('ac-7zrxalx-shard-00-00.v1mxd4q.mongodb.net', 27017) server_type: Unknown, rtt: None, error=AutoReconnect('ac-7zrxalx-shard-00-00.v1mxd4q.mongodb.net:27017: [WinError 10013] Intento de acceso a un socket no permitido por sus permisos de acceso (configured timeouts: socketTimeoutMS: 20000.0ms, connectTimeoutMS: 20000.0ms)')>, <ServerDescription ('ac-7zrxalx-shard-00-01.v1mxd4q.mongodb.net', 27017) server_type: Unknown, rtt: None, error=AutoReconnect('ac-7zrxalx-shard-00-01.v1mxd4q.mongodb.net:27017: [WinError 10013] Intento de acceso a un socket no permitido por sus permisos de acceso (configured timeouts: socketTimeoutMS: 20000.0ms, connectTimeoutMS: 20000.0ms)')>, <ServerDescription ('ac-7zrxalx-shard-00-02.v1mxd4q.mongodb.net', 27017) server_type: Unknown, rtt: None, error=AutoReconnect('ac-7zrxalx-shard-00-02.v1mxd4q.mongodb.net:27017: [WinError 10013] Intento de acceso a un socket no permitido por sus permisos de acceso (configured timeouts: socketTimeoutMS: 20000.0ms, connectTimeoutMS: 20000.0ms)')>]>
INFO:root:2024-05-22 17:34:40.786563 - Login failed - Incorrect username: marti
INFO:root:2024-05-22 17:35:02.680001 - Login failed - Incorrect username: marti
INFO:root:2024-05-22 17:35:04.850324 - Login failed - Incorrect username: marti
INFO:root:2024-05-22 17:35:05.470309 - Login failed - Incorrect username: marti
ERROR:asyncio:Task exception was never retrieved
future: <Task finished name='Task-3' coro=<watch_changes() done, defined at e:\Project\Back4\BN-BackEnd\config\changeStream.py:5> exception=ServerSelectionTimeoutError("ac-7zrxalx-shard-00-02.v1mxd4q.mongodb.net:27017: [Errno 11001] getaddrinfo failed (configured timeouts: socketTimeoutMS: 20000.0ms, connectTimeoutMS: 20000.0ms),ac-7zrxalx-shard-00-01.v1mxd4q.mongodb.net:27017: [Errno 11001] getaddrinfo failed (configured timeouts: socketTimeoutMS: 20000.0ms, connectTimeoutMS: 20000.0ms),ac-7zrxalx-shard-00-00.v1mxd4q.mongodb.net:27017: [Errno 11001] getaddrinfo failed (configured timeouts: socketTimeoutMS: 20000.0ms, connectTimeoutMS: 20000.0ms), Timeout: 30s, Topology Description: <TopologyDescription id: 664e388fb7c828e04f2bf489, topology_type: ReplicaSetNoPrimary, servers: [<ServerDescription ('ac-7zrxalx-shard-00-00.v1mxd4q.mongodb.net', 27017) server_type: Unknown, rtt: None, error=AutoReconnect('ac-7zrxalx-shard-00-00.v1mxd4q.mongodb.net:27017: [Errno 11001] getaddrinfo failed (configured timeouts: socketTimeoutMS: 20000.0ms, connectTimeoutMS: 20000.0ms)')>, <ServerDescription ('ac-7zrxalx-shard-00-01.v1mxd4q.mongodb.net', 27017) server_type: Unknown, rtt: None, error=AutoReconnect('ac-7zrxalx-shard-00-01.v1mxd4q.mongodb.net:27017: [Errno 11001] getaddrinfo failed (configured timeouts: socketTimeoutMS: 20000.0ms, connectTimeoutMS: 20000.0ms)')>, <ServerDescription ('ac-7zrxalx-shard-00-02.v1mxd4q.mongodb.net', 27017) server_type: Unknown, rtt: None, error=AutoReconnect('ac-7zrxalx-shard-00-02.v1mxd4q.mongodb.net:27017: [Errno 11001] getaddrinfo failed (configured timeouts: socketTimeoutMS: 20000.0ms, connectTimeoutMS: 20000.0ms)')>]>")>
Traceback (most recent call last):
  File "C:\Users\martimasxax\AppData\Local\Packages\PythonSoftwareFoundation.Python.3.12_qbz5n2kfra8p0\LocalCache\local-packages\Python312\site-packages\pymongo\pool.py", line 1020, in receive_message
    return receive_message(self, request_id, self.max_message_size)
           ^^^^^^^^^^^^^^^^^^^^^^^^^^^^^^^^^^^^^^^^^^^^^^^^^^^^^^^^
  File "C:\Users\martimasxax\AppData\Local\Packages\PythonSoftwareFoundation.Python.3.12_qbz5n2kfra8p0\LocalCache\local-packages\Python312\site-packages\pymongo\network.py", line 257, in receive_message
    length, _, response_to, op_code = _UNPACK_HEADER(_receive_data_on_socket(conn, 16, deadline))
                                                     ^^^^^^^^^^^^^^^^^^^^^^^^^^^^^^^^^^^^^^^^^^^
  File "C:\Users\martimasxax\AppData\Local\Packages\PythonSoftwareFoundation.Python.3.12_qbz5n2kfra8p0\LocalCache\local-packages\Python312\site-packages\pymongo\network.py", line 340, in _receive_data_on_socket
    chunk_length = conn.conn.recv_into(mv[bytes_read:])
                   ^^^^^^^^^^^^^^^^^^^^^^^^^^^^^^^^^^^^
  File "C:\Users\martimasxax\AppData\Local\Packages\PythonSoftwareFoundation.Python.3.12_qbz5n2kfra8p0\LocalCache\local-packages\Python312\site-packages\pymongo\pyopenssl_context.py", line 155, in recv_into
    return self._call(super().recv_into, *args, **kwargs)
           ^^^^^^^^^^^^^^^^^^^^^^^^^^^^^^^^^^^^^^^^^^^^^^
  File "C:\Users\martimasxax\AppData\Local\Packages\PythonSoftwareFoundation.Python.3.12_qbz5n2kfra8p0\LocalCache\local-packages\Python312\site-packages\pymongo\pyopenssl_context.py", line 120, in _call
    return call(*args, **kwargs)
           ^^^^^^^^^^^^^^^^^^^^^
  File "C:\Users\martimasxax\AppData\Local\Packages\PythonSoftwareFoundation.Python.3.12_qbz5n2kfra8p0\LocalCache\local-packages\Python312\site-packages\OpenSSL\SSL.py", line 2099, in recv_into
    self._raise_ssl_error(self._ssl, result)
  File "C:\Users\martimasxax\AppData\Local\Packages\PythonSoftwareFoundation.Python.3.12_qbz5n2kfra8p0\LocalCache\local-packages\Python312\site-packages\OpenSSL\SSL.py", line 1818, in _raise_ssl_error
    raise SysCallError(errno, errorcode.get(errno))
OpenSSL.SSL.SysCallError: (10054, 'WSAECONNRESET')

The above exception was the direct cause of the following exception:

Traceback (most recent call last):
  File "C:\Users\martimasxax\AppData\Local\Packages\PythonSoftwareFoundation.Python.3.12_qbz5n2kfra8p0\LocalCache\local-packages\Python312\site-packages\pymongo\change_stream.py", line 372, in try_next
    change = self._cursor._try_next(True)
             ^^^^^^^^^^^^^^^^^^^^^^^^^^^^
  File "C:\Users\martimasxax\AppData\Local\Packages\PythonSoftwareFoundation.Python.3.12_qbz5n2kfra8p0\LocalCache\local-packages\Python312\site-packages\pymongo\command_cursor.py", line 321, in _try_next
    self._refresh()
  File "C:\Users\martimasxax\AppData\Local\Packages\PythonSoftwareFoundation.Python.3.12_qbz5n2kfra8p0\LocalCache\local-packages\Python312\site-packages\pymongo\command_cursor.py", line 242, in _refresh
    self.__send_message(
  File "C:\Users\martimasxax\AppData\Local\Packages\PythonSoftwareFoundation.Python.3.12_qbz5n2kfra8p0\LocalCache\local-packages\Python312\site-packages\pymongo\command_cursor.py", line 179, in __send_message
    response = client._run_operation(
               ^^^^^^^^^^^^^^^^^^^^^^
  File "C:\Users\martimasxax\AppData\Local\Packages\PythonSoftwareFoundation.Python.3.12_qbz5n2kfra8p0\LocalCache\local-packages\Python312\site-packages\pymongo\_csot.py", line 107, in csot_wrapper
    return func(self, *args, **kwargs)
           ^^^^^^^^^^^^^^^^^^^^^^^^^^^
  File "C:\Users\martimasxax\AppData\Local\Packages\PythonSoftwareFoundation.Python.3.12_qbz5n2kfra8p0\LocalCache\local-packages\Python312\site-packages\pymongo\mongo_client.py", line 1394, in _run_operation
    return self._retryable_read(
           ^^^^^^^^^^^^^^^^^^^^^
  File "C:\Users\martimasxax\AppData\Local\Packages\PythonSoftwareFoundation.Python.3.12_qbz5n2kfra8p0\LocalCache\local-packages\Python312\site-packages\pymongo\mongo_client.py", line 1492, in _retryable_read
    return self._retry_internal(
           ^^^^^^^^^^^^^^^^^^^^^
  File "C:\Users\martimasxax\AppData\Local\Packages\PythonSoftwareFoundation.Python.3.12_qbz5n2kfra8p0\LocalCache\local-packages\Python312\site-packages\pymongo\_csot.py", line 107, in csot_wrapper
    return func(self, *args, **kwargs)
           ^^^^^^^^^^^^^^^^^^^^^^^^^^^
  File "C:\Users\martimasxax\AppData\Local\Packages\PythonSoftwareFoundation.Python.3.12_qbz5n2kfra8p0\LocalCache\local-packages\Python312\site-packages\pymongo\mongo_client.py", line 1462, in _retry_internal
    ).run()
      ^^^^^
  File "C:\Users\martimasxax\AppData\Local\Packages\PythonSoftwareFoundation.Python.3.12_qbz5n2kfra8p0\LocalCache\local-packages\Python312\site-packages\pymongo\mongo_client.py", line 2315, in run
    return self._read() if self._is_read else self._write()
           ^^^^^^^^^^^^
  File "C:\Users\martimasxax\AppData\Local\Packages\PythonSoftwareFoundation.Python.3.12_qbz5n2kfra8p0\LocalCache\local-packages\Python312\site-packages\pymongo\mongo_client.py", line 2445, in _read
    return self._func(self._session, self._server, conn, read_pref)  # type: ignore
           ^^^^^^^^^^^^^^^^^^^^^^^^^^^^^^^^^^^^^^^^^^^^^^^^^^^^^^^^
  File "C:\Users\martimasxax\AppData\Local\Packages\PythonSoftwareFoundation.Python.3.12_qbz5n2kfra8p0\LocalCache\local-packages\Python312\site-packages\pymongo\mongo_client.py", line 1390, in _cmd
    return server.run_operation(
           ^^^^^^^^^^^^^^^^^^^^^
  File "C:\Users\martimasxax\AppData\Local\Packages\PythonSoftwareFoundation.Python.3.12_qbz5n2kfra8p0\LocalCache\local-packages\Python312\site-packages\pymongo\helpers.py", line 322, in inner
    return func(*args, **kwargs)
           ^^^^^^^^^^^^^^^^^^^^^
  File "C:\Users\martimasxax\AppData\Local\Packages\PythonSoftwareFoundation.Python.3.12_qbz5n2kfra8p0\LocalCache\local-packages\Python312\site-packages\pymongo\server.py", line 148, in run_operation
    reply = conn.receive_message(request_id)
            ^^^^^^^^^^^^^^^^^^^^^^^^^^^^^^^^
  File "C:\Users\martimasxax\AppData\Local\Packages\PythonSoftwareFoundation.Python.3.12_qbz5n2kfra8p0\LocalCache\local-packages\Python312\site-packages\pymongo\pool.py", line 1022, in receive_message
    self._raise_connection_failure(error)
  File "C:\Users\martimasxax\AppData\Local\Packages\PythonSoftwareFoundation.Python.3.12_qbz5n2kfra8p0\LocalCache\local-packages\Python312\site-packages\pymongo\pool.py", line 1171, in _raise_connection_failure
    _raise_connection_failure(self.address, error, timeout_details=details)
  File "C:\Users\martimasxax\AppData\Local\Packages\PythonSoftwareFoundation.Python.3.12_qbz5n2kfra8p0\LocalCache\local-packages\Python312\site-packages\pymongo\pool.py", line 411, in _raise_connection_failure
    raise AutoReconnect(msg) from error
pymongo.errors.AutoReconnect: ac-7zrxalx-shard-00-01.v1mxd4q.mongodb.net:27017: (10054, 'WSAECONNRESET') (configured timeouts: connectTimeoutMS: 20000.0ms)

During handling of the above exception, another exception occurred:

Traceback (most recent call last):
  File "e:\Project\Back4\BN-BackEnd\config\changeStream.py", line 7, in watch_changes
    async for change in stream:
  File "C:\Users\martimasxax\AppData\Local\Packages\PythonSoftwareFoundation.Python.3.12_qbz5n2kfra8p0\LocalCache\local-packages\Python312\site-packages\motor\core.py", line 2038, in next
    doc = await self.try_next()
          ^^^^^^^^^^^^^^^^^^^^^
  File "C:\Users\martimasxax\AppData\Local\Packages\PythonSoftwareFoundation.Python.3.12_qbz5n2kfra8p0\LocalCache\local-packages\Python312\site-packages\motor\core.py", line 2079, in try_next
    return await self._framework.run_on_executor(loop, self._try_next)
           ^^^^^^^^^^^^^^^^^^^^^^^^^^^^^^^^^^^^^^^^^^^^^^^^^^^^^^^^^^^
  File "C:\Program Files\WindowsApps\PythonSoftwareFoundation.Python.3.12_3.12.1008.0_x64__qbz5n2kfra8p0\Lib\concurrent\futures\thread.py", line 58, in run
    result = self.fn(*self.args, **self.kwargs)
             ^^^^^^^^^^^^^^^^^^^^^^^^^^^^^^^^^^
  File "C:\Users\martimasxax\AppData\Local\Packages\PythonSoftwareFoundation.Python.3.12_qbz5n2kfra8p0\LocalCache\local-packages\Python312\site-packages\motor\core.py", line 1984, in _try_next
    return self.delegate.try_next()
           ^^^^^^^^^^^^^^^^^^^^^^^^
  File "C:\Users\martimasxax\AppData\Local\Packages\PythonSoftwareFoundation.Python.3.12_qbz5n2kfra8p0\LocalCache\local-packages\Python312\site-packages\pymongo\_csot.py", line 107, in csot_wrapper
    return func(self, *args, **kwargs)
           ^^^^^^^^^^^^^^^^^^^^^^^^^^^
  File "C:\Users\martimasxax\AppData\Local\Packages\PythonSoftwareFoundation.Python.3.12_qbz5n2kfra8p0\LocalCache\local-packages\Python312\site-packages\pymongo\change_stream.py", line 376, in try_next
    self._resume()
  File "C:\Users\martimasxax\AppData\Local\Packages\PythonSoftwareFoundation.Python.3.12_qbz5n2kfra8p0\LocalCache\local-packages\Python312\site-packages\pymongo\change_stream.py", line 260, in _resume
    self._cursor = self._create_cursor()
                   ^^^^^^^^^^^^^^^^^^^^^
  File "C:\Users\martimasxax\AppData\Local\Packages\PythonSoftwareFoundation.Python.3.12_qbz5n2kfra8p0\LocalCache\local-packages\Python312\site-packages\pymongo\change_stream.py", line 252, in _create_cursor
    return self._run_aggregation_cmd(session=s, explicit_session=self._session is not None)
           ^^^^^^^^^^^^^^^^^^^^^^^^^^^^^^^^^^^^^^^^^^^^^^^^^^^^^^^^^^^^^^^^^^^^^^^^^^^^^^^^
  File "C:\Users\martimasxax\AppData\Local\Packages\PythonSoftwareFoundation.Python.3.12_qbz5n2kfra8p0\LocalCache\local-packages\Python312\site-packages\pymongo\change_stream.py", line 246, in _run_aggregation_cmd
    return self._client._retryable_read(
           ^^^^^^^^^^^^^^^^^^^^^^^^^^^^^
  File "C:\Users\martimasxax\AppData\Local\Packages\PythonSoftwareFoundation.Python.3.12_qbz5n2kfra8p0\LocalCache\local-packages\Python312\site-packages\pymongo\mongo_client.py", line 1492, in _retryable_read
    return self._retry_internal(
           ^^^^^^^^^^^^^^^^^^^^^
  File "C:\Users\martimasxax\AppData\Local\Packages\PythonSoftwareFoundation.Python.3.12_qbz5n2kfra8p0\LocalCache\local-packages\Python312\site-packages\pymongo\_csot.py", line 107, in csot_wrapper
    return func(self, *args, **kwargs)
           ^^^^^^^^^^^^^^^^^^^^^^^^^^^
  File "C:\Users\martimasxax\AppData\Local\Packages\PythonSoftwareFoundation.Python.3.12_qbz5n2kfra8p0\LocalCache\local-packages\Python312\site-packages\pymongo\mongo_client.py", line 1462, in _retry_internal
    ).run()
      ^^^^^
  File "C:\Users\martimasxax\AppData\Local\Packages\PythonSoftwareFoundation.Python.3.12_qbz5n2kfra8p0\LocalCache\local-packages\Python312\site-packages\pymongo\mongo_client.py", line 2315, in run
    return self._read() if self._is_read else self._write()
           ^^^^^^^^^^^^
  File "C:\Users\martimasxax\AppData\Local\Packages\PythonSoftwareFoundation.Python.3.12_qbz5n2kfra8p0\LocalCache\local-packages\Python312\site-packages\pymongo\mongo_client.py", line 2437, in _read
    self._server = self._get_server()
                   ^^^^^^^^^^^^^^^^^^
  File "C:\Users\martimasxax\AppData\Local\Packages\PythonSoftwareFoundation.Python.3.12_qbz5n2kfra8p0\LocalCache\local-packages\Python312\site-packages\pymongo\mongo_client.py", line 2400, in _get_server
    return self._client._select_server(
           ^^^^^^^^^^^^^^^^^^^^^^^^^^^^
  File "C:\Users\martimasxax\AppData\Local\Packages\PythonSoftwareFoundation.Python.3.12_qbz5n2kfra8p0\LocalCache\local-packages\Python312\site-packages\pymongo\mongo_client.py", line 1303, in _select_server
    server = topology.select_server(server_selector)
             ^^^^^^^^^^^^^^^^^^^^^^^^^^^^^^^^^^^^^^^
  File "C:\Users\martimasxax\AppData\Local\Packages\PythonSoftwareFoundation.Python.3.12_qbz5n2kfra8p0\LocalCache\local-packages\Python312\site-packages\pymongo\topology.py", line 302, in select_server
    server = self._select_server(selector, server_selection_timeout, address)
             ^^^^^^^^^^^^^^^^^^^^^^^^^^^^^^^^^^^^^^^^^^^^^^^^^^^^^^^^^^^^^^^^
  File "C:\Users\martimasxax\AppData\Local\Packages\PythonSoftwareFoundation.Python.3.12_qbz5n2kfra8p0\LocalCache\local-packages\Python312\site-packages\pymongo\topology.py", line 286, in _select_server
    servers = self.select_servers(selector, server_selection_timeout, address)
              ^^^^^^^^^^^^^^^^^^^^^^^^^^^^^^^^^^^^^^^^^^^^^^^^^^^^^^^^^^^^^^^^
  File "C:\Users\martimasxax\AppData\Local\Packages\PythonSoftwareFoundation.Python.3.12_qbz5n2kfra8p0\LocalCache\local-packages\Python312\site-packages\pymongo\topology.py", line 237, in select_servers
    server_descriptions = self._select_servers_loop(selector, server_timeout, address)
                          ^^^^^^^^^^^^^^^^^^^^^^^^^^^^^^^^^^^^^^^^^^^^^^^^^^^^^^^^^^^^
  File "C:\Users\martimasxax\AppData\Local\Packages\PythonSoftwareFoundation.Python.3.12_qbz5n2kfra8p0\LocalCache\local-packages\Python312\site-packages\pymongo\topology.py", line 259, in _select_servers_loop
    raise ServerSelectionTimeoutError(
pymongo.errors.ServerSelectionTimeoutError: ac-7zrxalx-shard-00-02.v1mxd4q.mongodb.net:27017: [Errno 11001] getaddrinfo failed (configured timeouts: socketTimeoutMS: 20000.0ms, connectTimeoutMS: 20000.0ms),ac-7zrxalx-shard-00-01.v1mxd4q.mongodb.net:27017: [Errno 11001] getaddrinfo failed (configured timeouts: socketTimeoutMS: 20000.0ms, connectTimeoutMS: 20000.0ms),ac-7zrxalx-shard-00-00.v1mxd4q.mongodb.net:27017: [Errno 11001] getaddrinfo failed (configured timeouts: socketTimeoutMS: 20000.0ms, connectTimeoutMS: 20000.0ms), Timeout: 30s, Topology Description: <TopologyDescription id: 664e388fb7c828e04f2bf489, topology_type: ReplicaSetNoPrimary, servers: [<ServerDescription ('ac-7zrxalx-shard-00-00.v1mxd4q.mongodb.net', 27017) server_type: Unknown, rtt: None, error=AutoReconnect('ac-7zrxalx-shard-00-00.v1mxd4q.mongodb.net:27017: [Errno 11001] getaddrinfo failed (configured timeouts: socketTimeoutMS: 20000.0ms, connectTimeoutMS: 20000.0ms)')>, <ServerDescription ('ac-7zrxalx-shard-00-01.v1mxd4q.mongodb.net', 27017) server_type: Unknown, rtt: None, error=AutoReconnect('ac-7zrxalx-shard-00-01.v1mxd4q.mongodb.net:27017: [Errno 11001] getaddrinfo failed (configured timeouts: socketTimeoutMS: 20000.0ms, connectTimeoutMS: 20000.0ms)')>, <ServerDescription ('ac-7zrxalx-shard-00-02.v1mxd4q.mongodb.net', 27017) server_type: Unknown, rtt: None, error=AutoReconnect('ac-7zrxalx-shard-00-02.v1mxd4q.mongodb.net:27017: [Errno 11001] getaddrinfo failed (configured timeouts: socketTimeoutMS: 20000.0ms, connectTimeoutMS: 20000.0ms)')>]>
ERROR:asyncio:Task exception was never retrieved
future: <Task finished name='Task-3' coro=<watch_changes() done, defined at E:\Project\Back4\BN-BackEnd\config\changeStream.py:5> exception=ServerSelectionTimeoutError("ac-7zrxalx-shard-00-01.v1mxd4q.mongodb.net:27017: [Errno 11001] getaddrinfo failed (configured timeouts: socketTimeoutMS: 20000.0ms, connectTimeoutMS: 20000.0ms),ac-7zrxalx-shard-00-00.v1mxd4q.mongodb.net:27017: [Errno 11001] getaddrinfo failed (configured timeouts: socketTimeoutMS: 20000.0ms, connectTimeoutMS: 20000.0ms),ac-7zrxalx-shard-00-02.v1mxd4q.mongodb.net:27017: [Errno 11001] getaddrinfo failed (configured timeouts: socketTimeoutMS: 20000.0ms, connectTimeoutMS: 20000.0ms), Timeout: 30s, Topology Description: <TopologyDescription id: 664e38986dd1f182d608b9d8, topology_type: ReplicaSetNoPrimary, servers: [<ServerDescription ('ac-7zrxalx-shard-00-00.v1mxd4q.mongodb.net', 27017) server_type: Unknown, rtt: None, error=AutoReconnect('ac-7zrxalx-shard-00-00.v1mxd4q.mongodb.net:27017: [Errno 11001] getaddrinfo failed (configured timeouts: socketTimeoutMS: 20000.0ms, connectTimeoutMS: 20000.0ms)')>, <ServerDescription ('ac-7zrxalx-shard-00-01.v1mxd4q.mongodb.net', 27017) server_type: Unknown, rtt: None, error=AutoReconnect('ac-7zrxalx-shard-00-01.v1mxd4q.mongodb.net:27017: [Errno 11001] getaddrinfo failed (configured timeouts: socketTimeoutMS: 20000.0ms, connectTimeoutMS: 20000.0ms)')>, <ServerDescription ('ac-7zrxalx-shard-00-02.v1mxd4q.mongodb.net', 27017) server_type: Unknown, rtt: None, error=AutoReconnect('ac-7zrxalx-shard-00-02.v1mxd4q.mongodb.net:27017: [Errno 11001] getaddrinfo failed (configured timeouts: socketTimeoutMS: 20000.0ms, connectTimeoutMS: 20000.0ms)')>]>")>
Traceback (most recent call last):
  File "C:\Users\martimasxax\AppData\Local\Packages\PythonSoftwareFoundation.Python.3.12_qbz5n2kfra8p0\LocalCache\local-packages\Python312\site-packages\pymongo\pool.py", line 1020, in receive_message
    return receive_message(self, request_id, self.max_message_size)
           ^^^^^^^^^^^^^^^^^^^^^^^^^^^^^^^^^^^^^^^^^^^^^^^^^^^^^^^^
  File "C:\Users\martimasxax\AppData\Local\Packages\PythonSoftwareFoundation.Python.3.12_qbz5n2kfra8p0\LocalCache\local-packages\Python312\site-packages\pymongo\network.py", line 257, in receive_message
    length, _, response_to, op_code = _UNPACK_HEADER(_receive_data_on_socket(conn, 16, deadline))
                                                     ^^^^^^^^^^^^^^^^^^^^^^^^^^^^^^^^^^^^^^^^^^^
  File "C:\Users\martimasxax\AppData\Local\Packages\PythonSoftwareFoundation.Python.3.12_qbz5n2kfra8p0\LocalCache\local-packages\Python312\site-packages\pymongo\network.py", line 340, in _receive_data_on_socket
    chunk_length = conn.conn.recv_into(mv[bytes_read:])
                   ^^^^^^^^^^^^^^^^^^^^^^^^^^^^^^^^^^^^
  File "C:\Users\martimasxax\AppData\Local\Packages\PythonSoftwareFoundation.Python.3.12_qbz5n2kfra8p0\LocalCache\local-packages\Python312\site-packages\pymongo\pyopenssl_context.py", line 155, in recv_into
    return self._call(super().recv_into, *args, **kwargs)
           ^^^^^^^^^^^^^^^^^^^^^^^^^^^^^^^^^^^^^^^^^^^^^^
  File "C:\Users\martimasxax\AppData\Local\Packages\PythonSoftwareFoundation.Python.3.12_qbz5n2kfra8p0\LocalCache\local-packages\Python312\site-packages\pymongo\pyopenssl_context.py", line 120, in _call
    return call(*args, **kwargs)
           ^^^^^^^^^^^^^^^^^^^^^
  File "C:\Users\martimasxax\AppData\Local\Packages\PythonSoftwareFoundation.Python.3.12_qbz5n2kfra8p0\LocalCache\local-packages\Python312\site-packages\OpenSSL\SSL.py", line 2099, in recv_into
    self._raise_ssl_error(self._ssl, result)
  File "C:\Users\martimasxax\AppData\Local\Packages\PythonSoftwareFoundation.Python.3.12_qbz5n2kfra8p0\LocalCache\local-packages\Python312\site-packages\OpenSSL\SSL.py", line 1818, in _raise_ssl_error
    raise SysCallError(errno, errorcode.get(errno))
OpenSSL.SSL.SysCallError: (10054, 'WSAECONNRESET')

The above exception was the direct cause of the following exception:

Traceback (most recent call last):
  File "C:\Users\martimasxax\AppData\Local\Packages\PythonSoftwareFoundation.Python.3.12_qbz5n2kfra8p0\LocalCache\local-packages\Python312\site-packages\pymongo\change_stream.py", line 372, in try_next
    change = self._cursor._try_next(True)
             ^^^^^^^^^^^^^^^^^^^^^^^^^^^^
  File "C:\Users\martimasxax\AppData\Local\Packages\PythonSoftwareFoundation.Python.3.12_qbz5n2kfra8p0\LocalCache\local-packages\Python312\site-packages\pymongo\command_cursor.py", line 321, in _try_next
    self._refresh()
  File "C:\Users\martimasxax\AppData\Local\Packages\PythonSoftwareFoundation.Python.3.12_qbz5n2kfra8p0\LocalCache\local-packages\Python312\site-packages\pymongo\command_cursor.py", line 242, in _refresh
    self.__send_message(
  File "C:\Users\martimasxax\AppData\Local\Packages\PythonSoftwareFoundation.Python.3.12_qbz5n2kfra8p0\LocalCache\local-packages\Python312\site-packages\pymongo\command_cursor.py", line 179, in __send_message
    response = client._run_operation(
               ^^^^^^^^^^^^^^^^^^^^^^
  File "C:\Users\martimasxax\AppData\Local\Packages\PythonSoftwareFoundation.Python.3.12_qbz5n2kfra8p0\LocalCache\local-packages\Python312\site-packages\pymongo\_csot.py", line 107, in csot_wrapper
    return func(self, *args, **kwargs)
           ^^^^^^^^^^^^^^^^^^^^^^^^^^^
  File "C:\Users\martimasxax\AppData\Local\Packages\PythonSoftwareFoundation.Python.3.12_qbz5n2kfra8p0\LocalCache\local-packages\Python312\site-packages\pymongo\mongo_client.py", line 1394, in _run_operation
    return self._retryable_read(
           ^^^^^^^^^^^^^^^^^^^^^
  File "C:\Users\martimasxax\AppData\Local\Packages\PythonSoftwareFoundation.Python.3.12_qbz5n2kfra8p0\LocalCache\local-packages\Python312\site-packages\pymongo\mongo_client.py", line 1492, in _retryable_read
    return self._retry_internal(
           ^^^^^^^^^^^^^^^^^^^^^
  File "C:\Users\martimasxax\AppData\Local\Packages\PythonSoftwareFoundation.Python.3.12_qbz5n2kfra8p0\LocalCache\local-packages\Python312\site-packages\pymongo\_csot.py", line 107, in csot_wrapper
    return func(self, *args, **kwargs)
           ^^^^^^^^^^^^^^^^^^^^^^^^^^^
  File "C:\Users\martimasxax\AppData\Local\Packages\PythonSoftwareFoundation.Python.3.12_qbz5n2kfra8p0\LocalCache\local-packages\Python312\site-packages\pymongo\mongo_client.py", line 1462, in _retry_internal
    ).run()
      ^^^^^
  File "C:\Users\martimasxax\AppData\Local\Packages\PythonSoftwareFoundation.Python.3.12_qbz5n2kfra8p0\LocalCache\local-packages\Python312\site-packages\pymongo\mongo_client.py", line 2315, in run
    return self._read() if self._is_read else self._write()
           ^^^^^^^^^^^^
  File "C:\Users\martimasxax\AppData\Local\Packages\PythonSoftwareFoundation.Python.3.12_qbz5n2kfra8p0\LocalCache\local-packages\Python312\site-packages\pymongo\mongo_client.py", line 2445, in _read
    return self._func(self._session, self._server, conn, read_pref)  # type: ignore
           ^^^^^^^^^^^^^^^^^^^^^^^^^^^^^^^^^^^^^^^^^^^^^^^^^^^^^^^^
  File "C:\Users\martimasxax\AppData\Local\Packages\PythonSoftwareFoundation.Python.3.12_qbz5n2kfra8p0\LocalCache\local-packages\Python312\site-packages\pymongo\mongo_client.py", line 1390, in _cmd
    return server.run_operation(
           ^^^^^^^^^^^^^^^^^^^^^
  File "C:\Users\martimasxax\AppData\Local\Packages\PythonSoftwareFoundation.Python.3.12_qbz5n2kfra8p0\LocalCache\local-packages\Python312\site-packages\pymongo\helpers.py", line 322, in inner
    return func(*args, **kwargs)
           ^^^^^^^^^^^^^^^^^^^^^
  File "C:\Users\martimasxax\AppData\Local\Packages\PythonSoftwareFoundation.Python.3.12_qbz5n2kfra8p0\LocalCache\local-packages\Python312\site-packages\pymongo\server.py", line 148, in run_operation
    reply = conn.receive_message(request_id)
            ^^^^^^^^^^^^^^^^^^^^^^^^^^^^^^^^
  File "C:\Users\martimasxax\AppData\Local\Packages\PythonSoftwareFoundation.Python.3.12_qbz5n2kfra8p0\LocalCache\local-packages\Python312\site-packages\pymongo\pool.py", line 1022, in receive_message
    self._raise_connection_failure(error)
  File "C:\Users\martimasxax\AppData\Local\Packages\PythonSoftwareFoundation.Python.3.12_qbz5n2kfra8p0\LocalCache\local-packages\Python312\site-packages\pymongo\pool.py", line 1171, in _raise_connection_failure
    _raise_connection_failure(self.address, error, timeout_details=details)
  File "C:\Users\martimasxax\AppData\Local\Packages\PythonSoftwareFoundation.Python.3.12_qbz5n2kfra8p0\LocalCache\local-packages\Python312\site-packages\pymongo\pool.py", line 411, in _raise_connection_failure
    raise AutoReconnect(msg) from error
pymongo.errors.AutoReconnect: ac-7zrxalx-shard-00-01.v1mxd4q.mongodb.net:27017: (10054, 'WSAECONNRESET') (configured timeouts: connectTimeoutMS: 20000.0ms)

During handling of the above exception, another exception occurred:

Traceback (most recent call last):
  File "E:\Project\Back4\BN-BackEnd\config\changeStream.py", line 7, in watch_changes
    async for change in stream:
  File "C:\Users\martimasxax\AppData\Local\Packages\PythonSoftwareFoundation.Python.3.12_qbz5n2kfra8p0\LocalCache\local-packages\Python312\site-packages\motor\core.py", line 2038, in next
    doc = await self.try_next()
          ^^^^^^^^^^^^^^^^^^^^^
  File "C:\Users\martimasxax\AppData\Local\Packages\PythonSoftwareFoundation.Python.3.12_qbz5n2kfra8p0\LocalCache\local-packages\Python312\site-packages\motor\core.py", line 2079, in try_next
    return await self._framework.run_on_executor(loop, self._try_next)
           ^^^^^^^^^^^^^^^^^^^^^^^^^^^^^^^^^^^^^^^^^^^^^^^^^^^^^^^^^^^
  File "C:\Program Files\WindowsApps\PythonSoftwareFoundation.Python.3.12_3.12.1008.0_x64__qbz5n2kfra8p0\Lib\concurrent\futures\thread.py", line 58, in run
    result = self.fn(*self.args, **self.kwargs)
             ^^^^^^^^^^^^^^^^^^^^^^^^^^^^^^^^^^
  File "C:\Users\martimasxax\AppData\Local\Packages\PythonSoftwareFoundation.Python.3.12_qbz5n2kfra8p0\LocalCache\local-packages\Python312\site-packages\motor\core.py", line 1984, in _try_next
    return self.delegate.try_next()
           ^^^^^^^^^^^^^^^^^^^^^^^^
  File "C:\Users\martimasxax\AppData\Local\Packages\PythonSoftwareFoundation.Python.3.12_qbz5n2kfra8p0\LocalCache\local-packages\Python312\site-packages\pymongo\_csot.py", line 107, in csot_wrapper
    return func(self, *args, **kwargs)
           ^^^^^^^^^^^^^^^^^^^^^^^^^^^
  File "C:\Users\martimasxax\AppData\Local\Packages\PythonSoftwareFoundation.Python.3.12_qbz5n2kfra8p0\LocalCache\local-packages\Python312\site-packages\pymongo\change_stream.py", line 376, in try_next
    self._resume()
  File "C:\Users\martimasxax\AppData\Local\Packages\PythonSoftwareFoundation.Python.3.12_qbz5n2kfra8p0\LocalCache\local-packages\Python312\site-packages\pymongo\change_stream.py", line 260, in _resume
    self._cursor = self._create_cursor()
                   ^^^^^^^^^^^^^^^^^^^^^
  File "C:\Users\martimasxax\AppData\Local\Packages\PythonSoftwareFoundation.Python.3.12_qbz5n2kfra8p0\LocalCache\local-packages\Python312\site-packages\pymongo\change_stream.py", line 252, in _create_cursor
    return self._run_aggregation_cmd(session=s, explicit_session=self._session is not None)
           ^^^^^^^^^^^^^^^^^^^^^^^^^^^^^^^^^^^^^^^^^^^^^^^^^^^^^^^^^^^^^^^^^^^^^^^^^^^^^^^^
  File "C:\Users\martimasxax\AppData\Local\Packages\PythonSoftwareFoundation.Python.3.12_qbz5n2kfra8p0\LocalCache\local-packages\Python312\site-packages\pymongo\change_stream.py", line 246, in _run_aggregation_cmd
    return self._client._retryable_read(
           ^^^^^^^^^^^^^^^^^^^^^^^^^^^^^
  File "C:\Users\martimasxax\AppData\Local\Packages\PythonSoftwareFoundation.Python.3.12_qbz5n2kfra8p0\LocalCache\local-packages\Python312\site-packages\pymongo\mongo_client.py", line 1492, in _retryable_read
    return self._retry_internal(
           ^^^^^^^^^^^^^^^^^^^^^
  File "C:\Users\martimasxax\AppData\Local\Packages\PythonSoftwareFoundation.Python.3.12_qbz5n2kfra8p0\LocalCache\local-packages\Python312\site-packages\pymongo\_csot.py", line 107, in csot_wrapper
    return func(self, *args, **kwargs)
           ^^^^^^^^^^^^^^^^^^^^^^^^^^^
  File "C:\Users\martimasxax\AppData\Local\Packages\PythonSoftwareFoundation.Python.3.12_qbz5n2kfra8p0\LocalCache\local-packages\Python312\site-packages\pymongo\mongo_client.py", line 1462, in _retry_internal
    ).run()
      ^^^^^
  File "C:\Users\martimasxax\AppData\Local\Packages\PythonSoftwareFoundation.Python.3.12_qbz5n2kfra8p0\LocalCache\local-packages\Python312\site-packages\pymongo\mongo_client.py", line 2315, in run
    return self._read() if self._is_read else self._write()
           ^^^^^^^^^^^^
  File "C:\Users\martimasxax\AppData\Local\Packages\PythonSoftwareFoundation.Python.3.12_qbz5n2kfra8p0\LocalCache\local-packages\Python312\site-packages\pymongo\mongo_client.py", line 2437, in _read
    self._server = self._get_server()
                   ^^^^^^^^^^^^^^^^^^
  File "C:\Users\martimasxax\AppData\Local\Packages\PythonSoftwareFoundation.Python.3.12_qbz5n2kfra8p0\LocalCache\local-packages\Python312\site-packages\pymongo\mongo_client.py", line 2400, in _get_server
    return self._client._select_server(
           ^^^^^^^^^^^^^^^^^^^^^^^^^^^^
  File "C:\Users\martimasxax\AppData\Local\Packages\PythonSoftwareFoundation.Python.3.12_qbz5n2kfra8p0\LocalCache\local-packages\Python312\site-packages\pymongo\mongo_client.py", line 1303, in _select_server
    server = topology.select_server(server_selector)
             ^^^^^^^^^^^^^^^^^^^^^^^^^^^^^^^^^^^^^^^
  File "C:\Users\martimasxax\AppData\Local\Packages\PythonSoftwareFoundation.Python.3.12_qbz5n2kfra8p0\LocalCache\local-packages\Python312\site-packages\pymongo\topology.py", line 302, in select_server
    server = self._select_server(selector, server_selection_timeout, address)
             ^^^^^^^^^^^^^^^^^^^^^^^^^^^^^^^^^^^^^^^^^^^^^^^^^^^^^^^^^^^^^^^^
  File "C:\Users\martimasxax\AppData\Local\Packages\PythonSoftwareFoundation.Python.3.12_qbz5n2kfra8p0\LocalCache\local-packages\Python312\site-packages\pymongo\topology.py", line 286, in _select_server
    servers = self.select_servers(selector, server_selection_timeout, address)
              ^^^^^^^^^^^^^^^^^^^^^^^^^^^^^^^^^^^^^^^^^^^^^^^^^^^^^^^^^^^^^^^^
  File "C:\Users\martimasxax\AppData\Local\Packages\PythonSoftwareFoundation.Python.3.12_qbz5n2kfra8p0\LocalCache\local-packages\Python312\site-packages\pymongo\topology.py", line 237, in select_servers
    server_descriptions = self._select_servers_loop(selector, server_timeout, address)
                          ^^^^^^^^^^^^^^^^^^^^^^^^^^^^^^^^^^^^^^^^^^^^^^^^^^^^^^^^^^^^
  File "C:\Users\martimasxax\AppData\Local\Packages\PythonSoftwareFoundation.Python.3.12_qbz5n2kfra8p0\LocalCache\local-packages\Python312\site-packages\pymongo\topology.py", line 259, in _select_servers_loop
    raise ServerSelectionTimeoutError(
pymongo.errors.ServerSelectionTimeoutError: ac-7zrxalx-shard-00-01.v1mxd4q.mongodb.net:27017: [Errno 11001] getaddrinfo failed (configured timeouts: socketTimeoutMS: 20000.0ms, connectTimeoutMS: 20000.0ms),ac-7zrxalx-shard-00-00.v1mxd4q.mongodb.net:27017: [Errno 11001] getaddrinfo failed (configured timeouts: socketTimeoutMS: 20000.0ms, connectTimeoutMS: 20000.0ms),ac-7zrxalx-shard-00-02.v1mxd4q.mongodb.net:27017: [Errno 11001] getaddrinfo failed (configured timeouts: socketTimeoutMS: 20000.0ms, connectTimeoutMS: 20000.0ms), Timeout: 30s, Topology Description: <TopologyDescription id: 664e38986dd1f182d608b9d8, topology_type: ReplicaSetNoPrimary, servers: [<ServerDescription ('ac-7zrxalx-shard-00-00.v1mxd4q.mongodb.net', 27017) server_type: Unknown, rtt: None, error=AutoReconnect('ac-7zrxalx-shard-00-00.v1mxd4q.mongodb.net:27017: [Errno 11001] getaddrinfo failed (configured timeouts: socketTimeoutMS: 20000.0ms, connectTimeoutMS: 20000.0ms)')>, <ServerDescription ('ac-7zrxalx-shard-00-01.v1mxd4q.mongodb.net', 27017) server_type: Unknown, rtt: None, error=AutoReconnect('ac-7zrxalx-shard-00-01.v1mxd4q.mongodb.net:27017: [Errno 11001] getaddrinfo failed (configured timeouts: socketTimeoutMS: 20000.0ms, connectTimeoutMS: 20000.0ms)')>, <ServerDescription ('ac-7zrxalx-shard-00-02.v1mxd4q.mongodb.net', 27017) server_type: Unknown, rtt: None, error=AutoReconnect('ac-7zrxalx-shard-00-02.v1mxd4q.mongodb.net:27017: [Errno 11001] getaddrinfo failed (configured timeouts: socketTimeoutMS: 20000.0ms, connectTimeoutMS: 20000.0ms)')>]>
INFO:root:2024-05-23 17:06:11.493470 - Login failed - Incorrect username: beatnow
INFO:root:2024-05-23 17:06:17.673656 - Login failed - Incorrect username: beatnow
INFO:root:2024-05-23 17:06:18.736174 - Login failed - Incorrect username: beatnow
INFO:root:2024-05-23 17:06:19.720077 - Login failed - Incorrect username: beatnow
INFO:paramiko.transport:Connected (version 2.0, client OpenSSH_8.2p1)
INFO:paramiko.transport:Authentication (password) successful!
INFO:paramiko.transport:Connected (version 2.0, client OpenSSH_8.2p1)
INFO:paramiko.transport:Authentication (password) successful!
INFO:paramiko.transport:Connected (version 2.0, client OpenSSH_8.2p1)
INFO:paramiko.transport:Authentication (password) successful!
INFO:paramiko.transport:Connected (version 2.0, client OpenSSH_8.2p1)
INFO:paramiko.transport:Authentication (password) successful!
INFO:paramiko.transport:Connected (version 2.0, client OpenSSH_8.2p1)
INFO:paramiko.transport:Authentication (password) successful!
INFO:root:2024-05-23 18:28:48.252944 - Login successful for username: aa
INFO:paramiko.transport:Connected (version 2.0, client OpenSSH_8.2p1)
INFO:paramiko.transport:Authentication (password) successful!
ERROR:asyncio:Task exception was never retrieved
future: <Task finished name='Task-3' coro=<watch_changes() done, defined at E:\Project\Back4\BN-BackEnd\config\changeStream.py:5> exception=AutoReconnect("ac-7zrxalx-shard-00-01.v1mxd4q.mongodb.net:27017: (10053, 'WSAECONNABORTED') (configured timeouts: connectTimeoutMS: 20000.0ms)")>
Traceback (most recent call last):
  File "C:\Users\martimasxax\AppData\Local\Packages\PythonSoftwareFoundation.Python.3.12_qbz5n2kfra8p0\LocalCache\local-packages\Python312\site-packages\pymongo\pool.py", line 1020, in receive_message
    return receive_message(self, request_id, self.max_message_size)
           ^^^^^^^^^^^^^^^^^^^^^^^^^^^^^^^^^^^^^^^^^^^^^^^^^^^^^^^^
  File "C:\Users\martimasxax\AppData\Local\Packages\PythonSoftwareFoundation.Python.3.12_qbz5n2kfra8p0\LocalCache\local-packages\Python312\site-packages\pymongo\network.py", line 257, in receive_message
    length, _, response_to, op_code = _UNPACK_HEADER(_receive_data_on_socket(conn, 16, deadline))
                                                     ^^^^^^^^^^^^^^^^^^^^^^^^^^^^^^^^^^^^^^^^^^^
  File "C:\Users\martimasxax\AppData\Local\Packages\PythonSoftwareFoundation.Python.3.12_qbz5n2kfra8p0\LocalCache\local-packages\Python312\site-packages\pymongo\network.py", line 340, in _receive_data_on_socket
    chunk_length = conn.conn.recv_into(mv[bytes_read:])
                   ^^^^^^^^^^^^^^^^^^^^^^^^^^^^^^^^^^^^
  File "C:\Users\martimasxax\AppData\Local\Packages\PythonSoftwareFoundation.Python.3.12_qbz5n2kfra8p0\LocalCache\local-packages\Python312\site-packages\pymongo\pyopenssl_context.py", line 155, in recv_into
    return self._call(super().recv_into, *args, **kwargs)
           ^^^^^^^^^^^^^^^^^^^^^^^^^^^^^^^^^^^^^^^^^^^^^^
  File "C:\Users\martimasxax\AppData\Local\Packages\PythonSoftwareFoundation.Python.3.12_qbz5n2kfra8p0\LocalCache\local-packages\Python312\site-packages\pymongo\pyopenssl_context.py", line 120, in _call
    return call(*args, **kwargs)
           ^^^^^^^^^^^^^^^^^^^^^
  File "C:\Users\martimasxax\AppData\Local\Packages\PythonSoftwareFoundation.Python.3.12_qbz5n2kfra8p0\LocalCache\local-packages\Python312\site-packages\OpenSSL\SSL.py", line 2099, in recv_into
    self._raise_ssl_error(self._ssl, result)
  File "C:\Users\martimasxax\AppData\Local\Packages\PythonSoftwareFoundation.Python.3.12_qbz5n2kfra8p0\LocalCache\local-packages\Python312\site-packages\OpenSSL\SSL.py", line 1818, in _raise_ssl_error
    raise SysCallError(errno, errorcode.get(errno))
OpenSSL.SSL.SysCallError: (10054, 'WSAECONNRESET')

The above exception was the direct cause of the following exception:

Traceback (most recent call last):
  File "C:\Users\martimasxax\AppData\Local\Packages\PythonSoftwareFoundation.Python.3.12_qbz5n2kfra8p0\LocalCache\local-packages\Python312\site-packages\pymongo\change_stream.py", line 372, in try_next
    change = self._cursor._try_next(True)
             ^^^^^^^^^^^^^^^^^^^^^^^^^^^^
  File "C:\Users\martimasxax\AppData\Local\Packages\PythonSoftwareFoundation.Python.3.12_qbz5n2kfra8p0\LocalCache\local-packages\Python312\site-packages\pymongo\command_cursor.py", line 321, in _try_next
    self._refresh()
  File "C:\Users\martimasxax\AppData\Local\Packages\PythonSoftwareFoundation.Python.3.12_qbz5n2kfra8p0\LocalCache\local-packages\Python312\site-packages\pymongo\command_cursor.py", line 242, in _refresh
    self.__send_message(
  File "C:\Users\martimasxax\AppData\Local\Packages\PythonSoftwareFoundation.Python.3.12_qbz5n2kfra8p0\LocalCache\local-packages\Python312\site-packages\pymongo\command_cursor.py", line 179, in __send_message
    response = client._run_operation(
               ^^^^^^^^^^^^^^^^^^^^^^
  File "C:\Users\martimasxax\AppData\Local\Packages\PythonSoftwareFoundation.Python.3.12_qbz5n2kfra8p0\LocalCache\local-packages\Python312\site-packages\pymongo\_csot.py", line 107, in csot_wrapper
    return func(self, *args, **kwargs)
           ^^^^^^^^^^^^^^^^^^^^^^^^^^^
  File "C:\Users\martimasxax\AppData\Local\Packages\PythonSoftwareFoundation.Python.3.12_qbz5n2kfra8p0\LocalCache\local-packages\Python312\site-packages\pymongo\mongo_client.py", line 1394, in _run_operation
    return self._retryable_read(
           ^^^^^^^^^^^^^^^^^^^^^
  File "C:\Users\martimasxax\AppData\Local\Packages\PythonSoftwareFoundation.Python.3.12_qbz5n2kfra8p0\LocalCache\local-packages\Python312\site-packages\pymongo\mongo_client.py", line 1492, in _retryable_read
    return self._retry_internal(
           ^^^^^^^^^^^^^^^^^^^^^
  File "C:\Users\martimasxax\AppData\Local\Packages\PythonSoftwareFoundation.Python.3.12_qbz5n2kfra8p0\LocalCache\local-packages\Python312\site-packages\pymongo\_csot.py", line 107, in csot_wrapper
    return func(self, *args, **kwargs)
           ^^^^^^^^^^^^^^^^^^^^^^^^^^^
  File "C:\Users\martimasxax\AppData\Local\Packages\PythonSoftwareFoundation.Python.3.12_qbz5n2kfra8p0\LocalCache\local-packages\Python312\site-packages\pymongo\mongo_client.py", line 1462, in _retry_internal
    ).run()
      ^^^^^
  File "C:\Users\martimasxax\AppData\Local\Packages\PythonSoftwareFoundation.Python.3.12_qbz5n2kfra8p0\LocalCache\local-packages\Python312\site-packages\pymongo\mongo_client.py", line 2315, in run
    return self._read() if self._is_read else self._write()
           ^^^^^^^^^^^^
  File "C:\Users\martimasxax\AppData\Local\Packages\PythonSoftwareFoundation.Python.3.12_qbz5n2kfra8p0\LocalCache\local-packages\Python312\site-packages\pymongo\mongo_client.py", line 2445, in _read
    return self._func(self._session, self._server, conn, read_pref)  # type: ignore
           ^^^^^^^^^^^^^^^^^^^^^^^^^^^^^^^^^^^^^^^^^^^^^^^^^^^^^^^^
  File "C:\Users\martimasxax\AppData\Local\Packages\PythonSoftwareFoundation.Python.3.12_qbz5n2kfra8p0\LocalCache\local-packages\Python312\site-packages\pymongo\mongo_client.py", line 1390, in _cmd
    return server.run_operation(
           ^^^^^^^^^^^^^^^^^^^^^
  File "C:\Users\martimasxax\AppData\Local\Packages\PythonSoftwareFoundation.Python.3.12_qbz5n2kfra8p0\LocalCache\local-packages\Python312\site-packages\pymongo\helpers.py", line 322, in inner
    return func(*args, **kwargs)
           ^^^^^^^^^^^^^^^^^^^^^
  File "C:\Users\martimasxax\AppData\Local\Packages\PythonSoftwareFoundation.Python.3.12_qbz5n2kfra8p0\LocalCache\local-packages\Python312\site-packages\pymongo\server.py", line 148, in run_operation
    reply = conn.receive_message(request_id)
            ^^^^^^^^^^^^^^^^^^^^^^^^^^^^^^^^
  File "C:\Users\martimasxax\AppData\Local\Packages\PythonSoftwareFoundation.Python.3.12_qbz5n2kfra8p0\LocalCache\local-packages\Python312\site-packages\pymongo\pool.py", line 1022, in receive_message
    self._raise_connection_failure(error)
  File "C:\Users\martimasxax\AppData\Local\Packages\PythonSoftwareFoundation.Python.3.12_qbz5n2kfra8p0\LocalCache\local-packages\Python312\site-packages\pymongo\pool.py", line 1171, in _raise_connection_failure
    _raise_connection_failure(self.address, error, timeout_details=details)
  File "C:\Users\martimasxax\AppData\Local\Packages\PythonSoftwareFoundation.Python.3.12_qbz5n2kfra8p0\LocalCache\local-packages\Python312\site-packages\pymongo\pool.py", line 411, in _raise_connection_failure
    raise AutoReconnect(msg) from error
pymongo.errors.AutoReconnect: ac-7zrxalx-shard-00-01.v1mxd4q.mongodb.net:27017: (10054, 'WSAECONNRESET') (configured timeouts: connectTimeoutMS: 20000.0ms)

During handling of the above exception, another exception occurred:

Traceback (most recent call last):
  File "C:\Users\martimasxax\AppData\Local\Packages\PythonSoftwareFoundation.Python.3.12_qbz5n2kfra8p0\LocalCache\local-packages\Python312\site-packages\pymongo\pool.py", line 968, in command
    return command(
           ^^^^^^^^
  File "C:\Users\martimasxax\AppData\Local\Packages\PythonSoftwareFoundation.Python.3.12_qbz5n2kfra8p0\LocalCache\local-packages\Python312\site-packages\pymongo\network.py", line 182, in command
    reply = receive_message(conn, request_id)
            ^^^^^^^^^^^^^^^^^^^^^^^^^^^^^^^^^
  File "C:\Users\martimasxax\AppData\Local\Packages\PythonSoftwareFoundation.Python.3.12_qbz5n2kfra8p0\LocalCache\local-packages\Python312\site-packages\pymongo\network.py", line 257, in receive_message
    length, _, response_to, op_code = _UNPACK_HEADER(_receive_data_on_socket(conn, 16, deadline))
                                                     ^^^^^^^^^^^^^^^^^^^^^^^^^^^^^^^^^^^^^^^^^^^
  File "C:\Users\martimasxax\AppData\Local\Packages\PythonSoftwareFoundation.Python.3.12_qbz5n2kfra8p0\LocalCache\local-packages\Python312\site-packages\pymongo\network.py", line 340, in _receive_data_on_socket
    chunk_length = conn.conn.recv_into(mv[bytes_read:])
                   ^^^^^^^^^^^^^^^^^^^^^^^^^^^^^^^^^^^^
  File "C:\Users\martimasxax\AppData\Local\Packages\PythonSoftwareFoundation.Python.3.12_qbz5n2kfra8p0\LocalCache\local-packages\Python312\site-packages\pymongo\pyopenssl_context.py", line 155, in recv_into
    return self._call(super().recv_into, *args, **kwargs)
           ^^^^^^^^^^^^^^^^^^^^^^^^^^^^^^^^^^^^^^^^^^^^^^
  File "C:\Users\martimasxax\AppData\Local\Packages\PythonSoftwareFoundation.Python.3.12_qbz5n2kfra8p0\LocalCache\local-packages\Python312\site-packages\pymongo\pyopenssl_context.py", line 120, in _call
    return call(*args, **kwargs)
           ^^^^^^^^^^^^^^^^^^^^^
  File "C:\Users\martimasxax\AppData\Local\Packages\PythonSoftwareFoundation.Python.3.12_qbz5n2kfra8p0\LocalCache\local-packages\Python312\site-packages\OpenSSL\SSL.py", line 2099, in recv_into
    self._raise_ssl_error(self._ssl, result)
  File "C:\Users\martimasxax\AppData\Local\Packages\PythonSoftwareFoundation.Python.3.12_qbz5n2kfra8p0\LocalCache\local-packages\Python312\site-packages\OpenSSL\SSL.py", line 1818, in _raise_ssl_error
    raise SysCallError(errno, errorcode.get(errno))
OpenSSL.SSL.SysCallError: (10053, 'WSAECONNABORTED')

The above exception was the direct cause of the following exception:

Traceback (most recent call last):
  File "E:\Project\Back4\BN-BackEnd\config\changeStream.py", line 7, in watch_changes
    async for change in stream:
  File "C:\Users\martimasxax\AppData\Local\Packages\PythonSoftwareFoundation.Python.3.12_qbz5n2kfra8p0\LocalCache\local-packages\Python312\site-packages\motor\core.py", line 2038, in next
    doc = await self.try_next()
          ^^^^^^^^^^^^^^^^^^^^^
  File "C:\Users\martimasxax\AppData\Local\Packages\PythonSoftwareFoundation.Python.3.12_qbz5n2kfra8p0\LocalCache\local-packages\Python312\site-packages\motor\core.py", line 2079, in try_next
    return await self._framework.run_on_executor(loop, self._try_next)
           ^^^^^^^^^^^^^^^^^^^^^^^^^^^^^^^^^^^^^^^^^^^^^^^^^^^^^^^^^^^
  File "C:\Program Files\WindowsApps\PythonSoftwareFoundation.Python.3.12_3.12.1008.0_x64__qbz5n2kfra8p0\Lib\concurrent\futures\thread.py", line 58, in run
    result = self.fn(*self.args, **self.kwargs)
             ^^^^^^^^^^^^^^^^^^^^^^^^^^^^^^^^^^
  File "C:\Users\martimasxax\AppData\Local\Packages\PythonSoftwareFoundation.Python.3.12_qbz5n2kfra8p0\LocalCache\local-packages\Python312\site-packages\motor\core.py", line 1984, in _try_next
    return self.delegate.try_next()
           ^^^^^^^^^^^^^^^^^^^^^^^^
  File "C:\Users\martimasxax\AppData\Local\Packages\PythonSoftwareFoundation.Python.3.12_qbz5n2kfra8p0\LocalCache\local-packages\Python312\site-packages\pymongo\_csot.py", line 107, in csot_wrapper
    return func(self, *args, **kwargs)
           ^^^^^^^^^^^^^^^^^^^^^^^^^^^
  File "C:\Users\martimasxax\AppData\Local\Packages\PythonSoftwareFoundation.Python.3.12_qbz5n2kfra8p0\LocalCache\local-packages\Python312\site-packages\pymongo\change_stream.py", line 376, in try_next
    self._resume()
  File "C:\Users\martimasxax\AppData\Local\Packages\PythonSoftwareFoundation.Python.3.12_qbz5n2kfra8p0\LocalCache\local-packages\Python312\site-packages\pymongo\change_stream.py", line 260, in _resume
    self._cursor = self._create_cursor()
                   ^^^^^^^^^^^^^^^^^^^^^
  File "C:\Users\martimasxax\AppData\Local\Packages\PythonSoftwareFoundation.Python.3.12_qbz5n2kfra8p0\LocalCache\local-packages\Python312\site-packages\pymongo\change_stream.py", line 252, in _create_cursor
    return self._run_aggregation_cmd(session=s, explicit_session=self._session is not None)
           ^^^^^^^^^^^^^^^^^^^^^^^^^^^^^^^^^^^^^^^^^^^^^^^^^^^^^^^^^^^^^^^^^^^^^^^^^^^^^^^^
  File "C:\Users\martimasxax\AppData\Local\Packages\PythonSoftwareFoundation.Python.3.12_qbz5n2kfra8p0\LocalCache\local-packages\Python312\site-packages\pymongo\change_stream.py", line 246, in _run_aggregation_cmd
    return self._client._retryable_read(
           ^^^^^^^^^^^^^^^^^^^^^^^^^^^^^
  File "C:\Users\martimasxax\AppData\Local\Packages\PythonSoftwareFoundation.Python.3.12_qbz5n2kfra8p0\LocalCache\local-packages\Python312\site-packages\pymongo\mongo_client.py", line 1492, in _retryable_read
    return self._retry_internal(
           ^^^^^^^^^^^^^^^^^^^^^
  File "C:\Users\martimasxax\AppData\Local\Packages\PythonSoftwareFoundation.Python.3.12_qbz5n2kfra8p0\LocalCache\local-packages\Python312\site-packages\pymongo\_csot.py", line 107, in csot_wrapper
    return func(self, *args, **kwargs)
           ^^^^^^^^^^^^^^^^^^^^^^^^^^^
  File "C:\Users\martimasxax\AppData\Local\Packages\PythonSoftwareFoundation.Python.3.12_qbz5n2kfra8p0\LocalCache\local-packages\Python312\site-packages\pymongo\mongo_client.py", line 1462, in _retry_internal
    ).run()
      ^^^^^
  File "C:\Users\martimasxax\AppData\Local\Packages\PythonSoftwareFoundation.Python.3.12_qbz5n2kfra8p0\LocalCache\local-packages\Python312\site-packages\pymongo\mongo_client.py", line 2315, in run
    return self._read() if self._is_read else self._write()
           ^^^^^^^^^^^^
  File "C:\Users\martimasxax\AppData\Local\Packages\PythonSoftwareFoundation.Python.3.12_qbz5n2kfra8p0\LocalCache\local-packages\Python312\site-packages\pymongo\mongo_client.py", line 2445, in _read
    return self._func(self._session, self._server, conn, read_pref)  # type: ignore
           ^^^^^^^^^^^^^^^^^^^^^^^^^^^^^^^^^^^^^^^^^^^^^^^^^^^^^^^^
  File "C:\Users\martimasxax\AppData\Local\Packages\PythonSoftwareFoundation.Python.3.12_qbz5n2kfra8p0\LocalCache\local-packages\Python312\site-packages\pymongo\aggregation.py", line 164, in get_cursor
    result = conn.command(
             ^^^^^^^^^^^^^
  File "C:\Users\martimasxax\AppData\Local\Packages\PythonSoftwareFoundation.Python.3.12_qbz5n2kfra8p0\LocalCache\local-packages\Python312\site-packages\pymongo\helpers.py", line 322, in inner
    return func(*args, **kwargs)
           ^^^^^^^^^^^^^^^^^^^^^
  File "C:\Users\martimasxax\AppData\Local\Packages\PythonSoftwareFoundation.Python.3.12_qbz5n2kfra8p0\LocalCache\local-packages\Python312\site-packages\pymongo\pool.py", line 996, in command
    self._raise_connection_failure(error)
  File "C:\Users\martimasxax\AppData\Local\Packages\PythonSoftwareFoundation.Python.3.12_qbz5n2kfra8p0\LocalCache\local-packages\Python312\site-packages\pymongo\pool.py", line 1171, in _raise_connection_failure
    _raise_connection_failure(self.address, error, timeout_details=details)
  File "C:\Users\martimasxax\AppData\Local\Packages\PythonSoftwareFoundation.Python.3.12_qbz5n2kfra8p0\LocalCache\local-packages\Python312\site-packages\pymongo\pool.py", line 411, in _raise_connection_failure
    raise AutoReconnect(msg) from error
pymongo.errors.AutoReconnect: ac-7zrxalx-shard-00-01.v1mxd4q.mongodb.net:27017: (10053, 'WSAECONNABORTED') (configured timeouts: connectTimeoutMS: 20000.0ms)
ERROR:asyncio:Task exception was never retrieved
future: <Task finished name='Task-3' coro=<watch_changes() done, defined at e:\Project\Back4\BN-BackEnd\config\changeStream.py:5> exception=AutoReconnect("ac-7zrxalx-shard-00-01.v1mxd4q.mongodb.net:27017: (10053, 'WSAECONNABORTED') (configured timeouts: connectTimeoutMS: 20000.0ms)")>
Traceback (most recent call last):
  File "C:\Users\martimasxax\AppData\Local\Packages\PythonSoftwareFoundation.Python.3.12_qbz5n2kfra8p0\LocalCache\local-packages\Python312\site-packages\pymongo\pool.py", line 1020, in receive_message
    return receive_message(self, request_id, self.max_message_size)
           ^^^^^^^^^^^^^^^^^^^^^^^^^^^^^^^^^^^^^^^^^^^^^^^^^^^^^^^^
  File "C:\Users\martimasxax\AppData\Local\Packages\PythonSoftwareFoundation.Python.3.12_qbz5n2kfra8p0\LocalCache\local-packages\Python312\site-packages\pymongo\network.py", line 257, in receive_message
    length, _, response_to, op_code = _UNPACK_HEADER(_receive_data_on_socket(conn, 16, deadline))
                                                     ^^^^^^^^^^^^^^^^^^^^^^^^^^^^^^^^^^^^^^^^^^^
  File "C:\Users\martimasxax\AppData\Local\Packages\PythonSoftwareFoundation.Python.3.12_qbz5n2kfra8p0\LocalCache\local-packages\Python312\site-packages\pymongo\network.py", line 340, in _receive_data_on_socket
    chunk_length = conn.conn.recv_into(mv[bytes_read:])
                   ^^^^^^^^^^^^^^^^^^^^^^^^^^^^^^^^^^^^
  File "C:\Users\martimasxax\AppData\Local\Packages\PythonSoftwareFoundation.Python.3.12_qbz5n2kfra8p0\LocalCache\local-packages\Python312\site-packages\pymongo\pyopenssl_context.py", line 155, in recv_into
    return self._call(super().recv_into, *args, **kwargs)
           ^^^^^^^^^^^^^^^^^^^^^^^^^^^^^^^^^^^^^^^^^^^^^^
  File "C:\Users\martimasxax\AppData\Local\Packages\PythonSoftwareFoundation.Python.3.12_qbz5n2kfra8p0\LocalCache\local-packages\Python312\site-packages\pymongo\pyopenssl_context.py", line 120, in _call
    return call(*args, **kwargs)
           ^^^^^^^^^^^^^^^^^^^^^
  File "C:\Users\martimasxax\AppData\Local\Packages\PythonSoftwareFoundation.Python.3.12_qbz5n2kfra8p0\LocalCache\local-packages\Python312\site-packages\OpenSSL\SSL.py", line 2099, in recv_into
    self._raise_ssl_error(self._ssl, result)
  File "C:\Users\martimasxax\AppData\Local\Packages\PythonSoftwareFoundation.Python.3.12_qbz5n2kfra8p0\LocalCache\local-packages\Python312\site-packages\OpenSSL\SSL.py", line 1818, in _raise_ssl_error
    raise SysCallError(errno, errorcode.get(errno))
OpenSSL.SSL.SysCallError: (10054, 'WSAECONNRESET')

The above exception was the direct cause of the following exception:

Traceback (most recent call last):
  File "C:\Users\martimasxax\AppData\Local\Packages\PythonSoftwareFoundation.Python.3.12_qbz5n2kfra8p0\LocalCache\local-packages\Python312\site-packages\pymongo\change_stream.py", line 372, in try_next
    change = self._cursor._try_next(True)
             ^^^^^^^^^^^^^^^^^^^^^^^^^^^^
  File "C:\Users\martimasxax\AppData\Local\Packages\PythonSoftwareFoundation.Python.3.12_qbz5n2kfra8p0\LocalCache\local-packages\Python312\site-packages\pymongo\command_cursor.py", line 321, in _try_next
    self._refresh()
  File "C:\Users\martimasxax\AppData\Local\Packages\PythonSoftwareFoundation.Python.3.12_qbz5n2kfra8p0\LocalCache\local-packages\Python312\site-packages\pymongo\command_cursor.py", line 242, in _refresh
    self.__send_message(
  File "C:\Users\martimasxax\AppData\Local\Packages\PythonSoftwareFoundation.Python.3.12_qbz5n2kfra8p0\LocalCache\local-packages\Python312\site-packages\pymongo\command_cursor.py", line 179, in __send_message
    response = client._run_operation(
               ^^^^^^^^^^^^^^^^^^^^^^
  File "C:\Users\martimasxax\AppData\Local\Packages\PythonSoftwareFoundation.Python.3.12_qbz5n2kfra8p0\LocalCache\local-packages\Python312\site-packages\pymongo\_csot.py", line 107, in csot_wrapper
    return func(self, *args, **kwargs)
           ^^^^^^^^^^^^^^^^^^^^^^^^^^^
  File "C:\Users\martimasxax\AppData\Local\Packages\PythonSoftwareFoundation.Python.3.12_qbz5n2kfra8p0\LocalCache\local-packages\Python312\site-packages\pymongo\mongo_client.py", line 1394, in _run_operation
    return self._retryable_read(
           ^^^^^^^^^^^^^^^^^^^^^
  File "C:\Users\martimasxax\AppData\Local\Packages\PythonSoftwareFoundation.Python.3.12_qbz5n2kfra8p0\LocalCache\local-packages\Python312\site-packages\pymongo\mongo_client.py", line 1492, in _retryable_read
    return self._retry_internal(
           ^^^^^^^^^^^^^^^^^^^^^
  File "C:\Users\martimasxax\AppData\Local\Packages\PythonSoftwareFoundation.Python.3.12_qbz5n2kfra8p0\LocalCache\local-packages\Python312\site-packages\pymongo\_csot.py", line 107, in csot_wrapper
    return func(self, *args, **kwargs)
           ^^^^^^^^^^^^^^^^^^^^^^^^^^^
  File "C:\Users\martimasxax\AppData\Local\Packages\PythonSoftwareFoundation.Python.3.12_qbz5n2kfra8p0\LocalCache\local-packages\Python312\site-packages\pymongo\mongo_client.py", line 1462, in _retry_internal
    ).run()
      ^^^^^
  File "C:\Users\martimasxax\AppData\Local\Packages\PythonSoftwareFoundation.Python.3.12_qbz5n2kfra8p0\LocalCache\local-packages\Python312\site-packages\pymongo\mongo_client.py", line 2315, in run
    return self._read() if self._is_read else self._write()
           ^^^^^^^^^^^^
  File "C:\Users\martimasxax\AppData\Local\Packages\PythonSoftwareFoundation.Python.3.12_qbz5n2kfra8p0\LocalCache\local-packages\Python312\site-packages\pymongo\mongo_client.py", line 2445, in _read
    return self._func(self._session, self._server, conn, read_pref)  # type: ignore
           ^^^^^^^^^^^^^^^^^^^^^^^^^^^^^^^^^^^^^^^^^^^^^^^^^^^^^^^^
  File "C:\Users\martimasxax\AppData\Local\Packages\PythonSoftwareFoundation.Python.3.12_qbz5n2kfra8p0\LocalCache\local-packages\Python312\site-packages\pymongo\mongo_client.py", line 1390, in _cmd
    return server.run_operation(
           ^^^^^^^^^^^^^^^^^^^^^
  File "C:\Users\martimasxax\AppData\Local\Packages\PythonSoftwareFoundation.Python.3.12_qbz5n2kfra8p0\LocalCache\local-packages\Python312\site-packages\pymongo\helpers.py", line 322, in inner
    return func(*args, **kwargs)
           ^^^^^^^^^^^^^^^^^^^^^
  File "C:\Users\martimasxax\AppData\Local\Packages\PythonSoftwareFoundation.Python.3.12_qbz5n2kfra8p0\LocalCache\local-packages\Python312\site-packages\pymongo\server.py", line 148, in run_operation
    reply = conn.receive_message(request_id)
            ^^^^^^^^^^^^^^^^^^^^^^^^^^^^^^^^
  File "C:\Users\martimasxax\AppData\Local\Packages\PythonSoftwareFoundation.Python.3.12_qbz5n2kfra8p0\LocalCache\local-packages\Python312\site-packages\pymongo\pool.py", line 1022, in receive_message
    self._raise_connection_failure(error)
  File "C:\Users\martimasxax\AppData\Local\Packages\PythonSoftwareFoundation.Python.3.12_qbz5n2kfra8p0\LocalCache\local-packages\Python312\site-packages\pymongo\pool.py", line 1171, in _raise_connection_failure
    _raise_connection_failure(self.address, error, timeout_details=details)
  File "C:\Users\martimasxax\AppData\Local\Packages\PythonSoftwareFoundation.Python.3.12_qbz5n2kfra8p0\LocalCache\local-packages\Python312\site-packages\pymongo\pool.py", line 411, in _raise_connection_failure
    raise AutoReconnect(msg) from error
pymongo.errors.AutoReconnect: ac-7zrxalx-shard-00-01.v1mxd4q.mongodb.net:27017: (10054, 'WSAECONNRESET') (configured timeouts: connectTimeoutMS: 20000.0ms)

During handling of the above exception, another exception occurred:

Traceback (most recent call last):
  File "C:\Users\martimasxax\AppData\Local\Packages\PythonSoftwareFoundation.Python.3.12_qbz5n2kfra8p0\LocalCache\local-packages\Python312\site-packages\pymongo\pool.py", line 968, in command
    return command(
           ^^^^^^^^
  File "C:\Users\martimasxax\AppData\Local\Packages\PythonSoftwareFoundation.Python.3.12_qbz5n2kfra8p0\LocalCache\local-packages\Python312\site-packages\pymongo\network.py", line 182, in command
    reply = receive_message(conn, request_id)
            ^^^^^^^^^^^^^^^^^^^^^^^^^^^^^^^^^
  File "C:\Users\martimasxax\AppData\Local\Packages\PythonSoftwareFoundation.Python.3.12_qbz5n2kfra8p0\LocalCache\local-packages\Python312\site-packages\pymongo\network.py", line 257, in receive_message
    length, _, response_to, op_code = _UNPACK_HEADER(_receive_data_on_socket(conn, 16, deadline))
                                                     ^^^^^^^^^^^^^^^^^^^^^^^^^^^^^^^^^^^^^^^^^^^
  File "C:\Users\martimasxax\AppData\Local\Packages\PythonSoftwareFoundation.Python.3.12_qbz5n2kfra8p0\LocalCache\local-packages\Python312\site-packages\pymongo\network.py", line 340, in _receive_data_on_socket
    chunk_length = conn.conn.recv_into(mv[bytes_read:])
                   ^^^^^^^^^^^^^^^^^^^^^^^^^^^^^^^^^^^^
  File "C:\Users\martimasxax\AppData\Local\Packages\PythonSoftwareFoundation.Python.3.12_qbz5n2kfra8p0\LocalCache\local-packages\Python312\site-packages\pymongo\pyopenssl_context.py", line 155, in recv_into
    return self._call(super().recv_into, *args, **kwargs)
           ^^^^^^^^^^^^^^^^^^^^^^^^^^^^^^^^^^^^^^^^^^^^^^
  File "C:\Users\martimasxax\AppData\Local\Packages\PythonSoftwareFoundation.Python.3.12_qbz5n2kfra8p0\LocalCache\local-packages\Python312\site-packages\pymongo\pyopenssl_context.py", line 120, in _call
    return call(*args, **kwargs)
           ^^^^^^^^^^^^^^^^^^^^^
  File "C:\Users\martimasxax\AppData\Local\Packages\PythonSoftwareFoundation.Python.3.12_qbz5n2kfra8p0\LocalCache\local-packages\Python312\site-packages\OpenSSL\SSL.py", line 2099, in recv_into
    self._raise_ssl_error(self._ssl, result)
  File "C:\Users\martimasxax\AppData\Local\Packages\PythonSoftwareFoundation.Python.3.12_qbz5n2kfra8p0\LocalCache\local-packages\Python312\site-packages\OpenSSL\SSL.py", line 1818, in _raise_ssl_error
    raise SysCallError(errno, errorcode.get(errno))
OpenSSL.SSL.SysCallError: (10053, 'WSAECONNABORTED')

The above exception was the direct cause of the following exception:

Traceback (most recent call last):
  File "e:\Project\Back4\BN-BackEnd\config\changeStream.py", line 7, in watch_changes
    async for change in stream:
  File "C:\Users\martimasxax\AppData\Local\Packages\PythonSoftwareFoundation.Python.3.12_qbz5n2kfra8p0\LocalCache\local-packages\Python312\site-packages\motor\core.py", line 2038, in next
    doc = await self.try_next()
          ^^^^^^^^^^^^^^^^^^^^^
  File "C:\Users\martimasxax\AppData\Local\Packages\PythonSoftwareFoundation.Python.3.12_qbz5n2kfra8p0\LocalCache\local-packages\Python312\site-packages\motor\core.py", line 2079, in try_next
    return await self._framework.run_on_executor(loop, self._try_next)
           ^^^^^^^^^^^^^^^^^^^^^^^^^^^^^^^^^^^^^^^^^^^^^^^^^^^^^^^^^^^
  File "C:\Program Files\WindowsApps\PythonSoftwareFoundation.Python.3.12_3.12.1008.0_x64__qbz5n2kfra8p0\Lib\concurrent\futures\thread.py", line 58, in run
    result = self.fn(*self.args, **self.kwargs)
             ^^^^^^^^^^^^^^^^^^^^^^^^^^^^^^^^^^
  File "C:\Users\martimasxax\AppData\Local\Packages\PythonSoftwareFoundation.Python.3.12_qbz5n2kfra8p0\LocalCache\local-packages\Python312\site-packages\motor\core.py", line 1984, in _try_next
    return self.delegate.try_next()
           ^^^^^^^^^^^^^^^^^^^^^^^^
  File "C:\Users\martimasxax\AppData\Local\Packages\PythonSoftwareFoundation.Python.3.12_qbz5n2kfra8p0\LocalCache\local-packages\Python312\site-packages\pymongo\_csot.py", line 107, in csot_wrapper
    return func(self, *args, **kwargs)
           ^^^^^^^^^^^^^^^^^^^^^^^^^^^
  File "C:\Users\martimasxax\AppData\Local\Packages\PythonSoftwareFoundation.Python.3.12_qbz5n2kfra8p0\LocalCache\local-packages\Python312\site-packages\pymongo\change_stream.py", line 376, in try_next
    self._resume()
  File "C:\Users\martimasxax\AppData\Local\Packages\PythonSoftwareFoundation.Python.3.12_qbz5n2kfra8p0\LocalCache\local-packages\Python312\site-packages\pymongo\change_stream.py", line 260, in _resume
    self._cursor = self._create_cursor()
                   ^^^^^^^^^^^^^^^^^^^^^
  File "C:\Users\martimasxax\AppData\Local\Packages\PythonSoftwareFoundation.Python.3.12_qbz5n2kfra8p0\LocalCache\local-packages\Python312\site-packages\pymongo\change_stream.py", line 252, in _create_cursor
    return self._run_aggregation_cmd(session=s, explicit_session=self._session is not None)
           ^^^^^^^^^^^^^^^^^^^^^^^^^^^^^^^^^^^^^^^^^^^^^^^^^^^^^^^^^^^^^^^^^^^^^^^^^^^^^^^^
  File "C:\Users\martimasxax\AppData\Local\Packages\PythonSoftwareFoundation.Python.3.12_qbz5n2kfra8p0\LocalCache\local-packages\Python312\site-packages\pymongo\change_stream.py", line 246, in _run_aggregation_cmd
    return self._client._retryable_read(
           ^^^^^^^^^^^^^^^^^^^^^^^^^^^^^
  File "C:\Users\martimasxax\AppData\Local\Packages\PythonSoftwareFoundation.Python.3.12_qbz5n2kfra8p0\LocalCache\local-packages\Python312\site-packages\pymongo\mongo_client.py", line 1492, in _retryable_read
    return self._retry_internal(
           ^^^^^^^^^^^^^^^^^^^^^
  File "C:\Users\martimasxax\AppData\Local\Packages\PythonSoftwareFoundation.Python.3.12_qbz5n2kfra8p0\LocalCache\local-packages\Python312\site-packages\pymongo\_csot.py", line 107, in csot_wrapper
    return func(self, *args, **kwargs)
           ^^^^^^^^^^^^^^^^^^^^^^^^^^^
  File "C:\Users\martimasxax\AppData\Local\Packages\PythonSoftwareFoundation.Python.3.12_qbz5n2kfra8p0\LocalCache\local-packages\Python312\site-packages\pymongo\mongo_client.py", line 1462, in _retry_internal
    ).run()
      ^^^^^
  File "C:\Users\martimasxax\AppData\Local\Packages\PythonSoftwareFoundation.Python.3.12_qbz5n2kfra8p0\LocalCache\local-packages\Python312\site-packages\pymongo\mongo_client.py", line 2315, in run
    return self._read() if self._is_read else self._write()
           ^^^^^^^^^^^^
  File "C:\Users\martimasxax\AppData\Local\Packages\PythonSoftwareFoundation.Python.3.12_qbz5n2kfra8p0\LocalCache\local-packages\Python312\site-packages\pymongo\mongo_client.py", line 2445, in _read
    return self._func(self._session, self._server, conn, read_pref)  # type: ignore
           ^^^^^^^^^^^^^^^^^^^^^^^^^^^^^^^^^^^^^^^^^^^^^^^^^^^^^^^^
  File "C:\Users\martimasxax\AppData\Local\Packages\PythonSoftwareFoundation.Python.3.12_qbz5n2kfra8p0\LocalCache\local-packages\Python312\site-packages\pymongo\aggregation.py", line 164, in get_cursor
    result = conn.command(
             ^^^^^^^^^^^^^
  File "C:\Users\martimasxax\AppData\Local\Packages\PythonSoftwareFoundation.Python.3.12_qbz5n2kfra8p0\LocalCache\local-packages\Python312\site-packages\pymongo\helpers.py", line 322, in inner
    return func(*args, **kwargs)
           ^^^^^^^^^^^^^^^^^^^^^
  File "C:\Users\martimasxax\AppData\Local\Packages\PythonSoftwareFoundation.Python.3.12_qbz5n2kfra8p0\LocalCache\local-packages\Python312\site-packages\pymongo\pool.py", line 996, in command
    self._raise_connection_failure(error)
  File "C:\Users\martimasxax\AppData\Local\Packages\PythonSoftwareFoundation.Python.3.12_qbz5n2kfra8p0\LocalCache\local-packages\Python312\site-packages\pymongo\pool.py", line 1171, in _raise_connection_failure
    _raise_connection_failure(self.address, error, timeout_details=details)
  File "C:\Users\martimasxax\AppData\Local\Packages\PythonSoftwareFoundation.Python.3.12_qbz5n2kfra8p0\LocalCache\local-packages\Python312\site-packages\pymongo\pool.py", line 411, in _raise_connection_failure
    raise AutoReconnect(msg) from error
pymongo.errors.AutoReconnect: ac-7zrxalx-shard-00-01.v1mxd4q.mongodb.net:27017: (10053, 'WSAECONNABORTED') (configured timeouts: connectTimeoutMS: 20000.0ms)
INFO:paramiko.transport:Connected (version 2.0, client OpenSSH_8.2p1)
INFO:paramiko.transport:Authentication (password) successful!
INFO:paramiko.transport:Connected (version 2.0, client OpenSSH_8.2p1)
INFO:paramiko.transport:Authentication (password) successful!
INFO:paramiko.transport:Connected (version 2.0, client OpenSSH_8.2p1)
INFO:paramiko.transport:Authentication (password) successful!
INFO:paramiko.transport:Connected (version 2.0, client OpenSSH_8.2p1)
INFO:paramiko.transport:Authentication (password) successful!
INFO:paramiko.transport:Connected (version 2.0, client OpenSSH_8.2p1)
INFO:paramiko.transport:Authentication (password) successful!
ERROR:asyncio:Task exception was never retrieved
future: <Task finished name='Task-3' coro=<watch_changes() done, defined at E:\Project\Back4\BN-BackEnd\config\changeStream.py:5> exception=ServerSelectionTimeoutError("ac-7zrxalx-shard-00-01.v1mxd4q.mongodb.net:27017: [WinError 10013] Intento de acceso a un socket no permitido por sus permisos de acceso (configured timeouts: socketTimeoutMS: 20000.0ms, connectTimeoutMS: 20000.0ms),ac-7zrxalx-shard-00-02.v1mxd4q.mongodb.net:27017: [WinError 10013] Intento de acceso a un socket no permitido por sus permisos de acceso (configured timeouts: socketTimeoutMS: 20000.0ms, connectTimeoutMS: 20000.0ms),ac-7zrxalx-shard-00-00.v1mxd4q.mongodb.net:27017: [WinError 10013] Intento de acceso a un socket no permitido por sus permisos de acceso (configured timeouts: socketTimeoutMS: 20000.0ms, connectTimeoutMS: 20000.0ms), Timeout: 30s, Topology Description: <TopologyDescription id: 6654c7f11ee59c591e0bbbd2, topology_type: ReplicaSetNoPrimary, servers: [<ServerDescription ('ac-7zrxalx-shard-00-00.v1mxd4q.mongodb.net', 27017) server_type: Unknown, rtt: None, error=AutoReconnect('ac-7zrxalx-shard-00-00.v1mxd4q.mongodb.net:27017: [WinError 10013] Intento de acceso a un socket no permitido por sus permisos de acceso (configured timeouts: socketTimeoutMS: 20000.0ms, connectTimeoutMS: 20000.0ms)')>, <ServerDescription ('ac-7zrxalx-shard-00-01.v1mxd4q.mongodb.net', 27017) server_type: Unknown, rtt: None, error=AutoReconnect('ac-7zrxalx-shard-00-01.v1mxd4q.mongodb.net:27017: [WinError 10013] Intento de acceso a un socket no permitido por sus permisos de acceso (configured timeouts: socketTimeoutMS: 20000.0ms, connectTimeoutMS: 20000.0ms)')>, <ServerDescription ('ac-7zrxalx-shard-00-02.v1mxd4q.mongodb.net', 27017) server_type: Unknown, rtt: None, error=AutoReconnect('ac-7zrxalx-shard-00-02.v1mxd4q.mongodb.net:27017: [WinError 10013] Intento de acceso a un socket no permitido por sus permisos de acceso (configured timeouts: socketTimeoutMS: 20000.0ms, connectTimeoutMS: 20000.0ms)')>]>")>
Traceback (most recent call last):
  File "C:\Users\martimasxax\AppData\Local\Packages\PythonSoftwareFoundation.Python.3.12_qbz5n2kfra8p0\LocalCache\local-packages\Python312\site-packages\pymongo\pool.py", line 1020, in receive_message
    return receive_message(self, request_id, self.max_message_size)
           ^^^^^^^^^^^^^^^^^^^^^^^^^^^^^^^^^^^^^^^^^^^^^^^^^^^^^^^^
  File "C:\Users\martimasxax\AppData\Local\Packages\PythonSoftwareFoundation.Python.3.12_qbz5n2kfra8p0\LocalCache\local-packages\Python312\site-packages\pymongo\network.py", line 257, in receive_message
    length, _, response_to, op_code = _UNPACK_HEADER(_receive_data_on_socket(conn, 16, deadline))
                                                     ^^^^^^^^^^^^^^^^^^^^^^^^^^^^^^^^^^^^^^^^^^^
  File "C:\Users\martimasxax\AppData\Local\Packages\PythonSoftwareFoundation.Python.3.12_qbz5n2kfra8p0\LocalCache\local-packages\Python312\site-packages\pymongo\network.py", line 340, in _receive_data_on_socket
    chunk_length = conn.conn.recv_into(mv[bytes_read:])
                   ^^^^^^^^^^^^^^^^^^^^^^^^^^^^^^^^^^^^
  File "C:\Users\martimasxax\AppData\Local\Packages\PythonSoftwareFoundation.Python.3.12_qbz5n2kfra8p0\LocalCache\local-packages\Python312\site-packages\pymongo\pyopenssl_context.py", line 155, in recv_into
    return self._call(super().recv_into, *args, **kwargs)
           ^^^^^^^^^^^^^^^^^^^^^^^^^^^^^^^^^^^^^^^^^^^^^^
  File "C:\Users\martimasxax\AppData\Local\Packages\PythonSoftwareFoundation.Python.3.12_qbz5n2kfra8p0\LocalCache\local-packages\Python312\site-packages\pymongo\pyopenssl_context.py", line 120, in _call
    return call(*args, **kwargs)
           ^^^^^^^^^^^^^^^^^^^^^
  File "C:\Users\martimasxax\AppData\Local\Packages\PythonSoftwareFoundation.Python.3.12_qbz5n2kfra8p0\LocalCache\local-packages\Python312\site-packages\OpenSSL\SSL.py", line 2099, in recv_into
    self._raise_ssl_error(self._ssl, result)
  File "C:\Users\martimasxax\AppData\Local\Packages\PythonSoftwareFoundation.Python.3.12_qbz5n2kfra8p0\LocalCache\local-packages\Python312\site-packages\OpenSSL\SSL.py", line 1818, in _raise_ssl_error
    raise SysCallError(errno, errorcode.get(errno))
OpenSSL.SSL.SysCallError: (10053, 'WSAECONNABORTED')

The above exception was the direct cause of the following exception:

Traceback (most recent call last):
  File "C:\Users\martimasxax\AppData\Local\Packages\PythonSoftwareFoundation.Python.3.12_qbz5n2kfra8p0\LocalCache\local-packages\Python312\site-packages\pymongo\change_stream.py", line 372, in try_next
    change = self._cursor._try_next(True)
             ^^^^^^^^^^^^^^^^^^^^^^^^^^^^
  File "C:\Users\martimasxax\AppData\Local\Packages\PythonSoftwareFoundation.Python.3.12_qbz5n2kfra8p0\LocalCache\local-packages\Python312\site-packages\pymongo\command_cursor.py", line 321, in _try_next
    self._refresh()
  File "C:\Users\martimasxax\AppData\Local\Packages\PythonSoftwareFoundation.Python.3.12_qbz5n2kfra8p0\LocalCache\local-packages\Python312\site-packages\pymongo\command_cursor.py", line 242, in _refresh
    self.__send_message(
  File "C:\Users\martimasxax\AppData\Local\Packages\PythonSoftwareFoundation.Python.3.12_qbz5n2kfra8p0\LocalCache\local-packages\Python312\site-packages\pymongo\command_cursor.py", line 179, in __send_message
    response = client._run_operation(
               ^^^^^^^^^^^^^^^^^^^^^^
  File "C:\Users\martimasxax\AppData\Local\Packages\PythonSoftwareFoundation.Python.3.12_qbz5n2kfra8p0\LocalCache\local-packages\Python312\site-packages\pymongo\_csot.py", line 107, in csot_wrapper
    return func(self, *args, **kwargs)
           ^^^^^^^^^^^^^^^^^^^^^^^^^^^
  File "C:\Users\martimasxax\AppData\Local\Packages\PythonSoftwareFoundation.Python.3.12_qbz5n2kfra8p0\LocalCache\local-packages\Python312\site-packages\pymongo\mongo_client.py", line 1394, in _run_operation
    return self._retryable_read(
           ^^^^^^^^^^^^^^^^^^^^^
  File "C:\Users\martimasxax\AppData\Local\Packages\PythonSoftwareFoundation.Python.3.12_qbz5n2kfra8p0\LocalCache\local-packages\Python312\site-packages\pymongo\mongo_client.py", line 1492, in _retryable_read
    return self._retry_internal(
           ^^^^^^^^^^^^^^^^^^^^^
  File "C:\Users\martimasxax\AppData\Local\Packages\PythonSoftwareFoundation.Python.3.12_qbz5n2kfra8p0\LocalCache\local-packages\Python312\site-packages\pymongo\_csot.py", line 107, in csot_wrapper
    return func(self, *args, **kwargs)
           ^^^^^^^^^^^^^^^^^^^^^^^^^^^
  File "C:\Users\martimasxax\AppData\Local\Packages\PythonSoftwareFoundation.Python.3.12_qbz5n2kfra8p0\LocalCache\local-packages\Python312\site-packages\pymongo\mongo_client.py", line 1462, in _retry_internal
    ).run()
      ^^^^^
  File "C:\Users\martimasxax\AppData\Local\Packages\PythonSoftwareFoundation.Python.3.12_qbz5n2kfra8p0\LocalCache\local-packages\Python312\site-packages\pymongo\mongo_client.py", line 2315, in run
    return self._read() if self._is_read else self._write()
           ^^^^^^^^^^^^
  File "C:\Users\martimasxax\AppData\Local\Packages\PythonSoftwareFoundation.Python.3.12_qbz5n2kfra8p0\LocalCache\local-packages\Python312\site-packages\pymongo\mongo_client.py", line 2445, in _read
    return self._func(self._session, self._server, conn, read_pref)  # type: ignore
           ^^^^^^^^^^^^^^^^^^^^^^^^^^^^^^^^^^^^^^^^^^^^^^^^^^^^^^^^
  File "C:\Users\martimasxax\AppData\Local\Packages\PythonSoftwareFoundation.Python.3.12_qbz5n2kfra8p0\LocalCache\local-packages\Python312\site-packages\pymongo\mongo_client.py", line 1390, in _cmd
    return server.run_operation(
           ^^^^^^^^^^^^^^^^^^^^^
  File "C:\Users\martimasxax\AppData\Local\Packages\PythonSoftwareFoundation.Python.3.12_qbz5n2kfra8p0\LocalCache\local-packages\Python312\site-packages\pymongo\helpers.py", line 322, in inner
    return func(*args, **kwargs)
           ^^^^^^^^^^^^^^^^^^^^^
  File "C:\Users\martimasxax\AppData\Local\Packages\PythonSoftwareFoundation.Python.3.12_qbz5n2kfra8p0\LocalCache\local-packages\Python312\site-packages\pymongo\server.py", line 148, in run_operation
    reply = conn.receive_message(request_id)
            ^^^^^^^^^^^^^^^^^^^^^^^^^^^^^^^^
  File "C:\Users\martimasxax\AppData\Local\Packages\PythonSoftwareFoundation.Python.3.12_qbz5n2kfra8p0\LocalCache\local-packages\Python312\site-packages\pymongo\pool.py", line 1022, in receive_message
    self._raise_connection_failure(error)
  File "C:\Users\martimasxax\AppData\Local\Packages\PythonSoftwareFoundation.Python.3.12_qbz5n2kfra8p0\LocalCache\local-packages\Python312\site-packages\pymongo\pool.py", line 1171, in _raise_connection_failure
    _raise_connection_failure(self.address, error, timeout_details=details)
  File "C:\Users\martimasxax\AppData\Local\Packages\PythonSoftwareFoundation.Python.3.12_qbz5n2kfra8p0\LocalCache\local-packages\Python312\site-packages\pymongo\pool.py", line 411, in _raise_connection_failure
    raise AutoReconnect(msg) from error
pymongo.errors.AutoReconnect: ac-7zrxalx-shard-00-01.v1mxd4q.mongodb.net:27017: (10053, 'WSAECONNABORTED') (configured timeouts: connectTimeoutMS: 20000.0ms)

During handling of the above exception, another exception occurred:

Traceback (most recent call last):
  File "E:\Project\Back4\BN-BackEnd\config\changeStream.py", line 7, in watch_changes
    async for change in stream:
  File "C:\Users\martimasxax\AppData\Local\Packages\PythonSoftwareFoundation.Python.3.12_qbz5n2kfra8p0\LocalCache\local-packages\Python312\site-packages\motor\core.py", line 2038, in next
    doc = await self.try_next()
          ^^^^^^^^^^^^^^^^^^^^^
  File "C:\Users\martimasxax\AppData\Local\Packages\PythonSoftwareFoundation.Python.3.12_qbz5n2kfra8p0\LocalCache\local-packages\Python312\site-packages\motor\core.py", line 2079, in try_next
    return await self._framework.run_on_executor(loop, self._try_next)
           ^^^^^^^^^^^^^^^^^^^^^^^^^^^^^^^^^^^^^^^^^^^^^^^^^^^^^^^^^^^
  File "C:\Program Files\WindowsApps\PythonSoftwareFoundation.Python.3.12_3.12.1008.0_x64__qbz5n2kfra8p0\Lib\concurrent\futures\thread.py", line 58, in run
    result = self.fn(*self.args, **self.kwargs)
             ^^^^^^^^^^^^^^^^^^^^^^^^^^^^^^^^^^
  File "C:\Users\martimasxax\AppData\Local\Packages\PythonSoftwareFoundation.Python.3.12_qbz5n2kfra8p0\LocalCache\local-packages\Python312\site-packages\motor\core.py", line 1984, in _try_next
    return self.delegate.try_next()
           ^^^^^^^^^^^^^^^^^^^^^^^^
  File "C:\Users\martimasxax\AppData\Local\Packages\PythonSoftwareFoundation.Python.3.12_qbz5n2kfra8p0\LocalCache\local-packages\Python312\site-packages\pymongo\_csot.py", line 107, in csot_wrapper
    return func(self, *args, **kwargs)
           ^^^^^^^^^^^^^^^^^^^^^^^^^^^
  File "C:\Users\martimasxax\AppData\Local\Packages\PythonSoftwareFoundation.Python.3.12_qbz5n2kfra8p0\LocalCache\local-packages\Python312\site-packages\pymongo\change_stream.py", line 376, in try_next
    self._resume()
  File "C:\Users\martimasxax\AppData\Local\Packages\PythonSoftwareFoundation.Python.3.12_qbz5n2kfra8p0\LocalCache\local-packages\Python312\site-packages\pymongo\change_stream.py", line 260, in _resume
    self._cursor = self._create_cursor()
                   ^^^^^^^^^^^^^^^^^^^^^
  File "C:\Users\martimasxax\AppData\Local\Packages\PythonSoftwareFoundation.Python.3.12_qbz5n2kfra8p0\LocalCache\local-packages\Python312\site-packages\pymongo\change_stream.py", line 252, in _create_cursor
    return self._run_aggregation_cmd(session=s, explicit_session=self._session is not None)
           ^^^^^^^^^^^^^^^^^^^^^^^^^^^^^^^^^^^^^^^^^^^^^^^^^^^^^^^^^^^^^^^^^^^^^^^^^^^^^^^^
  File "C:\Users\martimasxax\AppData\Local\Packages\PythonSoftwareFoundation.Python.3.12_qbz5n2kfra8p0\LocalCache\local-packages\Python312\site-packages\pymongo\change_stream.py", line 246, in _run_aggregation_cmd
    return self._client._retryable_read(
           ^^^^^^^^^^^^^^^^^^^^^^^^^^^^^
  File "C:\Users\martimasxax\AppData\Local\Packages\PythonSoftwareFoundation.Python.3.12_qbz5n2kfra8p0\LocalCache\local-packages\Python312\site-packages\pymongo\mongo_client.py", line 1492, in _retryable_read
    return self._retry_internal(
           ^^^^^^^^^^^^^^^^^^^^^
  File "C:\Users\martimasxax\AppData\Local\Packages\PythonSoftwareFoundation.Python.3.12_qbz5n2kfra8p0\LocalCache\local-packages\Python312\site-packages\pymongo\_csot.py", line 107, in csot_wrapper
    return func(self, *args, **kwargs)
           ^^^^^^^^^^^^^^^^^^^^^^^^^^^
  File "C:\Users\martimasxax\AppData\Local\Packages\PythonSoftwareFoundation.Python.3.12_qbz5n2kfra8p0\LocalCache\local-packages\Python312\site-packages\pymongo\mongo_client.py", line 1462, in _retry_internal
    ).run()
      ^^^^^
  File "C:\Users\martimasxax\AppData\Local\Packages\PythonSoftwareFoundation.Python.3.12_qbz5n2kfra8p0\LocalCache\local-packages\Python312\site-packages\pymongo\mongo_client.py", line 2315, in run
    return self._read() if self._is_read else self._write()
           ^^^^^^^^^^^^
  File "C:\Users\martimasxax\AppData\Local\Packages\PythonSoftwareFoundation.Python.3.12_qbz5n2kfra8p0\LocalCache\local-packages\Python312\site-packages\pymongo\mongo_client.py", line 2437, in _read
    self._server = self._get_server()
                   ^^^^^^^^^^^^^^^^^^
  File "C:\Users\martimasxax\AppData\Local\Packages\PythonSoftwareFoundation.Python.3.12_qbz5n2kfra8p0\LocalCache\local-packages\Python312\site-packages\pymongo\mongo_client.py", line 2400, in _get_server
    return self._client._select_server(
           ^^^^^^^^^^^^^^^^^^^^^^^^^^^^
  File "C:\Users\martimasxax\AppData\Local\Packages\PythonSoftwareFoundation.Python.3.12_qbz5n2kfra8p0\LocalCache\local-packages\Python312\site-packages\pymongo\mongo_client.py", line 1303, in _select_server
    server = topology.select_server(server_selector)
             ^^^^^^^^^^^^^^^^^^^^^^^^^^^^^^^^^^^^^^^
  File "C:\Users\martimasxax\AppData\Local\Packages\PythonSoftwareFoundation.Python.3.12_qbz5n2kfra8p0\LocalCache\local-packages\Python312\site-packages\pymongo\topology.py", line 302, in select_server
    server = self._select_server(selector, server_selection_timeout, address)
             ^^^^^^^^^^^^^^^^^^^^^^^^^^^^^^^^^^^^^^^^^^^^^^^^^^^^^^^^^^^^^^^^
  File "C:\Users\martimasxax\AppData\Local\Packages\PythonSoftwareFoundation.Python.3.12_qbz5n2kfra8p0\LocalCache\local-packages\Python312\site-packages\pymongo\topology.py", line 286, in _select_server
    servers = self.select_servers(selector, server_selection_timeout, address)
              ^^^^^^^^^^^^^^^^^^^^^^^^^^^^^^^^^^^^^^^^^^^^^^^^^^^^^^^^^^^^^^^^
  File "C:\Users\martimasxax\AppData\Local\Packages\PythonSoftwareFoundation.Python.3.12_qbz5n2kfra8p0\LocalCache\local-packages\Python312\site-packages\pymongo\topology.py", line 237, in select_servers
    server_descriptions = self._select_servers_loop(selector, server_timeout, address)
                          ^^^^^^^^^^^^^^^^^^^^^^^^^^^^^^^^^^^^^^^^^^^^^^^^^^^^^^^^^^^^
  File "C:\Users\martimasxax\AppData\Local\Packages\PythonSoftwareFoundation.Python.3.12_qbz5n2kfra8p0\LocalCache\local-packages\Python312\site-packages\pymongo\topology.py", line 259, in _select_servers_loop
    raise ServerSelectionTimeoutError(
pymongo.errors.ServerSelectionTimeoutError: ac-7zrxalx-shard-00-01.v1mxd4q.mongodb.net:27017: [WinError 10013] Intento de acceso a un socket no permitido por sus permisos de acceso (configured timeouts: socketTimeoutMS: 20000.0ms, connectTimeoutMS: 20000.0ms),ac-7zrxalx-shard-00-02.v1mxd4q.mongodb.net:27017: [WinError 10013] Intento de acceso a un socket no permitido por sus permisos de acceso (configured timeouts: socketTimeoutMS: 20000.0ms, connectTimeoutMS: 20000.0ms),ac-7zrxalx-shard-00-00.v1mxd4q.mongodb.net:27017: [WinError 10013] Intento de acceso a un socket no permitido por sus permisos de acceso (configured timeouts: socketTimeoutMS: 20000.0ms, connectTimeoutMS: 20000.0ms), Timeout: 30s, Topology Description: <TopologyDescription id: 6654c7f11ee59c591e0bbbd2, topology_type: ReplicaSetNoPrimary, servers: [<ServerDescription ('ac-7zrxalx-shard-00-00.v1mxd4q.mongodb.net', 27017) server_type: Unknown, rtt: None, error=AutoReconnect('ac-7zrxalx-shard-00-00.v1mxd4q.mongodb.net:27017: [WinError 10013] Intento de acceso a un socket no permitido por sus permisos de acceso (configured timeouts: socketTimeoutMS: 20000.0ms, connectTimeoutMS: 20000.0ms)')>, <ServerDescription ('ac-7zrxalx-shard-00-01.v1mxd4q.mongodb.net', 27017) server_type: Unknown, rtt: None, error=AutoReconnect('ac-7zrxalx-shard-00-01.v1mxd4q.mongodb.net:27017: [WinError 10013] Intento de acceso a un socket no permitido por sus permisos de acceso (configured timeouts: socketTimeoutMS: 20000.0ms, connectTimeoutMS: 20000.0ms)')>, <ServerDescription ('ac-7zrxalx-shard-00-02.v1mxd4q.mongodb.net', 27017) server_type: Unknown, rtt: None, error=AutoReconnect('ac-7zrxalx-shard-00-02.v1mxd4q.mongodb.net:27017: [WinError 10013] Intento de acceso a un socket no permitido por sus permisos de acceso (configured timeouts: socketTimeoutMS: 20000.0ms, connectTimeoutMS: 20000.0ms)')>]>
ERROR:asyncio:Task exception was never retrieved
future: <Task finished name='Task-3' coro=<watch_changes() done, defined at E:\Project\Back4\BN-BackEnd\config\changeStream.py:5> exception=ServerSelectionTimeoutError("ac-7zrxalx-shard-00-01.v1mxd4q.mongodb.net:27017: [WinError 10013] Intento de acceso a un socket no permitido por sus permisos de acceso (configured timeouts: socketTimeoutMS: 20000.0ms, connectTimeoutMS: 20000.0ms),ac-7zrxalx-shard-00-02.v1mxd4q.mongodb.net:27017: [WinError 10013] Intento de acceso a un socket no permitido por sus permisos de acceso (configured timeouts: socketTimeoutMS: 20000.0ms, connectTimeoutMS: 20000.0ms),ac-7zrxalx-shard-00-00.v1mxd4q.mongodb.net:27017: [WinError 10013] Intento de acceso a un socket no permitido por sus permisos de acceso (configured timeouts: socketTimeoutMS: 20000.0ms, connectTimeoutMS: 20000.0ms), Timeout: 30s, Topology Description: <TopologyDescription id: 665889bf91c27085cc191084, topology_type: ReplicaSetNoPrimary, servers: [<ServerDescription ('ac-7zrxalx-shard-00-00.v1mxd4q.mongodb.net', 27017) server_type: Unknown, rtt: None, error=AutoReconnect('ac-7zrxalx-shard-00-00.v1mxd4q.mongodb.net:27017: [WinError 10013] Intento de acceso a un socket no permitido por sus permisos de acceso (configured timeouts: socketTimeoutMS: 20000.0ms, connectTimeoutMS: 20000.0ms)')>, <ServerDescription ('ac-7zrxalx-shard-00-01.v1mxd4q.mongodb.net', 27017) server_type: Unknown, rtt: None, error=AutoReconnect('ac-7zrxalx-shard-00-01.v1mxd4q.mongodb.net:27017: [WinError 10013] Intento de acceso a un socket no permitido por sus permisos de acceso (configured timeouts: socketTimeoutMS: 20000.0ms, connectTimeoutMS: 20000.0ms)')>, <ServerDescription ('ac-7zrxalx-shard-00-02.v1mxd4q.mongodb.net', 27017) server_type: Unknown, rtt: None, error=AutoReconnect('ac-7zrxalx-shard-00-02.v1mxd4q.mongodb.net:27017: [WinError 10013] Intento de acceso a un socket no permitido por sus permisos de acceso (configured timeouts: socketTimeoutMS: 20000.0ms, connectTimeoutMS: 20000.0ms)')>]>")>
Traceback (most recent call last):
  File "C:\Users\martimasxax\AppData\Local\Packages\PythonSoftwareFoundation.Python.3.12_qbz5n2kfra8p0\LocalCache\local-packages\Python312\site-packages\pymongo\pool.py", line 1020, in receive_message
    return receive_message(self, request_id, self.max_message_size)
           ^^^^^^^^^^^^^^^^^^^^^^^^^^^^^^^^^^^^^^^^^^^^^^^^^^^^^^^^
  File "C:\Users\martimasxax\AppData\Local\Packages\PythonSoftwareFoundation.Python.3.12_qbz5n2kfra8p0\LocalCache\local-packages\Python312\site-packages\pymongo\network.py", line 257, in receive_message
    length, _, response_to, op_code = _UNPACK_HEADER(_receive_data_on_socket(conn, 16, deadline))
                                                     ^^^^^^^^^^^^^^^^^^^^^^^^^^^^^^^^^^^^^^^^^^^
  File "C:\Users\martimasxax\AppData\Local\Packages\PythonSoftwareFoundation.Python.3.12_qbz5n2kfra8p0\LocalCache\local-packages\Python312\site-packages\pymongo\network.py", line 340, in _receive_data_on_socket
    chunk_length = conn.conn.recv_into(mv[bytes_read:])
                   ^^^^^^^^^^^^^^^^^^^^^^^^^^^^^^^^^^^^
  File "C:\Users\martimasxax\AppData\Local\Packages\PythonSoftwareFoundation.Python.3.12_qbz5n2kfra8p0\LocalCache\local-packages\Python312\site-packages\pymongo\pyopenssl_context.py", line 155, in recv_into
    return self._call(super().recv_into, *args, **kwargs)
           ^^^^^^^^^^^^^^^^^^^^^^^^^^^^^^^^^^^^^^^^^^^^^^
  File "C:\Users\martimasxax\AppData\Local\Packages\PythonSoftwareFoundation.Python.3.12_qbz5n2kfra8p0\LocalCache\local-packages\Python312\site-packages\pymongo\pyopenssl_context.py", line 120, in _call
    return call(*args, **kwargs)
           ^^^^^^^^^^^^^^^^^^^^^
  File "C:\Users\martimasxax\AppData\Local\Packages\PythonSoftwareFoundation.Python.3.12_qbz5n2kfra8p0\LocalCache\local-packages\Python312\site-packages\OpenSSL\SSL.py", line 2099, in recv_into
    self._raise_ssl_error(self._ssl, result)
  File "C:\Users\martimasxax\AppData\Local\Packages\PythonSoftwareFoundation.Python.3.12_qbz5n2kfra8p0\LocalCache\local-packages\Python312\site-packages\OpenSSL\SSL.py", line 1818, in _raise_ssl_error
    raise SysCallError(errno, errorcode.get(errno))
OpenSSL.SSL.SysCallError: (10053, 'WSAECONNABORTED')

The above exception was the direct cause of the following exception:

Traceback (most recent call last):
  File "C:\Users\martimasxax\AppData\Local\Packages\PythonSoftwareFoundation.Python.3.12_qbz5n2kfra8p0\LocalCache\local-packages\Python312\site-packages\pymongo\change_stream.py", line 372, in try_next
    change = self._cursor._try_next(True)
             ^^^^^^^^^^^^^^^^^^^^^^^^^^^^
  File "C:\Users\martimasxax\AppData\Local\Packages\PythonSoftwareFoundation.Python.3.12_qbz5n2kfra8p0\LocalCache\local-packages\Python312\site-packages\pymongo\command_cursor.py", line 321, in _try_next
    self._refresh()
  File "C:\Users\martimasxax\AppData\Local\Packages\PythonSoftwareFoundation.Python.3.12_qbz5n2kfra8p0\LocalCache\local-packages\Python312\site-packages\pymongo\command_cursor.py", line 242, in _refresh
    self.__send_message(
  File "C:\Users\martimasxax\AppData\Local\Packages\PythonSoftwareFoundation.Python.3.12_qbz5n2kfra8p0\LocalCache\local-packages\Python312\site-packages\pymongo\command_cursor.py", line 179, in __send_message
    response = client._run_operation(
               ^^^^^^^^^^^^^^^^^^^^^^
  File "C:\Users\martimasxax\AppData\Local\Packages\PythonSoftwareFoundation.Python.3.12_qbz5n2kfra8p0\LocalCache\local-packages\Python312\site-packages\pymongo\_csot.py", line 107, in csot_wrapper
    return func(self, *args, **kwargs)
           ^^^^^^^^^^^^^^^^^^^^^^^^^^^
  File "C:\Users\martimasxax\AppData\Local\Packages\PythonSoftwareFoundation.Python.3.12_qbz5n2kfra8p0\LocalCache\local-packages\Python312\site-packages\pymongo\mongo_client.py", line 1394, in _run_operation
    return self._retryable_read(
           ^^^^^^^^^^^^^^^^^^^^^
  File "C:\Users\martimasxax\AppData\Local\Packages\PythonSoftwareFoundation.Python.3.12_qbz5n2kfra8p0\LocalCache\local-packages\Python312\site-packages\pymongo\mongo_client.py", line 1492, in _retryable_read
    return self._retry_internal(
           ^^^^^^^^^^^^^^^^^^^^^
  File "C:\Users\martimasxax\AppData\Local\Packages\PythonSoftwareFoundation.Python.3.12_qbz5n2kfra8p0\LocalCache\local-packages\Python312\site-packages\pymongo\_csot.py", line 107, in csot_wrapper
    return func(self, *args, **kwargs)
           ^^^^^^^^^^^^^^^^^^^^^^^^^^^
  File "C:\Users\martimasxax\AppData\Local\Packages\PythonSoftwareFoundation.Python.3.12_qbz5n2kfra8p0\LocalCache\local-packages\Python312\site-packages\pymongo\mongo_client.py", line 1462, in _retry_internal
    ).run()
      ^^^^^
  File "C:\Users\martimasxax\AppData\Local\Packages\PythonSoftwareFoundation.Python.3.12_qbz5n2kfra8p0\LocalCache\local-packages\Python312\site-packages\pymongo\mongo_client.py", line 2315, in run
    return self._read() if self._is_read else self._write()
           ^^^^^^^^^^^^
  File "C:\Users\martimasxax\AppData\Local\Packages\PythonSoftwareFoundation.Python.3.12_qbz5n2kfra8p0\LocalCache\local-packages\Python312\site-packages\pymongo\mongo_client.py", line 2445, in _read
    return self._func(self._session, self._server, conn, read_pref)  # type: ignore
           ^^^^^^^^^^^^^^^^^^^^^^^^^^^^^^^^^^^^^^^^^^^^^^^^^^^^^^^^
  File "C:\Users\martimasxax\AppData\Local\Packages\PythonSoftwareFoundation.Python.3.12_qbz5n2kfra8p0\LocalCache\local-packages\Python312\site-packages\pymongo\mongo_client.py", line 1390, in _cmd
    return server.run_operation(
           ^^^^^^^^^^^^^^^^^^^^^
  File "C:\Users\martimasxax\AppData\Local\Packages\PythonSoftwareFoundation.Python.3.12_qbz5n2kfra8p0\LocalCache\local-packages\Python312\site-packages\pymongo\helpers.py", line 322, in inner
    return func(*args, **kwargs)
           ^^^^^^^^^^^^^^^^^^^^^
  File "C:\Users\martimasxax\AppData\Local\Packages\PythonSoftwareFoundation.Python.3.12_qbz5n2kfra8p0\LocalCache\local-packages\Python312\site-packages\pymongo\server.py", line 148, in run_operation
    reply = conn.receive_message(request_id)
            ^^^^^^^^^^^^^^^^^^^^^^^^^^^^^^^^
  File "C:\Users\martimasxax\AppData\Local\Packages\PythonSoftwareFoundation.Python.3.12_qbz5n2kfra8p0\LocalCache\local-packages\Python312\site-packages\pymongo\pool.py", line 1022, in receive_message
    self._raise_connection_failure(error)
  File "C:\Users\martimasxax\AppData\Local\Packages\PythonSoftwareFoundation.Python.3.12_qbz5n2kfra8p0\LocalCache\local-packages\Python312\site-packages\pymongo\pool.py", line 1171, in _raise_connection_failure
    _raise_connection_failure(self.address, error, timeout_details=details)
  File "C:\Users\martimasxax\AppData\Local\Packages\PythonSoftwareFoundation.Python.3.12_qbz5n2kfra8p0\LocalCache\local-packages\Python312\site-packages\pymongo\pool.py", line 411, in _raise_connection_failure
    raise AutoReconnect(msg) from error
pymongo.errors.AutoReconnect: ac-7zrxalx-shard-00-02.v1mxd4q.mongodb.net:27017: (10053, 'WSAECONNABORTED') (configured timeouts: connectTimeoutMS: 20000.0ms)

During handling of the above exception, another exception occurred:

Traceback (most recent call last):
  File "E:\Project\Back4\BN-BackEnd\config\changeStream.py", line 7, in watch_changes
    async for change in stream:
  File "C:\Users\martimasxax\AppData\Local\Packages\PythonSoftwareFoundation.Python.3.12_qbz5n2kfra8p0\LocalCache\local-packages\Python312\site-packages\motor\core.py", line 2038, in next
    doc = await self.try_next()
          ^^^^^^^^^^^^^^^^^^^^^
  File "C:\Users\martimasxax\AppData\Local\Packages\PythonSoftwareFoundation.Python.3.12_qbz5n2kfra8p0\LocalCache\local-packages\Python312\site-packages\motor\core.py", line 2079, in try_next
    return await self._framework.run_on_executor(loop, self._try_next)
           ^^^^^^^^^^^^^^^^^^^^^^^^^^^^^^^^^^^^^^^^^^^^^^^^^^^^^^^^^^^
  File "C:\Program Files\WindowsApps\PythonSoftwareFoundation.Python.3.12_3.12.1008.0_x64__qbz5n2kfra8p0\Lib\concurrent\futures\thread.py", line 58, in run
    result = self.fn(*self.args, **self.kwargs)
             ^^^^^^^^^^^^^^^^^^^^^^^^^^^^^^^^^^
  File "C:\Users\martimasxax\AppData\Local\Packages\PythonSoftwareFoundation.Python.3.12_qbz5n2kfra8p0\LocalCache\local-packages\Python312\site-packages\motor\core.py", line 1984, in _try_next
    return self.delegate.try_next()
           ^^^^^^^^^^^^^^^^^^^^^^^^
  File "C:\Users\martimasxax\AppData\Local\Packages\PythonSoftwareFoundation.Python.3.12_qbz5n2kfra8p0\LocalCache\local-packages\Python312\site-packages\pymongo\_csot.py", line 107, in csot_wrapper
    return func(self, *args, **kwargs)
           ^^^^^^^^^^^^^^^^^^^^^^^^^^^
  File "C:\Users\martimasxax\AppData\Local\Packages\PythonSoftwareFoundation.Python.3.12_qbz5n2kfra8p0\LocalCache\local-packages\Python312\site-packages\pymongo\change_stream.py", line 376, in try_next
    self._resume()
  File "C:\Users\martimasxax\AppData\Local\Packages\PythonSoftwareFoundation.Python.3.12_qbz5n2kfra8p0\LocalCache\local-packages\Python312\site-packages\pymongo\change_stream.py", line 260, in _resume
    self._cursor = self._create_cursor()
                   ^^^^^^^^^^^^^^^^^^^^^
  File "C:\Users\martimasxax\AppData\Local\Packages\PythonSoftwareFoundation.Python.3.12_qbz5n2kfra8p0\LocalCache\local-packages\Python312\site-packages\pymongo\change_stream.py", line 252, in _create_cursor
    return self._run_aggregation_cmd(session=s, explicit_session=self._session is not None)
           ^^^^^^^^^^^^^^^^^^^^^^^^^^^^^^^^^^^^^^^^^^^^^^^^^^^^^^^^^^^^^^^^^^^^^^^^^^^^^^^^
  File "C:\Users\martimasxax\AppData\Local\Packages\PythonSoftwareFoundation.Python.3.12_qbz5n2kfra8p0\LocalCache\local-packages\Python312\site-packages\pymongo\change_stream.py", line 246, in _run_aggregation_cmd
    return self._client._retryable_read(
           ^^^^^^^^^^^^^^^^^^^^^^^^^^^^^
  File "C:\Users\martimasxax\AppData\Local\Packages\PythonSoftwareFoundation.Python.3.12_qbz5n2kfra8p0\LocalCache\local-packages\Python312\site-packages\pymongo\mongo_client.py", line 1492, in _retryable_read
    return self._retry_internal(
           ^^^^^^^^^^^^^^^^^^^^^
  File "C:\Users\martimasxax\AppData\Local\Packages\PythonSoftwareFoundation.Python.3.12_qbz5n2kfra8p0\LocalCache\local-packages\Python312\site-packages\pymongo\_csot.py", line 107, in csot_wrapper
    return func(self, *args, **kwargs)
           ^^^^^^^^^^^^^^^^^^^^^^^^^^^
  File "C:\Users\martimasxax\AppData\Local\Packages\PythonSoftwareFoundation.Python.3.12_qbz5n2kfra8p0\LocalCache\local-packages\Python312\site-packages\pymongo\mongo_client.py", line 1462, in _retry_internal
    ).run()
      ^^^^^
  File "C:\Users\martimasxax\AppData\Local\Packages\PythonSoftwareFoundation.Python.3.12_qbz5n2kfra8p0\LocalCache\local-packages\Python312\site-packages\pymongo\mongo_client.py", line 2315, in run
    return self._read() if self._is_read else self._write()
           ^^^^^^^^^^^^
  File "C:\Users\martimasxax\AppData\Local\Packages\PythonSoftwareFoundation.Python.3.12_qbz5n2kfra8p0\LocalCache\local-packages\Python312\site-packages\pymongo\mongo_client.py", line 2437, in _read
    self._server = self._get_server()
                   ^^^^^^^^^^^^^^^^^^
  File "C:\Users\martimasxax\AppData\Local\Packages\PythonSoftwareFoundation.Python.3.12_qbz5n2kfra8p0\LocalCache\local-packages\Python312\site-packages\pymongo\mongo_client.py", line 2400, in _get_server
    return self._client._select_server(
           ^^^^^^^^^^^^^^^^^^^^^^^^^^^^
  File "C:\Users\martimasxax\AppData\Local\Packages\PythonSoftwareFoundation.Python.3.12_qbz5n2kfra8p0\LocalCache\local-packages\Python312\site-packages\pymongo\mongo_client.py", line 1303, in _select_server
    server = topology.select_server(server_selector)
             ^^^^^^^^^^^^^^^^^^^^^^^^^^^^^^^^^^^^^^^
  File "C:\Users\martimasxax\AppData\Local\Packages\PythonSoftwareFoundation.Python.3.12_qbz5n2kfra8p0\LocalCache\local-packages\Python312\site-packages\pymongo\topology.py", line 302, in select_server
    server = self._select_server(selector, server_selection_timeout, address)
             ^^^^^^^^^^^^^^^^^^^^^^^^^^^^^^^^^^^^^^^^^^^^^^^^^^^^^^^^^^^^^^^^
  File "C:\Users\martimasxax\AppData\Local\Packages\PythonSoftwareFoundation.Python.3.12_qbz5n2kfra8p0\LocalCache\local-packages\Python312\site-packages\pymongo\topology.py", line 286, in _select_server
    servers = self.select_servers(selector, server_selection_timeout, address)
              ^^^^^^^^^^^^^^^^^^^^^^^^^^^^^^^^^^^^^^^^^^^^^^^^^^^^^^^^^^^^^^^^
  File "C:\Users\martimasxax\AppData\Local\Packages\PythonSoftwareFoundation.Python.3.12_qbz5n2kfra8p0\LocalCache\local-packages\Python312\site-packages\pymongo\topology.py", line 237, in select_servers
    server_descriptions = self._select_servers_loop(selector, server_timeout, address)
                          ^^^^^^^^^^^^^^^^^^^^^^^^^^^^^^^^^^^^^^^^^^^^^^^^^^^^^^^^^^^^
  File "C:\Users\martimasxax\AppData\Local\Packages\PythonSoftwareFoundation.Python.3.12_qbz5n2kfra8p0\LocalCache\local-packages\Python312\site-packages\pymongo\topology.py", line 259, in _select_servers_loop
    raise ServerSelectionTimeoutError(
pymongo.errors.ServerSelectionTimeoutError: ac-7zrxalx-shard-00-01.v1mxd4q.mongodb.net:27017: [WinError 10013] Intento de acceso a un socket no permitido por sus permisos de acceso (configured timeouts: socketTimeoutMS: 20000.0ms, connectTimeoutMS: 20000.0ms),ac-7zrxalx-shard-00-02.v1mxd4q.mongodb.net:27017: [WinError 10013] Intento de acceso a un socket no permitido por sus permisos de acceso (configured timeouts: socketTimeoutMS: 20000.0ms, connectTimeoutMS: 20000.0ms),ac-7zrxalx-shard-00-00.v1mxd4q.mongodb.net:27017: [WinError 10013] Intento de acceso a un socket no permitido por sus permisos de acceso (configured timeouts: socketTimeoutMS: 20000.0ms, connectTimeoutMS: 20000.0ms), Timeout: 30s, Topology Description: <TopologyDescription id: 665889bf91c27085cc191084, topology_type: ReplicaSetNoPrimary, servers: [<ServerDescription ('ac-7zrxalx-shard-00-00.v1mxd4q.mongodb.net', 27017) server_type: Unknown, rtt: None, error=AutoReconnect('ac-7zrxalx-shard-00-00.v1mxd4q.mongodb.net:27017: [WinError 10013] Intento de acceso a un socket no permitido por sus permisos de acceso (configured timeouts: socketTimeoutMS: 20000.0ms, connectTimeoutMS: 20000.0ms)')>, <ServerDescription ('ac-7zrxalx-shard-00-01.v1mxd4q.mongodb.net', 27017) server_type: Unknown, rtt: None, error=AutoReconnect('ac-7zrxalx-shard-00-01.v1mxd4q.mongodb.net:27017: [WinError 10013] Intento de acceso a un socket no permitido por sus permisos de acceso (configured timeouts: socketTimeoutMS: 20000.0ms, connectTimeoutMS: 20000.0ms)')>, <ServerDescription ('ac-7zrxalx-shard-00-02.v1mxd4q.mongodb.net', 27017) server_type: Unknown, rtt: None, error=AutoReconnect('ac-7zrxalx-shard-00-02.v1mxd4q.mongodb.net:27017: [WinError 10013] Intento de acceso a un socket no permitido por sus permisos de acceso (configured timeouts: socketTimeoutMS: 20000.0ms, connectTimeoutMS: 20000.0ms)')>]>
ERROR:paramiko.transport:Exception: Error reading SSH protocol banner
ERROR:paramiko.transport:Traceback (most recent call last):
ERROR:paramiko.transport:  File "C:\Users\martimasxax\AppData\Local\Packages\PythonSoftwareFoundation.Python.3.12_qbz5n2kfra8p0\LocalCache\local-packages\Python312\site-packages\paramiko\transport.py", line 2211, in _check_banner
ERROR:paramiko.transport:    buf = self.packetizer.readline(timeout)
ERROR:paramiko.transport:          ^^^^^^^^^^^^^^^^^^^^^^^^^^^^^^^^^
ERROR:paramiko.transport:  File "C:\Users\martimasxax\AppData\Local\Packages\PythonSoftwareFoundation.Python.3.12_qbz5n2kfra8p0\LocalCache\local-packages\Python312\site-packages\paramiko\packet.py", line 380, in readline
ERROR:paramiko.transport:    buf += self._read_timeout(timeout)
ERROR:paramiko.transport:           ^^^^^^^^^^^^^^^^^^^^^^^^^^^
ERROR:paramiko.transport:  File "C:\Users\martimasxax\AppData\Local\Packages\PythonSoftwareFoundation.Python.3.12_qbz5n2kfra8p0\LocalCache\local-packages\Python312\site-packages\paramiko\packet.py", line 622, in _read_timeout
ERROR:paramiko.transport:    raise socket.timeout()
ERROR:paramiko.transport:TimeoutError
ERROR:paramiko.transport:
ERROR:paramiko.transport:During handling of the above exception, another exception occurred:
ERROR:paramiko.transport:
ERROR:paramiko.transport:Traceback (most recent call last):
ERROR:paramiko.transport:  File "C:\Users\martimasxax\AppData\Local\Packages\PythonSoftwareFoundation.Python.3.12_qbz5n2kfra8p0\LocalCache\local-packages\Python312\site-packages\paramiko\transport.py", line 2039, in run
ERROR:paramiko.transport:    self._check_banner()
ERROR:paramiko.transport:  File "C:\Users\martimasxax\AppData\Local\Packages\PythonSoftwareFoundation.Python.3.12_qbz5n2kfra8p0\LocalCache\local-packages\Python312\site-packages\paramiko\transport.py", line 2215, in _check_banner
ERROR:paramiko.transport:    raise SSHException(
ERROR:paramiko.transport:paramiko.ssh_exception.SSHException: Error reading SSH protocol banner
ERROR:paramiko.transport:
INFO:paramiko.transport:Connected (version 2.0, client OpenSSH_8.2p1)
INFO:paramiko.transport:Authentication (password) successful!
INFO:paramiko.transport.sftp:[chan 3] Opened sftp connection (server version 3)
INFO:paramiko.transport.sftp:[chan 4] Opened sftp connection (server version 3)
ERROR:asyncio:Task exception was never retrieved
future: <Task finished name='Task-3' coro=<watch_changes() done, defined at E:\Project\Back4\BN-BackEnd\config\changeStream.py:6> exception=ServerSelectionTimeoutError('SSL handshake failed: ac-7zrxalx-shard-00-00.v1mxd4q.mongodb.net:27017: [(\'SSL routines\', \'\', \'tlsv1 alert internal error\')] (configured timeouts: socketTimeoutMS: 20000.0ms, connectTimeoutMS: 20000.0ms),SSL handshake failed: ac-7zrxalx-shard-00-02.v1mxd4q.mongodb.net:27017: [(\'SSL routines\', \'\', \'tlsv1 alert internal error\')] (configured timeouts: socketTimeoutMS: 20000.0ms, connectTimeoutMS: 20000.0ms),SSL handshake failed: ac-7zrxalx-shard-00-01.v1mxd4q.mongodb.net:27017: [(\'SSL routines\', \'\', \'tlsv1 alert internal error\')] (configured timeouts: socketTimeoutMS: 20000.0ms, connectTimeoutMS: 20000.0ms), Timeout: 30s, Topology Description: <TopologyDescription id: 6661dc849d9319afd1643703, topology_type: ReplicaSetNoPrimary, servers: [<ServerDescription (\'ac-7zrxalx-shard-00-00.v1mxd4q.mongodb.net\', 27017) server_type: Unknown, rtt: None, error=AutoReconnect("SSL handshake failed: ac-7zrxalx-shard-00-00.v1mxd4q.mongodb.net:27017: [(\'SSL routines\', \'\', \'tlsv1 alert internal error\')] (configured timeouts: socketTimeoutMS: 20000.0ms, connectTimeoutMS: 20000.0ms)")>, <ServerDescription (\'ac-7zrxalx-shard-00-01.v1mxd4q.mongodb.net\', 27017) server_type: Unknown, rtt: None, error=AutoReconnect("SSL handshake failed: ac-7zrxalx-shard-00-01.v1mxd4q.mongodb.net:27017: [(\'SSL routines\', \'\', \'tlsv1 alert internal error\')] (configured timeouts: socketTimeoutMS: 20000.0ms, connectTimeoutMS: 20000.0ms)")>, <ServerDescription (\'ac-7zrxalx-shard-00-02.v1mxd4q.mongodb.net\', 27017) server_type: Unknown, rtt: None, error=AutoReconnect("SSL handshake failed: ac-7zrxalx-shard-00-02.v1mxd4q.mongodb.net:27017: [(\'SSL routines\', \'\', \'tlsv1 alert internal error\')] (configured timeouts: socketTimeoutMS: 20000.0ms, connectTimeoutMS: 20000.0ms)")>]>')>
Traceback (most recent call last):
  File "E:\Project\Back4\BN-BackEnd\config\changeStream.py", line 7, in watch_changes
    async with interactions_collection.watch() as stream:
  File "C:\Users\martimasxax\AppData\Local\Packages\PythonSoftwareFoundation.Python.3.12_qbz5n2kfra8p0\LocalCache\local-packages\Python312\site-packages\motor\core.py", line 2097, in __aenter__
    await self._framework.run_on_executor(loop, self._lazy_init)
  File "C:\Program Files\WindowsApps\PythonSoftwareFoundation.Python.3.12_3.12.1008.0_x64__qbz5n2kfra8p0\Lib\concurrent\futures\thread.py", line 58, in run
    result = self.fn(*self.args, **self.kwargs)
             ^^^^^^^^^^^^^^^^^^^^^^^^^^^^^^^^^^
  File "C:\Users\martimasxax\AppData\Local\Packages\PythonSoftwareFoundation.Python.3.12_qbz5n2kfra8p0\LocalCache\local-packages\Python312\site-packages\motor\core.py", line 1979, in _lazy_init
    self.delegate = self._target.delegate.watch(**unwrap_kwargs_session(self._kwargs))
                    ^^^^^^^^^^^^^^^^^^^^^^^^^^^^^^^^^^^^^^^^^^^^^^^^^^^^^^^^^^^^^^^^^^
  File "C:\Users\martimasxax\AppData\Local\Packages\PythonSoftwareFoundation.Python.3.12_qbz5n2kfra8p0\LocalCache\local-packages\Python312\site-packages\pymongo\collection.py", line 2903, in watch
    return CollectionChangeStream(
           ^^^^^^^^^^^^^^^^^^^^^^^
  File "C:\Users\martimasxax\AppData\Local\Packages\PythonSoftwareFoundation.Python.3.12_qbz5n2kfra8p0\LocalCache\local-packages\Python312\site-packages\pymongo\change_stream.py", line 152, in __init__
    self._cursor = self._create_cursor()
                   ^^^^^^^^^^^^^^^^^^^^^
  File "C:\Users\martimasxax\AppData\Local\Packages\PythonSoftwareFoundation.Python.3.12_qbz5n2kfra8p0\LocalCache\local-packages\Python312\site-packages\pymongo\change_stream.py", line 251, in _create_cursor
    with self._client._tmp_session(self._session, close=False) as s:
  File "C:\Program Files\WindowsApps\PythonSoftwareFoundation.Python.3.12_3.12.1008.0_x64__qbz5n2kfra8p0\Lib\contextlib.py", line 137, in __enter__
    return next(self.gen)
           ^^^^^^^^^^^^^^
  File "C:\Users\martimasxax\AppData\Local\Packages\PythonSoftwareFoundation.Python.3.12_qbz5n2kfra8p0\LocalCache\local-packages\Python312\site-packages\pymongo\mongo_client.py", line 1840, in _tmp_session
    s = self._ensure_session(session)
        ^^^^^^^^^^^^^^^^^^^^^^^^^^^^^
  File "C:\Users\martimasxax\AppData\Local\Packages\PythonSoftwareFoundation.Python.3.12_qbz5n2kfra8p0\LocalCache\local-packages\Python312\site-packages\pymongo\mongo_client.py", line 1823, in _ensure_session
    return self.__start_session(True, causal_consistency=False)
           ^^^^^^^^^^^^^^^^^^^^^^^^^^^^^^^^^^^^^^^^^^^^^^^^^^^^
  File "C:\Users\martimasxax\AppData\Local\Packages\PythonSoftwareFoundation.Python.3.12_qbz5n2kfra8p0\LocalCache\local-packages\Python312\site-packages\pymongo\mongo_client.py", line 1766, in __start_session
    self._topology._check_implicit_session_support()
  File "C:\Users\martimasxax\AppData\Local\Packages\PythonSoftwareFoundation.Python.3.12_qbz5n2kfra8p0\LocalCache\local-packages\Python312\site-packages\pymongo\topology.py", line 573, in _check_implicit_session_support
    self._check_session_support()
  File "C:\Users\martimasxax\AppData\Local\Packages\PythonSoftwareFoundation.Python.3.12_qbz5n2kfra8p0\LocalCache\local-packages\Python312\site-packages\pymongo\topology.py", line 589, in _check_session_support
    self._select_servers_loop(
  File "C:\Users\martimasxax\AppData\Local\Packages\PythonSoftwareFoundation.Python.3.12_qbz5n2kfra8p0\LocalCache\local-packages\Python312\site-packages\pymongo\topology.py", line 259, in _select_servers_loop
    raise ServerSelectionTimeoutError(
pymongo.errors.ServerSelectionTimeoutError: SSL handshake failed: ac-7zrxalx-shard-00-00.v1mxd4q.mongodb.net:27017: [('SSL routines', '', 'tlsv1 alert internal error')] (configured timeouts: socketTimeoutMS: 20000.0ms, connectTimeoutMS: 20000.0ms),SSL handshake failed: ac-7zrxalx-shard-00-02.v1mxd4q.mongodb.net:27017: [('SSL routines', '', 'tlsv1 alert internal error')] (configured timeouts: socketTimeoutMS: 20000.0ms, connectTimeoutMS: 20000.0ms),SSL handshake failed: ac-7zrxalx-shard-00-01.v1mxd4q.mongodb.net:27017: [('SSL routines', '', 'tlsv1 alert internal error')] (configured timeouts: socketTimeoutMS: 20000.0ms, connectTimeoutMS: 20000.0ms), Timeout: 30s, Topology Description: <TopologyDescription id: 6661dc849d9319afd1643703, topology_type: ReplicaSetNoPrimary, servers: [<ServerDescription ('ac-7zrxalx-shard-00-00.v1mxd4q.mongodb.net', 27017) server_type: Unknown, rtt: None, error=AutoReconnect("SSL handshake failed: ac-7zrxalx-shard-00-00.v1mxd4q.mongodb.net:27017: [('SSL routines', '', 'tlsv1 alert internal error')] (configured timeouts: socketTimeoutMS: 20000.0ms, connectTimeoutMS: 20000.0ms)")>, <ServerDescription ('ac-7zrxalx-shard-00-01.v1mxd4q.mongodb.net', 27017) server_type: Unknown, rtt: None, error=AutoReconnect("SSL handshake failed: ac-7zrxalx-shard-00-01.v1mxd4q.mongodb.net:27017: [('SSL routines', '', 'tlsv1 alert internal error')] (configured timeouts: socketTimeoutMS: 20000.0ms, connectTimeoutMS: 20000.0ms)")>, <ServerDescription ('ac-7zrxalx-shard-00-02.v1mxd4q.mongodb.net', 27017) server_type: Unknown, rtt: None, error=AutoReconnect("SSL handshake failed: ac-7zrxalx-shard-00-02.v1mxd4q.mongodb.net:27017: [('SSL routines', '', 'tlsv1 alert internal error')] (configured timeouts: socketTimeoutMS: 20000.0ms, connectTimeoutMS: 20000.0ms)")>]>
ERROR:asyncio:Task exception was never retrieved
future: <Task finished name='Task-3' coro=<watch_changes() done, defined at E:\Project\Back4\BN-BackEnd\config\changeStream.py:6> exception=ServerSelectionTimeoutError('SSL handshake failed: ac-7zrxalx-shard-00-00.v1mxd4q.mongodb.net:27017: [(\'SSL routines\', \'\', \'tlsv1 alert internal error\')] (configured timeouts: socketTimeoutMS: 20000.0ms, connectTimeoutMS: 20000.0ms),SSL handshake failed: ac-7zrxalx-shard-00-01.v1mxd4q.mongodb.net:27017: [(\'SSL routines\', \'\', \'tlsv1 alert internal error\')] (configured timeouts: socketTimeoutMS: 20000.0ms, connectTimeoutMS: 20000.0ms),SSL handshake failed: ac-7zrxalx-shard-00-02.v1mxd4q.mongodb.net:27017: [(\'SSL routines\', \'\', \'tlsv1 alert internal error\')] (configured timeouts: socketTimeoutMS: 20000.0ms, connectTimeoutMS: 20000.0ms), Timeout: 30s, Topology Description: <TopologyDescription id: 6661dcaba9952afd0786d674, topology_type: ReplicaSetNoPrimary, servers: [<ServerDescription (\'ac-7zrxalx-shard-00-00.v1mxd4q.mongodb.net\', 27017) server_type: Unknown, rtt: None, error=AutoReconnect("SSL handshake failed: ac-7zrxalx-shard-00-00.v1mxd4q.mongodb.net:27017: [(\'SSL routines\', \'\', \'tlsv1 alert internal error\')] (configured timeouts: socketTimeoutMS: 20000.0ms, connectTimeoutMS: 20000.0ms)")>, <ServerDescription (\'ac-7zrxalx-shard-00-01.v1mxd4q.mongodb.net\', 27017) server_type: Unknown, rtt: None, error=AutoReconnect("SSL handshake failed: ac-7zrxalx-shard-00-01.v1mxd4q.mongodb.net:27017: [(\'SSL routines\', \'\', \'tlsv1 alert internal error\')] (configured timeouts: socketTimeoutMS: 20000.0ms, connectTimeoutMS: 20000.0ms)")>, <ServerDescription (\'ac-7zrxalx-shard-00-02.v1mxd4q.mongodb.net\', 27017) server_type: Unknown, rtt: None, error=AutoReconnect("SSL handshake failed: ac-7zrxalx-shard-00-02.v1mxd4q.mongodb.net:27017: [(\'SSL routines\', \'\', \'tlsv1 alert internal error\')] (configured timeouts: socketTimeoutMS: 20000.0ms, connectTimeoutMS: 20000.0ms)")>]>')>
Traceback (most recent call last):
  File "E:\Project\Back4\BN-BackEnd\config\changeStream.py", line 7, in watch_changes
    async with interactions_collection.watch() as stream:
  File "C:\Users\martimasxax\AppData\Local\Packages\PythonSoftwareFoundation.Python.3.12_qbz5n2kfra8p0\LocalCache\local-packages\Python312\site-packages\motor\core.py", line 2097, in __aenter__
    await self._framework.run_on_executor(loop, self._lazy_init)
  File "C:\Program Files\WindowsApps\PythonSoftwareFoundation.Python.3.12_3.12.1008.0_x64__qbz5n2kfra8p0\Lib\concurrent\futures\thread.py", line 58, in run
    result = self.fn(*self.args, **self.kwargs)
             ^^^^^^^^^^^^^^^^^^^^^^^^^^^^^^^^^^
  File "C:\Users\martimasxax\AppData\Local\Packages\PythonSoftwareFoundation.Python.3.12_qbz5n2kfra8p0\LocalCache\local-packages\Python312\site-packages\motor\core.py", line 1979, in _lazy_init
    self.delegate = self._target.delegate.watch(**unwrap_kwargs_session(self._kwargs))
                    ^^^^^^^^^^^^^^^^^^^^^^^^^^^^^^^^^^^^^^^^^^^^^^^^^^^^^^^^^^^^^^^^^^
  File "C:\Users\martimasxax\AppData\Local\Packages\PythonSoftwareFoundation.Python.3.12_qbz5n2kfra8p0\LocalCache\local-packages\Python312\site-packages\pymongo\collection.py", line 2903, in watch
    return CollectionChangeStream(
           ^^^^^^^^^^^^^^^^^^^^^^^
  File "C:\Users\martimasxax\AppData\Local\Packages\PythonSoftwareFoundation.Python.3.12_qbz5n2kfra8p0\LocalCache\local-packages\Python312\site-packages\pymongo\change_stream.py", line 152, in __init__
    self._cursor = self._create_cursor()
                   ^^^^^^^^^^^^^^^^^^^^^
  File "C:\Users\martimasxax\AppData\Local\Packages\PythonSoftwareFoundation.Python.3.12_qbz5n2kfra8p0\LocalCache\local-packages\Python312\site-packages\pymongo\change_stream.py", line 251, in _create_cursor
    with self._client._tmp_session(self._session, close=False) as s:
  File "C:\Program Files\WindowsApps\PythonSoftwareFoundation.Python.3.12_3.12.1008.0_x64__qbz5n2kfra8p0\Lib\contextlib.py", line 137, in __enter__
    return next(self.gen)
           ^^^^^^^^^^^^^^
  File "C:\Users\martimasxax\AppData\Local\Packages\PythonSoftwareFoundation.Python.3.12_qbz5n2kfra8p0\LocalCache\local-packages\Python312\site-packages\pymongo\mongo_client.py", line 1840, in _tmp_session
    s = self._ensure_session(session)
        ^^^^^^^^^^^^^^^^^^^^^^^^^^^^^
  File "C:\Users\martimasxax\AppData\Local\Packages\PythonSoftwareFoundation.Python.3.12_qbz5n2kfra8p0\LocalCache\local-packages\Python312\site-packages\pymongo\mongo_client.py", line 1823, in _ensure_session
    return self.__start_session(True, causal_consistency=False)
           ^^^^^^^^^^^^^^^^^^^^^^^^^^^^^^^^^^^^^^^^^^^^^^^^^^^^
  File "C:\Users\martimasxax\AppData\Local\Packages\PythonSoftwareFoundation.Python.3.12_qbz5n2kfra8p0\LocalCache\local-packages\Python312\site-packages\pymongo\mongo_client.py", line 1766, in __start_session
    self._topology._check_implicit_session_support()
  File "C:\Users\martimasxax\AppData\Local\Packages\PythonSoftwareFoundation.Python.3.12_qbz5n2kfra8p0\LocalCache\local-packages\Python312\site-packages\pymongo\topology.py", line 573, in _check_implicit_session_support
    self._check_session_support()
  File "C:\Users\martimasxax\AppData\Local\Packages\PythonSoftwareFoundation.Python.3.12_qbz5n2kfra8p0\LocalCache\local-packages\Python312\site-packages\pymongo\topology.py", line 589, in _check_session_support
    self._select_servers_loop(
  File "C:\Users\martimasxax\AppData\Local\Packages\PythonSoftwareFoundation.Python.3.12_qbz5n2kfra8p0\LocalCache\local-packages\Python312\site-packages\pymongo\topology.py", line 259, in _select_servers_loop
    raise ServerSelectionTimeoutError(
pymongo.errors.ServerSelectionTimeoutError: SSL handshake failed: ac-7zrxalx-shard-00-00.v1mxd4q.mongodb.net:27017: [('SSL routines', '', 'tlsv1 alert internal error')] (configured timeouts: socketTimeoutMS: 20000.0ms, connectTimeoutMS: 20000.0ms),SSL handshake failed: ac-7zrxalx-shard-00-01.v1mxd4q.mongodb.net:27017: [('SSL routines', '', 'tlsv1 alert internal error')] (configured timeouts: socketTimeoutMS: 20000.0ms, connectTimeoutMS: 20000.0ms),SSL handshake failed: ac-7zrxalx-shard-00-02.v1mxd4q.mongodb.net:27017: [('SSL routines', '', 'tlsv1 alert internal error')] (configured timeouts: socketTimeoutMS: 20000.0ms, connectTimeoutMS: 20000.0ms), Timeout: 30s, Topology Description: <TopologyDescription id: 6661dcaba9952afd0786d674, topology_type: ReplicaSetNoPrimary, servers: [<ServerDescription ('ac-7zrxalx-shard-00-00.v1mxd4q.mongodb.net', 27017) server_type: Unknown, rtt: None, error=AutoReconnect("SSL handshake failed: ac-7zrxalx-shard-00-00.v1mxd4q.mongodb.net:27017: [('SSL routines', '', 'tlsv1 alert internal error')] (configured timeouts: socketTimeoutMS: 20000.0ms, connectTimeoutMS: 20000.0ms)")>, <ServerDescription ('ac-7zrxalx-shard-00-01.v1mxd4q.mongodb.net', 27017) server_type: Unknown, rtt: None, error=AutoReconnect("SSL handshake failed: ac-7zrxalx-shard-00-01.v1mxd4q.mongodb.net:27017: [('SSL routines', '', 'tlsv1 alert internal error')] (configured timeouts: socketTimeoutMS: 20000.0ms, connectTimeoutMS: 20000.0ms)")>, <ServerDescription ('ac-7zrxalx-shard-00-02.v1mxd4q.mongodb.net', 27017) server_type: Unknown, rtt: None, error=AutoReconnect("SSL handshake failed: ac-7zrxalx-shard-00-02.v1mxd4q.mongodb.net:27017: [('SSL routines', '', 'tlsv1 alert internal error')] (configured timeouts: socketTimeoutMS: 20000.0ms, connectTimeoutMS: 20000.0ms)")>]>
ERROR:asyncio:Task exception was never retrieved
future: <Task finished name='Task-3' coro=<watch_changes() done, defined at E:\Project\Back4\BN-BackEnd\config\changeStream.py:6> exception=ServerSelectionTimeoutError('SSL handshake failed: ac-7zrxalx-shard-00-00.v1mxd4q.mongodb.net:27017: [(\'SSL routines\', \'\', \'tlsv1 alert internal error\')] (configured timeouts: socketTimeoutMS: 20000.0ms, connectTimeoutMS: 20000.0ms),SSL handshake failed: ac-7zrxalx-shard-00-01.v1mxd4q.mongodb.net:27017: [(\'SSL routines\', \'\', \'tlsv1 alert internal error\')] (configured timeouts: socketTimeoutMS: 20000.0ms, connectTimeoutMS: 20000.0ms),SSL handshake failed: ac-7zrxalx-shard-00-02.v1mxd4q.mongodb.net:27017: [(\'SSL routines\', \'\', \'tlsv1 alert internal error\')] (configured timeouts: socketTimeoutMS: 20000.0ms, connectTimeoutMS: 20000.0ms), Timeout: 30s, Topology Description: <TopologyDescription id: 6661dd7188e2628edc40b753, topology_type: ReplicaSetNoPrimary, servers: [<ServerDescription (\'ac-7zrxalx-shard-00-00.v1mxd4q.mongodb.net\', 27017) server_type: Unknown, rtt: None, error=AutoReconnect("SSL handshake failed: ac-7zrxalx-shard-00-00.v1mxd4q.mongodb.net:27017: [(\'SSL routines\', \'\', \'tlsv1 alert internal error\')] (configured timeouts: socketTimeoutMS: 20000.0ms, connectTimeoutMS: 20000.0ms)")>, <ServerDescription (\'ac-7zrxalx-shard-00-01.v1mxd4q.mongodb.net\', 27017) server_type: Unknown, rtt: None, error=AutoReconnect("SSL handshake failed: ac-7zrxalx-shard-00-01.v1mxd4q.mongodb.net:27017: [(\'SSL routines\', \'\', \'tlsv1 alert internal error\')] (configured timeouts: socketTimeoutMS: 20000.0ms, connectTimeoutMS: 20000.0ms)")>, <ServerDescription (\'ac-7zrxalx-shard-00-02.v1mxd4q.mongodb.net\', 27017) server_type: Unknown, rtt: None, error=AutoReconnect("SSL handshake failed: ac-7zrxalx-shard-00-02.v1mxd4q.mongodb.net:27017: [(\'SSL routines\', \'\', \'tlsv1 alert internal error\')] (configured timeouts: socketTimeoutMS: 20000.0ms, connectTimeoutMS: 20000.0ms)")>]>')>
Traceback (most recent call last):
  File "E:\Project\Back4\BN-BackEnd\config\changeStream.py", line 7, in watch_changes
    async with interactions_collection.watch() as stream:
  File "C:\Users\martimasxax\AppData\Local\Packages\PythonSoftwareFoundation.Python.3.12_qbz5n2kfra8p0\LocalCache\local-packages\Python312\site-packages\motor\core.py", line 2097, in __aenter__
    await self._framework.run_on_executor(loop, self._lazy_init)
  File "C:\Program Files\WindowsApps\PythonSoftwareFoundation.Python.3.12_3.12.1008.0_x64__qbz5n2kfra8p0\Lib\concurrent\futures\thread.py", line 58, in run
    result = self.fn(*self.args, **self.kwargs)
             ^^^^^^^^^^^^^^^^^^^^^^^^^^^^^^^^^^
  File "C:\Users\martimasxax\AppData\Local\Packages\PythonSoftwareFoundation.Python.3.12_qbz5n2kfra8p0\LocalCache\local-packages\Python312\site-packages\motor\core.py", line 1979, in _lazy_init
    self.delegate = self._target.delegate.watch(**unwrap_kwargs_session(self._kwargs))
                    ^^^^^^^^^^^^^^^^^^^^^^^^^^^^^^^^^^^^^^^^^^^^^^^^^^^^^^^^^^^^^^^^^^
  File "C:\Users\martimasxax\AppData\Local\Packages\PythonSoftwareFoundation.Python.3.12_qbz5n2kfra8p0\LocalCache\local-packages\Python312\site-packages\pymongo\collection.py", line 2903, in watch
    return CollectionChangeStream(
           ^^^^^^^^^^^^^^^^^^^^^^^
  File "C:\Users\martimasxax\AppData\Local\Packages\PythonSoftwareFoundation.Python.3.12_qbz5n2kfra8p0\LocalCache\local-packages\Python312\site-packages\pymongo\change_stream.py", line 152, in __init__
    self._cursor = self._create_cursor()
                   ^^^^^^^^^^^^^^^^^^^^^
  File "C:\Users\martimasxax\AppData\Local\Packages\PythonSoftwareFoundation.Python.3.12_qbz5n2kfra8p0\LocalCache\local-packages\Python312\site-packages\pymongo\change_stream.py", line 251, in _create_cursor
    with self._client._tmp_session(self._session, close=False) as s:
  File "C:\Program Files\WindowsApps\PythonSoftwareFoundation.Python.3.12_3.12.1008.0_x64__qbz5n2kfra8p0\Lib\contextlib.py", line 137, in __enter__
    return next(self.gen)
           ^^^^^^^^^^^^^^
  File "C:\Users\martimasxax\AppData\Local\Packages\PythonSoftwareFoundation.Python.3.12_qbz5n2kfra8p0\LocalCache\local-packages\Python312\site-packages\pymongo\mongo_client.py", line 1840, in _tmp_session
    s = self._ensure_session(session)
        ^^^^^^^^^^^^^^^^^^^^^^^^^^^^^
  File "C:\Users\martimasxax\AppData\Local\Packages\PythonSoftwareFoundation.Python.3.12_qbz5n2kfra8p0\LocalCache\local-packages\Python312\site-packages\pymongo\mongo_client.py", line 1823, in _ensure_session
    return self.__start_session(True, causal_consistency=False)
           ^^^^^^^^^^^^^^^^^^^^^^^^^^^^^^^^^^^^^^^^^^^^^^^^^^^^
  File "C:\Users\martimasxax\AppData\Local\Packages\PythonSoftwareFoundation.Python.3.12_qbz5n2kfra8p0\LocalCache\local-packages\Python312\site-packages\pymongo\mongo_client.py", line 1766, in __start_session
    self._topology._check_implicit_session_support()
  File "C:\Users\martimasxax\AppData\Local\Packages\PythonSoftwareFoundation.Python.3.12_qbz5n2kfra8p0\LocalCache\local-packages\Python312\site-packages\pymongo\topology.py", line 573, in _check_implicit_session_support
    self._check_session_support()
  File "C:\Users\martimasxax\AppData\Local\Packages\PythonSoftwareFoundation.Python.3.12_qbz5n2kfra8p0\LocalCache\local-packages\Python312\site-packages\pymongo\topology.py", line 589, in _check_session_support
    self._select_servers_loop(
  File "C:\Users\martimasxax\AppData\Local\Packages\PythonSoftwareFoundation.Python.3.12_qbz5n2kfra8p0\LocalCache\local-packages\Python312\site-packages\pymongo\topology.py", line 259, in _select_servers_loop
    raise ServerSelectionTimeoutError(
pymongo.errors.ServerSelectionTimeoutError: SSL handshake failed: ac-7zrxalx-shard-00-00.v1mxd4q.mongodb.net:27017: [('SSL routines', '', 'tlsv1 alert internal error')] (configured timeouts: socketTimeoutMS: 20000.0ms, connectTimeoutMS: 20000.0ms),SSL handshake failed: ac-7zrxalx-shard-00-01.v1mxd4q.mongodb.net:27017: [('SSL routines', '', 'tlsv1 alert internal error')] (configured timeouts: socketTimeoutMS: 20000.0ms, connectTimeoutMS: 20000.0ms),SSL handshake failed: ac-7zrxalx-shard-00-02.v1mxd4q.mongodb.net:27017: [('SSL routines', '', 'tlsv1 alert internal error')] (configured timeouts: socketTimeoutMS: 20000.0ms, connectTimeoutMS: 20000.0ms), Timeout: 30s, Topology Description: <TopologyDescription id: 6661dd7188e2628edc40b753, topology_type: ReplicaSetNoPrimary, servers: [<ServerDescription ('ac-7zrxalx-shard-00-00.v1mxd4q.mongodb.net', 27017) server_type: Unknown, rtt: None, error=AutoReconnect("SSL handshake failed: ac-7zrxalx-shard-00-00.v1mxd4q.mongodb.net:27017: [('SSL routines', '', 'tlsv1 alert internal error')] (configured timeouts: socketTimeoutMS: 20000.0ms, connectTimeoutMS: 20000.0ms)")>, <ServerDescription ('ac-7zrxalx-shard-00-01.v1mxd4q.mongodb.net', 27017) server_type: Unknown, rtt: None, error=AutoReconnect("SSL handshake failed: ac-7zrxalx-shard-00-01.v1mxd4q.mongodb.net:27017: [('SSL routines', '', 'tlsv1 alert internal error')] (configured timeouts: socketTimeoutMS: 20000.0ms, connectTimeoutMS: 20000.0ms)")>, <ServerDescription ('ac-7zrxalx-shard-00-02.v1mxd4q.mongodb.net', 27017) server_type: Unknown, rtt: None, error=AutoReconnect("SSL handshake failed: ac-7zrxalx-shard-00-02.v1mxd4q.mongodb.net:27017: [('SSL routines', '', 'tlsv1 alert internal error')] (configured timeouts: socketTimeoutMS: 20000.0ms, connectTimeoutMS: 20000.0ms)")>]>
ERROR:asyncio:Task exception was never retrieved
future: <Task finished name='Task-3' coro=<watch_changes() done, defined at E:\Project\Back4\BN-BackEnd\config\changeStream.py:6> exception=ServerSelectionTimeoutError('SSL handshake failed: ac-7zrxalx-shard-00-00.v1mxd4q.mongodb.net:27017: [(\'SSL routines\', \'\', \'tlsv1 alert internal error\')] (configured timeouts: socketTimeoutMS: 20000.0ms, connectTimeoutMS: 20000.0ms),SSL handshake failed: ac-7zrxalx-shard-00-02.v1mxd4q.mongodb.net:27017: [(\'SSL routines\', \'\', \'tlsv1 alert internal error\')] (configured timeouts: socketTimeoutMS: 20000.0ms, connectTimeoutMS: 20000.0ms),SSL handshake failed: ac-7zrxalx-shard-00-01.v1mxd4q.mongodb.net:27017: [(\'SSL routines\', \'\', \'tlsv1 alert internal error\')] (configured timeouts: socketTimeoutMS: 20000.0ms, connectTimeoutMS: 20000.0ms), Timeout: 30s, Topology Description: <TopologyDescription id: 6661de50e4f733568b37791d, topology_type: ReplicaSetNoPrimary, servers: [<ServerDescription (\'ac-7zrxalx-shard-00-00.v1mxd4q.mongodb.net\', 27017) server_type: Unknown, rtt: None, error=AutoReconnect("SSL handshake failed: ac-7zrxalx-shard-00-00.v1mxd4q.mongodb.net:27017: [(\'SSL routines\', \'\', \'tlsv1 alert internal error\')] (configured timeouts: socketTimeoutMS: 20000.0ms, connectTimeoutMS: 20000.0ms)")>, <ServerDescription (\'ac-7zrxalx-shard-00-01.v1mxd4q.mongodb.net\', 27017) server_type: Unknown, rtt: None, error=AutoReconnect("SSL handshake failed: ac-7zrxalx-shard-00-01.v1mxd4q.mongodb.net:27017: [(\'SSL routines\', \'\', \'tlsv1 alert internal error\')] (configured timeouts: socketTimeoutMS: 20000.0ms, connectTimeoutMS: 20000.0ms)")>, <ServerDescription (\'ac-7zrxalx-shard-00-02.v1mxd4q.mongodb.net\', 27017) server_type: Unknown, rtt: None, error=AutoReconnect("SSL handshake failed: ac-7zrxalx-shard-00-02.v1mxd4q.mongodb.net:27017: [(\'SSL routines\', \'\', \'tlsv1 alert internal error\')] (configured timeouts: socketTimeoutMS: 20000.0ms, connectTimeoutMS: 20000.0ms)")>]>')>
Traceback (most recent call last):
  File "E:\Project\Back4\BN-BackEnd\config\changeStream.py", line 7, in watch_changes
    async with interactions_collection.watch() as stream:
  File "C:\Users\martimasxax\AppData\Local\Packages\PythonSoftwareFoundation.Python.3.12_qbz5n2kfra8p0\LocalCache\local-packages\Python312\site-packages\motor\core.py", line 2097, in __aenter__
    await self._framework.run_on_executor(loop, self._lazy_init)
  File "C:\Program Files\WindowsApps\PythonSoftwareFoundation.Python.3.12_3.12.1008.0_x64__qbz5n2kfra8p0\Lib\concurrent\futures\thread.py", line 58, in run
    result = self.fn(*self.args, **self.kwargs)
             ^^^^^^^^^^^^^^^^^^^^^^^^^^^^^^^^^^
  File "C:\Users\martimasxax\AppData\Local\Packages\PythonSoftwareFoundation.Python.3.12_qbz5n2kfra8p0\LocalCache\local-packages\Python312\site-packages\motor\core.py", line 1979, in _lazy_init
    self.delegate = self._target.delegate.watch(**unwrap_kwargs_session(self._kwargs))
                    ^^^^^^^^^^^^^^^^^^^^^^^^^^^^^^^^^^^^^^^^^^^^^^^^^^^^^^^^^^^^^^^^^^
  File "C:\Users\martimasxax\AppData\Local\Packages\PythonSoftwareFoundation.Python.3.12_qbz5n2kfra8p0\LocalCache\local-packages\Python312\site-packages\pymongo\collection.py", line 2903, in watch
    return CollectionChangeStream(
           ^^^^^^^^^^^^^^^^^^^^^^^
  File "C:\Users\martimasxax\AppData\Local\Packages\PythonSoftwareFoundation.Python.3.12_qbz5n2kfra8p0\LocalCache\local-packages\Python312\site-packages\pymongo\change_stream.py", line 152, in __init__
    self._cursor = self._create_cursor()
                   ^^^^^^^^^^^^^^^^^^^^^
  File "C:\Users\martimasxax\AppData\Local\Packages\PythonSoftwareFoundation.Python.3.12_qbz5n2kfra8p0\LocalCache\local-packages\Python312\site-packages\pymongo\change_stream.py", line 251, in _create_cursor
    with self._client._tmp_session(self._session, close=False) as s:
  File "C:\Program Files\WindowsApps\PythonSoftwareFoundation.Python.3.12_3.12.1008.0_x64__qbz5n2kfra8p0\Lib\contextlib.py", line 137, in __enter__
    return next(self.gen)
           ^^^^^^^^^^^^^^
  File "C:\Users\martimasxax\AppData\Local\Packages\PythonSoftwareFoundation.Python.3.12_qbz5n2kfra8p0\LocalCache\local-packages\Python312\site-packages\pymongo\mongo_client.py", line 1840, in _tmp_session
    s = self._ensure_session(session)
        ^^^^^^^^^^^^^^^^^^^^^^^^^^^^^
  File "C:\Users\martimasxax\AppData\Local\Packages\PythonSoftwareFoundation.Python.3.12_qbz5n2kfra8p0\LocalCache\local-packages\Python312\site-packages\pymongo\mongo_client.py", line 1823, in _ensure_session
    return self.__start_session(True, causal_consistency=False)
           ^^^^^^^^^^^^^^^^^^^^^^^^^^^^^^^^^^^^^^^^^^^^^^^^^^^^
  File "C:\Users\martimasxax\AppData\Local\Packages\PythonSoftwareFoundation.Python.3.12_qbz5n2kfra8p0\LocalCache\local-packages\Python312\site-packages\pymongo\mongo_client.py", line 1766, in __start_session
    self._topology._check_implicit_session_support()
  File "C:\Users\martimasxax\AppData\Local\Packages\PythonSoftwareFoundation.Python.3.12_qbz5n2kfra8p0\LocalCache\local-packages\Python312\site-packages\pymongo\topology.py", line 573, in _check_implicit_session_support
    self._check_session_support()
  File "C:\Users\martimasxax\AppData\Local\Packages\PythonSoftwareFoundation.Python.3.12_qbz5n2kfra8p0\LocalCache\local-packages\Python312\site-packages\pymongo\topology.py", line 589, in _check_session_support
    self._select_servers_loop(
  File "C:\Users\martimasxax\AppData\Local\Packages\PythonSoftwareFoundation.Python.3.12_qbz5n2kfra8p0\LocalCache\local-packages\Python312\site-packages\pymongo\topology.py", line 259, in _select_servers_loop
    raise ServerSelectionTimeoutError(
pymongo.errors.ServerSelectionTimeoutError: SSL handshake failed: ac-7zrxalx-shard-00-00.v1mxd4q.mongodb.net:27017: [('SSL routines', '', 'tlsv1 alert internal error')] (configured timeouts: socketTimeoutMS: 20000.0ms, connectTimeoutMS: 20000.0ms),SSL handshake failed: ac-7zrxalx-shard-00-02.v1mxd4q.mongodb.net:27017: [('SSL routines', '', 'tlsv1 alert internal error')] (configured timeouts: socketTimeoutMS: 20000.0ms, connectTimeoutMS: 20000.0ms),SSL handshake failed: ac-7zrxalx-shard-00-01.v1mxd4q.mongodb.net:27017: [('SSL routines', '', 'tlsv1 alert internal error')] (configured timeouts: socketTimeoutMS: 20000.0ms, connectTimeoutMS: 20000.0ms), Timeout: 30s, Topology Description: <TopologyDescription id: 6661de50e4f733568b37791d, topology_type: ReplicaSetNoPrimary, servers: [<ServerDescription ('ac-7zrxalx-shard-00-00.v1mxd4q.mongodb.net', 27017) server_type: Unknown, rtt: None, error=AutoReconnect("SSL handshake failed: ac-7zrxalx-shard-00-00.v1mxd4q.mongodb.net:27017: [('SSL routines', '', 'tlsv1 alert internal error')] (configured timeouts: socketTimeoutMS: 20000.0ms, connectTimeoutMS: 20000.0ms)")>, <ServerDescription ('ac-7zrxalx-shard-00-01.v1mxd4q.mongodb.net', 27017) server_type: Unknown, rtt: None, error=AutoReconnect("SSL handshake failed: ac-7zrxalx-shard-00-01.v1mxd4q.mongodb.net:27017: [('SSL routines', '', 'tlsv1 alert internal error')] (configured timeouts: socketTimeoutMS: 20000.0ms, connectTimeoutMS: 20000.0ms)")>, <ServerDescription ('ac-7zrxalx-shard-00-02.v1mxd4q.mongodb.net', 27017) server_type: Unknown, rtt: None, error=AutoReconnect("SSL handshake failed: ac-7zrxalx-shard-00-02.v1mxd4q.mongodb.net:27017: [('SSL routines', '', 'tlsv1 alert internal error')] (configured timeouts: socketTimeoutMS: 20000.0ms, connectTimeoutMS: 20000.0ms)")>]>
INFO:paramiko.transport:Connected (version 2.0, client OpenSSH_8.2p1)
INFO:paramiko.transport:Authentication (password) successful!
INFO:paramiko.transport:Connected (version 2.0, client OpenSSH_8.2p1)
INFO:paramiko.transport:Authentication (password) successful!
INFO:paramiko.transport:Connected (version 2.0, client OpenSSH_8.2p1)
INFO:paramiko.transport:Authentication (password) successful!
INFO:paramiko.transport:Connected (version 2.0, client OpenSSH_8.2p1)
INFO:paramiko.transport:Authentication (password) successful!
INFO:paramiko.transport:Connected (version 2.0, client OpenSSH_8.2p1)
INFO:paramiko.transport:Authentication (password) successful!
INFO:paramiko.transport:Connected (version 2.0, client OpenSSH_8.2p1)
INFO:paramiko.transport:Authentication (password) successful!
INFO:paramiko.transport:Connected (version 2.0, client OpenSSH_8.2p1)
INFO:paramiko.transport:Authentication (password) successful!
